package com.trinia.world.gen;

import java.util.Random;

import com.trinia.blocks.TriniaBlocks;

import net.minecraft.util.BlockPos;
import net.minecraft.world.World;
import net.minecraft.world.gen.feature.WorldGenerator;

public class WorldGenTower extends WorldGenerator {
	
	@Override
	public boolean generate(World world, Random rand, BlockPos pos) {
		int i = pos.getX(), j = pos.getY(), k = pos.getZ();

		world.setBlockState(new BlockPos(i + 0, j + 4, k + 4), TriniaBlocks.triniaGrass.getDefaultState());
		world.setBlockState(new BlockPos(i + 0, j + 4, k + 5), TriniaBlocks.triniaGrass.getDefaultState());
		world.setBlockState(new BlockPos(i + 0, j + 14, k + 4), TriniaBlocks.triniaStoneBrick.getDefaultState());
		world.setBlockState(new BlockPos(i + 0, j + 14, k + 5), TriniaBlocks.triniaStoneBrick.getDefaultState());
		world.setBlockState(new BlockPos(i + 0, j + 14, k + 6), TriniaBlocks.triniaStoneBrick.getDefaultState());
		world.setBlockState(new BlockPos(i + 1, j + 3, k + 5), TriniaBlocks.triniaDirt.getDefaultState());
		world.setBlockState(new BlockPos(i + 1, j + 3, k + 6), TriniaBlocks.triniaDirt.getDefaultState());
		world.setBlockState(new BlockPos(i + 1, j + 4, k + 3), TriniaBlocks.triniaDirt.getDefaultState());
		world.setBlockState(new BlockPos(i + 1, j + 4, k + 4), TriniaBlocks.triniaGrass.getDefaultState());
		world.setBlockState(new BlockPos(i + 1, j + 4, k + 5), TriniaBlocks.triniaGrass.getDefaultState());
		world.setBlockState(new BlockPos(i + 1, j + 4, k + 6), TriniaBlocks.triniaGrass.getDefaultState());
		world.setBlockState(new BlockPos(i + 1, j + 4, k + 7), TriniaBlocks.triniaDirt.getDefaultState());
		world.setBlockState(new BlockPos(i + 1, j + 5, k + 3), TriniaBlocks.triniaDirt.getDefaultState());
		world.setBlockState(new BlockPos(i + 1, j + 5, k + 4), TriniaBlocks.triniaChiseledStoneBrick.getDefaultState());
		world.setBlockState(new BlockPos(i + 1, j + 5, k + 5), TriniaBlocks.triniaChiseledStoneBrick.getDefaultState());
		world.setBlockState(new BlockPos(i + 1, j + 5, k + 6), TriniaBlocks.triniaChiseledStoneBrick.getDefaultState());
		world.setBlockState(new BlockPos(i + 1, j + 5, k + 7), TriniaBlocks.triniaDirt.getDefaultState());
		world.setBlockState(new BlockPos(i + 1, j + 6, k + 3), TriniaBlocks.triniaStoneBrick.getDefaultState());
		world.setBlockState(new BlockPos(i + 1, j + 6, k + 7), TriniaBlocks.triniaStoneBrick.getDefaultState());
		world.setBlockState(new BlockPos(i + 1, j + 7, k + 3), TriniaBlocks.triniaStoneBrick.getDefaultState());
		world.setBlockState(new BlockPos(i + 1, j + 7, k + 7), TriniaBlocks.triniaStoneBrick.getDefaultState());
		world.setBlockState(new BlockPos(i + 1, j + 8, k + 4), TriniaBlocks.triniaStoneBrick.getDefaultState());
		world.setBlockState(new BlockPos(i + 1, j + 8, k + 5), TriniaBlocks.triniaStoneBrick.getDefaultState());
		world.setBlockState(new BlockPos(i + 1, j + 8, k + 6), TriniaBlocks.triniaStoneBrick.getDefaultState());
		world.setBlockState(new BlockPos(i + 1, j + 11, k + 4), TriniaBlocks.triniaStoneBrick.getDefaultState());
		world.setBlockState(new BlockPos(i + 1, j + 11, k + 5), TriniaBlocks.triniaStoneBrick.getDefaultState());
		world.setBlockState(new BlockPos(i + 1, j + 11, k + 6), TriniaBlocks.triniaStoneBrick.getDefaultState());
		world.setBlockState(new BlockPos(i + 1, j + 13, k + 4), TriniaBlocks.triniaStoneBrick.getDefaultState());
		world.setBlockState(new BlockPos(i + 1, j + 13, k + 5), TriniaBlocks.triniaStoneBrick.getDefaultState());
		world.setBlockState(new BlockPos(i + 1, j + 13, k + 6), TriniaBlocks.triniaStoneBrick.getDefaultState());
		world.setBlockState(new BlockPos(i + 1, j + 14, k + 3), TriniaBlocks.triniaStoneBrick.getDefaultState());
		world.setBlockState(new BlockPos(i + 1, j + 14, k + 4), TriniaBlocks.triniaStoneBrick.getDefaultState());
		world.setBlockState(new BlockPos(i + 1, j + 14, k + 5), TriniaBlocks.triniaStoneBrick.getDefaultState());
		world.setBlockState(new BlockPos(i + 1, j + 14, k + 6), TriniaBlocks.triniaStoneBrick.getDefaultState());
		world.setBlockState(new BlockPos(i + 1, j + 14, k + 7), TriniaBlocks.triniaStoneBrick.getDefaultState());
		world.setBlockState(new BlockPos(i + 1, j + 15, k + 4), TriniaBlocks.triniaStoneBrick.getDefaultState());
		world.setBlockState(new BlockPos(i + 1, j + 15, k + 5), TriniaBlocks.triniaStoneBrick.getDefaultState());
		world.setBlockState(new BlockPos(i + 1, j + 15, k + 6), TriniaBlocks.triniaStoneBrick.getDefaultState());
		world.setBlockState(new BlockPos(i + 2, j + 2, k + 5), TriniaBlocks.triniaDirt.getDefaultState());
		world.setBlockState(new BlockPos(i + 2, j + 2, k + 6), TriniaBlocks.triniaChiseledStoneBrick.getDefaultState());
		world.setBlockState(new BlockPos(i + 2, j + 3, k + 3), TriniaBlocks.triniaDirt.getDefaultState());
		world.setBlockState(new BlockPos(i + 2, j + 3, k + 4), TriniaBlocks.triniaDirt.getDefaultState());
		world.setBlockState(new BlockPos(i + 2, j + 3, k + 5), TriniaBlocks.triniaDirt.getDefaultState());
		world.setBlockState(new BlockPos(i + 2, j + 3, k + 6), TriniaBlocks.triniaDirt.getDefaultState());
		world.setBlockState(new BlockPos(i + 2, j + 3, k + 7), TriniaBlocks.triniaDirt.getDefaultState());
		world.setBlockState(new BlockPos(i + 2, j + 4, k + 2), TriniaBlocks.triniaDirt.getDefaultState());
		world.setBlockState(new BlockPos(i + 2, j + 4, k + 3), TriniaBlocks.triniaDirt.getDefaultState());
		world.setBlockState(new BlockPos(i + 2, j + 4, k + 4), TriniaBlocks.triniaGrass.getDefaultState());
		world.setBlockState(new BlockPos(i + 2, j + 4, k + 5), TriniaBlocks.triniaGrass.getDefaultState());
		world.setBlockState(new BlockPos(i + 2, j + 4, k + 6), TriniaBlocks.triniaGrass.getDefaultState());
		world.setBlockState(new BlockPos(i + 2, j + 4, k + 7), TriniaBlocks.triniaDirt.getDefaultState());
		world.setBlockState(new BlockPos(i + 2, j + 4, k + 8), TriniaBlocks.triniaDirt.getDefaultState());
		world.setBlockState(new BlockPos(i + 2, j + 5, k + 2), TriniaBlocks.triniaDirt.getDefaultState());
		world.setBlockState(new BlockPos(i + 2, j + 5, k + 3), TriniaBlocks.triniaDirt.getDefaultState());
		world.setBlockState(new BlockPos(i + 2, j + 5, k + 4), TriniaBlocks.triniaChiseledStoneBrick.getDefaultState());
		world.setBlockState(new BlockPos(i + 2, j + 5, k + 5), TriniaBlocks.triniaStoneBrick.getDefaultState());
		world.setBlockState(new BlockPos(i + 2, j + 5, k + 6), TriniaBlocks.triniaChiseledStoneBrick.getDefaultState());
		world.setBlockState(new BlockPos(i + 2, j + 5, k + 7), TriniaBlocks.triniaDirt.getDefaultState());
		world.setBlockState(new BlockPos(i + 2, j + 5, k + 8), TriniaBlocks.triniaDirt.getDefaultState());
		world.setBlockState(new BlockPos(i + 2, j + 6, k + 2), TriniaBlocks.triniaStoneBrick.getDefaultState());
		world.setBlockState(new BlockPos(i + 2, j + 6, k + 3), TriniaBlocks.triniaStoneBrick.getDefaultState());
		world.setBlockState(new BlockPos(i + 2, j + 6, k + 7), TriniaBlocks.triniaStoneBrick.getDefaultState());
		world.setBlockState(new BlockPos(i + 2, j + 6, k + 8), TriniaBlocks.triniaStoneBrick.getDefaultState());
		world.setBlockState(new BlockPos(i + 2, j + 7, k + 2), TriniaBlocks.triniaStoneBrick.getDefaultState());
		world.setBlockState(new BlockPos(i + 2, j + 7, k + 3), TriniaBlocks.triniaStoneBrick.getDefaultState());
		world.setBlockState(new BlockPos(i + 2, j + 7, k + 7), TriniaBlocks.triniaStoneBrick.getDefaultState());
		world.setBlockState(new BlockPos(i + 2, j + 7, k + 8), TriniaBlocks.triniaStoneBrick.getDefaultState());
		world.setBlockState(new BlockPos(i + 2, j + 8, k + 3), TriniaBlocks.triniaStoneBrick.getDefaultState());
		world.setBlockState(new BlockPos(i + 2, j + 8, k + 4), TriniaBlocks.triniaStoneBrick.getDefaultState());
		world.setBlockState(new BlockPos(i + 2, j + 8, k + 5), TriniaBlocks.triniaStoneBrick.getDefaultState());
		world.setBlockState(new BlockPos(i + 2, j + 8, k + 6), TriniaBlocks.triniaStoneBrick.getDefaultState());
		world.setBlockState(new BlockPos(i + 2, j + 8, k + 7), TriniaBlocks.triniaStoneBrick.getDefaultState());
		world.setBlockState(new BlockPos(i + 2, j + 9, k + 4), TriniaBlocks.triniaStoneBrick.getDefaultState());
		world.setBlockState(new BlockPos(i + 2, j + 9, k + 6), TriniaBlocks.triniaStoneBrick.getDefaultState());
		world.setBlockState(new BlockPos(i + 2, j + 10, k + 4), TriniaBlocks.triniaStoneBrick.getDefaultState());
		world.setBlockState(new BlockPos(i + 2, j + 10, k + 6), TriniaBlocks.triniaStoneBrick.getDefaultState());
		world.setBlockState(new BlockPos(i + 2, j + 11, k + 3), TriniaBlocks.triniaStoneBrick.getDefaultState());
		world.setBlockState(new BlockPos(i + 2, j + 11, k + 4), TriniaBlocks.triniaStoneBrick.getDefaultState());
		world.setBlockState(new BlockPos(i + 2, j + 11, k + 5), TriniaBlocks.triniaStoneBrick.getDefaultState());
		world.setBlockState(new BlockPos(i + 2, j + 11, k + 6), TriniaBlocks.triniaStoneBrick.getDefaultState());
		world.setBlockState(new BlockPos(i + 2, j + 11, k + 7), TriniaBlocks.triniaStoneBrick.getDefaultState());
		world.setBlockState(new BlockPos(i + 2, j + 12, k + 3), TriniaBlocks.triniaStoneBrick.getDefaultState());
		world.setBlockState(new BlockPos(i + 2, j + 12, k + 4), TriniaBlocks.triniaStoneBrick.getDefaultState());
		world.setBlockState(new BlockPos(i + 2, j + 12, k + 6), TriniaBlocks.triniaStoneBrick.getDefaultState());
		world.setBlockState(new BlockPos(i + 2, j + 12, k + 7), TriniaBlocks.triniaStoneBrick.getDefaultState());
		world.setBlockState(new BlockPos(i + 2, j + 13, k + 3), TriniaBlocks.triniaStoneBrick.getDefaultState());
		world.setBlockState(new BlockPos(i + 2, j + 13, k + 4), TriniaBlocks.triniaStoneBrick.getDefaultState());
		world.setBlockState(new BlockPos(i + 2, j + 13, k + 5), TriniaBlocks.triniaStoneBrick.getDefaultState());
		world.setBlockState(new BlockPos(i + 2, j + 13, k + 6), TriniaBlocks.triniaStoneBrick.getDefaultState());
		world.setBlockState(new BlockPos(i + 2, j + 13, k + 7), TriniaBlocks.triniaStoneBrick.getDefaultState());
		world.setBlockState(new BlockPos(i + 2, j + 14, k + 2), TriniaBlocks.triniaStoneBrick.getDefaultState());
		world.setBlockState(new BlockPos(i + 2, j + 14, k + 3), TriniaBlocks.triniaStoneBrick.getDefaultState());
		world.setBlockState(new BlockPos(i + 2, j + 14, k + 4), TriniaBlocks.triniaStoneBrick.getDefaultState());
		world.setBlockState(new BlockPos(i + 2, j + 14, k + 6), TriniaBlocks.triniaStoneBrick.getDefaultState());
		world.setBlockState(new BlockPos(i + 2, j + 14, k + 7), TriniaBlocks.triniaStoneBrick.getDefaultState());
		world.setBlockState(new BlockPos(i + 2, j + 14, k + 8), TriniaBlocks.triniaStoneBrick.getDefaultState());
		world.setBlockState(new BlockPos(i + 2, j + 15, k + 3), TriniaBlocks.triniaStoneBrick.getDefaultState());
		world.setBlockState(new BlockPos(i + 2, j + 15, k + 5), TriniaBlocks.triniaStoneBrick.getDefaultState());
		world.setBlockState(new BlockPos(i + 2, j + 15, k + 7), TriniaBlocks.triniaStoneBrick.getDefaultState());
		world.setBlockState(new BlockPos(i + 3, j + 2, k + 4), TriniaBlocks.triniaDirt.getDefaultState());
		world.setBlockState(new BlockPos(i + 3, j + 2, k + 5), TriniaBlocks.triniaChiseledStoneBrick.getDefaultState());
		world.setBlockState(new BlockPos(i + 3, j + 2, k + 6), TriniaBlocks.triniaChiseledStoneBrick.getDefaultState());
		world.setBlockState(new BlockPos(i + 3, j + 2, k + 7), TriniaBlocks.triniaDirt.getDefaultState());
		world.setBlockState(new BlockPos(i + 3, j + 3, k + 3), TriniaBlocks.triniaDirt.getDefaultState());
		world.setBlockState(new BlockPos(i + 3, j + 3, k + 4), TriniaBlocks.triniaDirt.getDefaultState());
		world.setBlockState(new BlockPos(i + 3, j + 3, k + 5), TriniaBlocks.triniaDirt.getDefaultState());
		world.setBlockState(new BlockPos(i + 3, j + 3, k + 6), TriniaBlocks.triniaDirt.getDefaultState());
		world.setBlockState(new BlockPos(i + 3, j + 3, k + 7), TriniaBlocks.triniaDirt.getDefaultState());
		world.setBlockState(new BlockPos(i + 3, j + 4, k + 2), TriniaBlocks.triniaDirt.getDefaultState());
		world.setBlockState(new BlockPos(i + 3, j + 4, k + 3), TriniaBlocks.triniaGrass.getDefaultState());
		world.setBlockState(new BlockPos(i + 3, j + 4, k + 4), TriniaBlocks.triniaGrass.getDefaultState());
		world.setBlockState(new BlockPos(i + 3, j + 4, k + 5), TriniaBlocks.triniaGrass.getDefaultState());
		world.setBlockState(new BlockPos(i + 3, j + 4, k + 6), TriniaBlocks.triniaGrass.getDefaultState());
		world.setBlockState(new BlockPos(i + 3, j + 4, k + 7), TriniaBlocks.triniaGrass.getDefaultState());
		world.setBlockState(new BlockPos(i + 3, j + 4, k + 8), TriniaBlocks.triniaDirt.getDefaultState());
		world.setBlockState(new BlockPos(i + 3, j + 4, k + 9), TriniaBlocks.triniaDirt.getDefaultState());
		world.setBlockState(new BlockPos(i + 3, j + 5, k + 1), TriniaBlocks.triniaDirt.getDefaultState());
		world.setBlockState(new BlockPos(i + 3, j + 5, k + 2), TriniaBlocks.triniaDirt.getDefaultState());
		world.setBlockState(new BlockPos(i + 3, j + 5, k + 3), TriniaBlocks.triniaStoneBrick.getDefaultState());
		world.setBlockState(new BlockPos(i + 3, j + 5, k + 4), TriniaBlocks.triniaStoneBrick.getDefaultState());
		world.setBlockState(new BlockPos(i + 3, j + 5, k + 5), TriniaBlocks.triniaStoneBrick.getDefaultState());
		world.setBlockState(new BlockPos(i + 3, j + 5, k + 6), TriniaBlocks.triniaStoneBrick.getDefaultState());
		world.setBlockState(new BlockPos(i + 3, j + 5, k + 7), TriniaBlocks.triniaStoneBrick.getDefaultState());
		world.setBlockState(new BlockPos(i + 3, j + 5, k + 8), TriniaBlocks.triniaDirt.getDefaultState());
		world.setBlockState(new BlockPos(i + 3, j + 5, k + 9), TriniaBlocks.triniaDirt.getDefaultState());
		world.setBlockState(new BlockPos(i + 3, j + 6, k + 1), TriniaBlocks.triniaStoneBrick.getDefaultState());
		world.setBlockState(new BlockPos(i + 3, j + 6, k + 2), TriniaBlocks.triniaStoneBrick.getDefaultState());
		world.setBlockState(new BlockPos(i + 3, j + 6, k + 8), TriniaBlocks.triniaStoneBrick.getDefaultState());
		world.setBlockState(new BlockPos(i + 3, j + 6, k + 9), TriniaBlocks.triniaStoneBrick.getDefaultState());
		world.setBlockState(new BlockPos(i + 3, j + 7, k + 1), TriniaBlocks.triniaStoneBrick.getDefaultState());
		world.setBlockState(new BlockPos(i + 3, j + 7, k + 2), TriniaBlocks.triniaStoneBrick.getDefaultState());
		world.setBlockState(new BlockPos(i + 3, j + 7, k + 8), TriniaBlocks.triniaStoneBrick.getDefaultState());
		world.setBlockState(new BlockPos(i + 3, j + 7, k + 9), TriniaBlocks.triniaStoneBrick.getDefaultState());
		world.setBlockState(new BlockPos(i + 3, j + 8, k + 2), TriniaBlocks.triniaStoneBrick.getDefaultState());
		world.setBlockState(new BlockPos(i + 3, j + 8, k + 8), TriniaBlocks.triniaStoneBrick.getDefaultState());
		world.setBlockState(new BlockPos(i + 3, j + 9, k + 3), TriniaBlocks.triniaStoneBrick.getDefaultState());
		world.setBlockState(new BlockPos(i + 3, j + 9, k + 7), TriniaBlocks.triniaStoneBrick.getDefaultState());
		world.setBlockState(new BlockPos(i + 3, j + 10, k + 3), TriniaBlocks.triniaStoneBrick.getDefaultState());
		world.setBlockState(new BlockPos(i + 3, j + 10, k + 7), TriniaBlocks.triniaStoneBrick.getDefaultState());
		world.setBlockState(new BlockPos(i + 3, j + 11, k + 2), TriniaBlocks.triniaStoneBrick.getDefaultState());
		world.setBlockState(new BlockPos(i + 3, j + 11, k + 3), TriniaBlocks.triniaStoneBrick.getDefaultState());
		world.setBlockState(new BlockPos(i + 3, j + 11, k + 7), TriniaBlocks.triniaStoneBrick.getDefaultState());
		world.setBlockState(new BlockPos(i + 3, j + 11, k + 8), TriniaBlocks.triniaStoneBrick.getDefaultState());
		world.setBlockState(new BlockPos(i + 3, j + 12, k + 2), TriniaBlocks.triniaStoneBrick.getDefaultState());
		world.setBlockState(new BlockPos(i + 3, j + 12, k + 8), TriniaBlocks.triniaStoneBrick.getDefaultState());
		world.setBlockState(new BlockPos(i + 3, j + 13, k + 2), TriniaBlocks.triniaStoneBrick.getDefaultState());
		world.setBlockState(new BlockPos(i + 3, j + 13, k + 8), TriniaBlocks.triniaStoneBrick.getDefaultState());
		world.setBlockState(new BlockPos(i + 3, j + 14, k + 1), TriniaBlocks.triniaStoneBrick.getDefaultState());
		world.setBlockState(new BlockPos(i + 3, j + 14, k + 2), TriniaBlocks.triniaStoneBrick.getDefaultState());
		world.setBlockState(new BlockPos(i + 3, j + 14, k + 8), TriniaBlocks.triniaStoneBrick.getDefaultState());
		world.setBlockState(new BlockPos(i + 3, j + 14, k + 9), TriniaBlocks.triniaStoneBrick.getDefaultState());
		world.setBlockState(new BlockPos(i + 3, j + 15, k + 2), TriniaBlocks.triniaStoneBrick.getDefaultState());
		world.setBlockState(new BlockPos(i + 3, j + 15, k + 8), TriniaBlocks.triniaStoneBrick.getDefaultState());
		world.setBlockState(new BlockPos(i + 4, j + 1, k + 5), TriniaBlocks.triniaChiseledStoneBrick.getDefaultState());
		world.setBlockState(new BlockPos(i + 4, j + 1, k + 6), TriniaBlocks.triniaChiseledStoneBrick.getDefaultState());
		world.setBlockState(new BlockPos(i + 4, j + 2, k + 3), TriniaBlocks.triniaChiseledStoneBrick.getDefaultState());
		world.setBlockState(new BlockPos(i + 4, j + 2, k + 4), TriniaBlocks.triniaChiseledStoneBrick.getDefaultState());
		world.setBlockState(new BlockPos(i + 4, j + 2, k + 5), TriniaBlocks.triniaChiseledStoneBrick.getDefaultState());
		world.setBlockState(new BlockPos(i + 4, j + 2, k + 6), TriniaBlocks.triniaChiseledStoneBrick.getDefaultState());
		world.setBlockState(new BlockPos(i + 4, j + 2, k + 7), TriniaBlocks.triniaChiseledStoneBrick.getDefaultState());
		world.setBlockState(new BlockPos(i + 4, j + 2, k + 8), TriniaBlocks.triniaDirt.getDefaultState());
		world.setBlockState(new BlockPos(i + 4, j + 3, k + 2), TriniaBlocks.triniaDirt.getDefaultState());
		world.setBlockState(new BlockPos(i + 4, j + 3, k + 3), TriniaBlocks.triniaDirt.getDefaultState());
		world.setBlockState(new BlockPos(i + 4, j + 3, k + 4), TriniaBlocks.triniaDirt.getDefaultState());
		world.setBlockState(new BlockPos(i + 4, j + 3, k + 5), TriniaBlocks.triniaDirt.getDefaultState());
		world.setBlockState(new BlockPos(i + 4, j + 3, k + 6), TriniaBlocks.triniaDirt.getDefaultState());
		world.setBlockState(new BlockPos(i + 4, j + 3, k + 7), TriniaBlocks.triniaDirt.getDefaultState());
		world.setBlockState(new BlockPos(i + 4, j + 3, k + 8), TriniaBlocks.triniaDirt.getDefaultState());
		world.setBlockState(new BlockPos(i + 4, j + 4, k + 1), TriniaBlocks.triniaGrass.getDefaultState());
		world.setBlockState(new BlockPos(i + 4, j + 4, k + 2), TriniaBlocks.triniaGrass.getDefaultState());
		world.setBlockState(new BlockPos(i + 4, j + 4, k + 3), TriniaBlocks.triniaGrass.getDefaultState());
		world.setBlockState(new BlockPos(i + 4, j + 4, k + 4), TriniaBlocks.triniaGrass.getDefaultState());
		world.setBlockState(new BlockPos(i + 4, j + 4, k + 5), TriniaBlocks.triniaGrass.getDefaultState());
		world.setBlockState(new BlockPos(i + 4, j + 4, k + 6), TriniaBlocks.triniaGrass.getDefaultState());
		world.setBlockState(new BlockPos(i + 4, j + 4, k + 7), TriniaBlocks.triniaGrass.getDefaultState());
		world.setBlockState(new BlockPos(i + 4, j + 4, k + 8), TriniaBlocks.triniaGrass.getDefaultState());
		world.setBlockState(new BlockPos(i + 4, j + 4, k + 9), TriniaBlocks.triniaGrass.getDefaultState());
		world.setBlockState(new BlockPos(i + 4, j + 5, k + 1), TriniaBlocks.triniaChiseledStoneBrick.getDefaultState());
		world.setBlockState(new BlockPos(i + 4, j + 5, k + 2), TriniaBlocks.triniaChiseledStoneBrick.getDefaultState());
		world.setBlockState(new BlockPos(i + 4, j + 5, k + 3), TriniaBlocks.triniaStoneBrick.getDefaultState());
		world.setBlockState(new BlockPos(i + 4, j + 5, k + 4), TriniaBlocks.triniaChiseledStoneBrick.getDefaultState());
		world.setBlockState(new BlockPos(i + 4, j + 5, k + 5), TriniaBlocks.triniaChiseledStoneBrick.getDefaultState());
		world.setBlockState(new BlockPos(i + 4, j + 5, k + 6), TriniaBlocks.triniaChiseledStoneBrick.getDefaultState());
		world.setBlockState(new BlockPos(i + 4, j + 5, k + 7), TriniaBlocks.triniaStoneBrick.getDefaultState());
		world.setBlockState(new BlockPos(i + 4, j + 5, k + 8), TriniaBlocks.triniaChiseledStoneBrick.getDefaultState());
		world.setBlockState(new BlockPos(i + 4, j + 5, k + 9), TriniaBlocks.triniaChiseledStoneBrick.getDefaultState());
		world.setBlockState(new BlockPos(i + 4, j + 8, k + 1), TriniaBlocks.triniaStoneBrick.getDefaultState());
		world.setBlockState(new BlockPos(i + 4, j + 8, k + 2), TriniaBlocks.triniaStoneBrick.getDefaultState());
		world.setBlockState(new BlockPos(i + 4, j + 8, k + 8), TriniaBlocks.triniaStoneBrick.getDefaultState());
		world.setBlockState(new BlockPos(i + 4, j + 8, k + 9), TriniaBlocks.triniaStoneBrick.getDefaultState());
		world.setBlockState(new BlockPos(i + 4, j + 9, k + 2), TriniaBlocks.triniaStoneBrick.getDefaultState());
		world.setBlockState(new BlockPos(i + 4, j + 9, k + 8), TriniaBlocks.triniaStoneBrick.getDefaultState());
		world.setBlockState(new BlockPos(i + 4, j + 10, k + 2), TriniaBlocks.triniaStoneBrick.getDefaultState());
		world.setBlockState(new BlockPos(i + 4, j + 10, k + 8), TriniaBlocks.triniaStoneBrick.getDefaultState());
		world.setBlockState(new BlockPos(i + 4, j + 11, k + 1), TriniaBlocks.triniaStoneBrick.getDefaultState());
		world.setBlockState(new BlockPos(i + 4, j + 11, k + 2), TriniaBlocks.triniaStoneBrick.getDefaultState());
		world.setBlockState(new BlockPos(i + 4, j + 11, k + 8), TriniaBlocks.triniaStoneBrick.getDefaultState());
		world.setBlockState(new BlockPos(i + 4, j + 11, k + 9), TriniaBlocks.triniaStoneBrick.getDefaultState());
		world.setBlockState(new BlockPos(i + 4, j + 12, k + 2), TriniaBlocks.triniaStoneBrick.getDefaultState());
		world.setBlockState(new BlockPos(i + 4, j + 12, k + 8), TriniaBlocks.triniaStoneBrick.getDefaultState());
		world.setBlockState(new BlockPos(i + 4, j + 13, k + 1), TriniaBlocks.triniaStoneBrick.getDefaultState());
		world.setBlockState(new BlockPos(i + 4, j + 13, k + 2), TriniaBlocks.triniaStoneBrick.getDefaultState());
		world.setBlockState(new BlockPos(i + 4, j + 13, k + 8), TriniaBlocks.triniaStoneBrick.getDefaultState());
		world.setBlockState(new BlockPos(i + 4, j + 13, k + 9), TriniaBlocks.triniaStoneBrick.getDefaultState());
		world.setBlockState(new BlockPos(i + 4, j + 14, k + 0), TriniaBlocks.triniaStoneBrick.getDefaultState());
		world.setBlockState(new BlockPos(i + 4, j + 14, k + 1), TriniaBlocks.triniaStoneBrick.getDefaultState());
		world.setBlockState(new BlockPos(i + 4, j + 14, k + 2), TriniaBlocks.triniaStoneBrick.getDefaultState());
		world.setBlockState(new BlockPos(i + 4, j + 14, k + 8), TriniaBlocks.triniaStoneBrick.getDefaultState());
		world.setBlockState(new BlockPos(i + 4, j + 14, k + 9), TriniaBlocks.triniaStoneBrick.getDefaultState());
		world.setBlockState(new BlockPos(i + 4, j + 14, k + 10), TriniaBlocks.triniaStoneBrick.getDefaultState());
		world.setBlockState(new BlockPos(i + 4, j + 15, k + 1), TriniaBlocks.triniaStoneBrick.getDefaultState());
		world.setBlockState(new BlockPos(i + 4, j + 15, k + 9), TriniaBlocks.triniaStoneBrick.getDefaultState());
		world.setBlockState(new BlockPos(i + 5, j + 0, k + 5), TriniaBlocks.triniaChiseledStoneBrick.getDefaultState());
		world.setBlockState(new BlockPos(i + 5, j + 1, k + 4), TriniaBlocks.triniaChiseledStoneBrick.getDefaultState());
		world.setBlockState(new BlockPos(i + 5, j + 1, k + 5), TriniaBlocks.triniaChiseledStoneBrick.getDefaultState());
		world.setBlockState(new BlockPos(i + 5, j + 1, k + 6), TriniaBlocks.triniaChiseledStoneBrick.getDefaultState());
		world.setBlockState(new BlockPos(i + 5, j + 1, k + 7), TriniaBlocks.triniaChiseledStoneBrick.getDefaultState());
		world.setBlockState(new BlockPos(i + 5, j + 2, k + 2), TriniaBlocks.triniaDirt.getDefaultState());
		world.setBlockState(new BlockPos(i + 5, j + 2, k + 3), TriniaBlocks.triniaChiseledStoneBrick.getDefaultState());
		world.setBlockState(new BlockPos(i + 5, j + 2, k + 4), TriniaBlocks.triniaChiseledStoneBrick.getDefaultState());
		world.setBlockState(new BlockPos(i + 5, j + 2, k + 5), TriniaBlocks.triniaChiseledStoneBrick.getDefaultState());
		world.setBlockState(new BlockPos(i + 5, j + 2, k + 6), TriniaBlocks.triniaChiseledStoneBrick.getDefaultState());
		world.setBlockState(new BlockPos(i + 5, j + 2, k + 7), TriniaBlocks.triniaChiseledStoneBrick.getDefaultState());
		world.setBlockState(new BlockPos(i + 5, j + 2, k + 8), TriniaBlocks.triniaChiseledStoneBrick.getDefaultState());
		world.setBlockState(new BlockPos(i + 5, j + 3, k + 1), TriniaBlocks.triniaDirt.getDefaultState());
		world.setBlockState(new BlockPos(i + 5, j + 3, k + 2), TriniaBlocks.triniaDirt.getDefaultState());
		world.setBlockState(new BlockPos(i + 5, j + 3, k + 3), TriniaBlocks.triniaDirt.getDefaultState());
		world.setBlockState(new BlockPos(i + 5, j + 3, k + 4), TriniaBlocks.triniaDirt.getDefaultState());
		world.setBlockState(new BlockPos(i + 5, j + 3, k + 5), TriniaBlocks.triniaDirt.getDefaultState());
		world.setBlockState(new BlockPos(i + 5, j + 3, k + 6), TriniaBlocks.triniaDirt.getDefaultState());
		world.setBlockState(new BlockPos(i + 5, j + 3, k + 7), TriniaBlocks.triniaDirt.getDefaultState());
		world.setBlockState(new BlockPos(i + 5, j + 3, k + 8), TriniaBlocks.triniaDirt.getDefaultState());
		world.setBlockState(new BlockPos(i + 5, j + 3, k + 9), TriniaBlocks.triniaDirt.getDefaultState());
		world.setBlockState(new BlockPos(i + 5, j + 4, k + 0), TriniaBlocks.triniaGrass.getDefaultState());
		world.setBlockState(new BlockPos(i + 5, j + 4, k + 1), TriniaBlocks.triniaGrass.getDefaultState());
		world.setBlockState(new BlockPos(i + 5, j + 4, k + 2), TriniaBlocks.triniaGrass.getDefaultState());
		world.setBlockState(new BlockPos(i + 5, j + 4, k + 3), TriniaBlocks.triniaGrass.getDefaultState());
		world.setBlockState(new BlockPos(i + 5, j + 4, k + 4), TriniaBlocks.triniaGrass.getDefaultState());
		world.setBlockState(new BlockPos(i + 5, j + 4, k + 5), TriniaBlocks.triniaGrass.getDefaultState());
		world.setBlockState(new BlockPos(i + 5, j + 4, k + 6), TriniaBlocks.triniaGrass.getDefaultState());
		world.setBlockState(new BlockPos(i + 5, j + 4, k + 7), TriniaBlocks.triniaGrass.getDefaultState());
		world.setBlockState(new BlockPos(i + 5, j + 4, k + 8), TriniaBlocks.triniaGrass.getDefaultState());
		world.setBlockState(new BlockPos(i + 5, j + 4, k + 9), TriniaBlocks.triniaGrass.getDefaultState());
		world.setBlockState(new BlockPos(i + 5, j + 4, k + 10), TriniaBlocks.triniaGrass.getDefaultState());
		world.setBlockState(new BlockPos(i + 5, j + 5, k + 1), TriniaBlocks.triniaChiseledStoneBrick.getDefaultState());
		world.setBlockState(new BlockPos(i + 5, j + 5, k + 2), TriniaBlocks.triniaStoneBrick.getDefaultState());
		world.setBlockState(new BlockPos(i + 5, j + 5, k + 3), TriniaBlocks.triniaStoneBrick.getDefaultState());
		world.setBlockState(new BlockPos(i + 5, j + 5, k + 4), TriniaBlocks.triniaChiseledStoneBrick.getDefaultState());
		world.setBlockState(new BlockPos(i + 5, j + 5, k + 5), TriniaBlocks.triniaStoneBrick.getDefaultState());
		world.setBlockState(new BlockPos(i + 5, j + 5, k + 6), TriniaBlocks.triniaChiseledStoneBrick.getDefaultState());
		world.setBlockState(new BlockPos(i + 5, j + 5, k + 7), TriniaBlocks.triniaStoneBrick.getDefaultState());
		world.setBlockState(new BlockPos(i + 5, j + 5, k + 8), TriniaBlocks.triniaStoneBrick.getDefaultState());
		world.setBlockState(new BlockPos(i + 5, j + 5, k + 9), TriniaBlocks.triniaChiseledStoneBrick.getDefaultState());
		world.setBlockState(new BlockPos(i + 5, j + 8, k + 1), TriniaBlocks.triniaStoneBrick.getDefaultState());
		world.setBlockState(new BlockPos(i + 5, j + 8, k + 2), TriniaBlocks.triniaStoneBrick.getDefaultState());
		world.setBlockState(new BlockPos(i + 5, j + 8, k + 8), TriniaBlocks.triniaStoneBrick.getDefaultState());
		world.setBlockState(new BlockPos(i + 5, j + 8, k + 9), TriniaBlocks.triniaStoneBrick.getDefaultState());
		world.setBlockState(new BlockPos(i + 5, j + 11, k + 1), TriniaBlocks.triniaStoneBrick.getDefaultState());
		world.setBlockState(new BlockPos(i + 5, j + 11, k + 2), TriniaBlocks.triniaStoneBrick.getDefaultState());
		world.setBlockState(new BlockPos(i + 5, j + 11, k + 8), TriniaBlocks.triniaStoneBrick.getDefaultState());
		world.setBlockState(new BlockPos(i + 5, j + 11, k + 9), TriniaBlocks.triniaStoneBrick.getDefaultState());
		world.setBlockState(new BlockPos(i + 5, j + 13, k + 1), TriniaBlocks.triniaStoneBrick.getDefaultState());
		world.setBlockState(new BlockPos(i + 5, j + 13, k + 2), TriniaBlocks.triniaStoneBrick.getDefaultState());
		world.setBlockState(new BlockPos(i + 5, j + 13, k + 8), TriniaBlocks.triniaStoneBrick.getDefaultState());
		world.setBlockState(new BlockPos(i + 5, j + 13, k + 9), TriniaBlocks.triniaStoneBrick.getDefaultState());
		world.setBlockState(new BlockPos(i + 5, j + 14, k + 0), TriniaBlocks.triniaStoneBrick.getDefaultState());
		world.setBlockState(new BlockPos(i + 5, j + 14, k + 1), TriniaBlocks.triniaStoneBrick.getDefaultState());
		world.setBlockState(new BlockPos(i + 5, j + 14, k + 9), TriniaBlocks.triniaStoneBrick.getDefaultState());
		world.setBlockState(new BlockPos(i + 5, j + 14, k + 10), TriniaBlocks.triniaStoneBrick.getDefaultState());
		world.setBlockState(new BlockPos(i + 5, j + 15, k + 1), TriniaBlocks.triniaStoneBrick.getDefaultState());
		world.setBlockState(new BlockPos(i + 5, j + 15, k + 2), TriniaBlocks.triniaStoneBrick.getDefaultState());
		world.setBlockState(new BlockPos(i + 5, j + 15, k + 8), TriniaBlocks.triniaStoneBrick.getDefaultState());
		world.setBlockState(new BlockPos(i + 5, j + 15, k + 9), TriniaBlocks.triniaStoneBrick.getDefaultState());
		world.setBlockState(new BlockPos(i + 6, j + 1, k + 5), TriniaBlocks.triniaChiseledStoneBrick.getDefaultState());
		world.setBlockState(new BlockPos(i + 6, j + 1, k + 6), TriniaBlocks.triniaChiseledStoneBrick.getDefaultState());
		world.setBlockState(new BlockPos(i + 6, j + 2, k + 2), TriniaBlocks.triniaChiseledStoneBrick.getDefaultState());
		world.setBlockState(new BlockPos(i + 6, j + 2, k + 3), TriniaBlocks.triniaChiseledStoneBrick.getDefaultState());
		world.setBlockState(new BlockPos(i + 6, j + 2, k + 4), TriniaBlocks.triniaChiseledStoneBrick.getDefaultState());
		world.setBlockState(new BlockPos(i + 6, j + 2, k + 5), TriniaBlocks.triniaChiseledStoneBrick.getDefaultState());
		world.setBlockState(new BlockPos(i + 6, j + 2, k + 6), TriniaBlocks.triniaChiseledStoneBrick.getDefaultState());
		world.setBlockState(new BlockPos(i + 6, j + 2, k + 7), TriniaBlocks.triniaChiseledStoneBrick.getDefaultState());
		world.setBlockState(new BlockPos(i + 6, j + 3, k + 1), TriniaBlocks.triniaDirt.getDefaultState());
		world.setBlockState(new BlockPos(i + 6, j + 3, k + 2), TriniaBlocks.triniaDirt.getDefaultState());
		world.setBlockState(new BlockPos(i + 6, j + 3, k + 3), TriniaBlocks.triniaDirt.getDefaultState());
		world.setBlockState(new BlockPos(i + 6, j + 3, k + 4), TriniaBlocks.triniaDirt.getDefaultState());
		world.setBlockState(new BlockPos(i + 6, j + 3, k + 5), TriniaBlocks.triniaDirt.getDefaultState());
		world.setBlockState(new BlockPos(i + 6, j + 3, k + 6), TriniaBlocks.triniaDirt.getDefaultState());
		world.setBlockState(new BlockPos(i + 6, j + 3, k + 7), TriniaBlocks.triniaDirt.getDefaultState());
		world.setBlockState(new BlockPos(i + 6, j + 3, k + 8), TriniaBlocks.triniaDirt.getDefaultState());
		world.setBlockState(new BlockPos(i + 6, j + 4, k + 0), TriniaBlocks.triniaGrass.getDefaultState());
		world.setBlockState(new BlockPos(i + 6, j + 4, k + 1), TriniaBlocks.triniaGrass.getDefaultState());
		world.setBlockState(new BlockPos(i + 6, j + 4, k + 2), TriniaBlocks.triniaGrass.getDefaultState());
		world.setBlockState(new BlockPos(i + 6, j + 4, k + 3), TriniaBlocks.triniaGrass.getDefaultState());
		world.setBlockState(new BlockPos(i + 6, j + 4, k + 4), TriniaBlocks.triniaGrass.getDefaultState());
		world.setBlockState(new BlockPos(i + 6, j + 4, k + 5), TriniaBlocks.triniaGrass.getDefaultState());
		world.setBlockState(new BlockPos(i + 6, j + 4, k + 6), TriniaBlocks.triniaGrass.getDefaultState());
		world.setBlockState(new BlockPos(i + 6, j + 4, k + 7), TriniaBlocks.triniaGrass.getDefaultState());
		world.setBlockState(new BlockPos(i + 6, j + 4, k + 8), TriniaBlocks.triniaGrass.getDefaultState());
		world.setBlockState(new BlockPos(i + 6, j + 4, k + 9), TriniaBlocks.triniaGrass.getDefaultState());
		world.setBlockState(new BlockPos(i + 6, j + 4, k + 10), TriniaBlocks.triniaGrass.getDefaultState());
		world.setBlockState(new BlockPos(i + 6, j + 5, k + 1), TriniaBlocks.triniaChiseledStoneBrick.getDefaultState());
		world.setBlockState(new BlockPos(i + 6, j + 5, k + 2), TriniaBlocks.triniaChiseledStoneBrick.getDefaultState());
		world.setBlockState(new BlockPos(i + 6, j + 5, k + 3), TriniaBlocks.triniaStoneBrick.getDefaultState());
		world.setBlockState(new BlockPos(i + 6, j + 5, k + 4), TriniaBlocks.triniaChiseledStoneBrick.getDefaultState());
		world.setBlockState(new BlockPos(i + 6, j + 5, k + 5), TriniaBlocks.triniaChiseledStoneBrick.getDefaultState());
		world.setBlockState(new BlockPos(i + 6, j + 5, k + 6), TriniaBlocks.triniaChiseledStoneBrick.getDefaultState());
		world.setBlockState(new BlockPos(i + 6, j + 5, k + 7), TriniaBlocks.triniaStoneBrick.getDefaultState());
		world.setBlockState(new BlockPos(i + 6, j + 5, k + 8), TriniaBlocks.triniaChiseledStoneBrick.getDefaultState());
		world.setBlockState(new BlockPos(i + 6, j + 5, k + 9), TriniaBlocks.triniaChiseledStoneBrick.getDefaultState());
		world.setBlockState(new BlockPos(i + 6, j + 8, k + 1), TriniaBlocks.triniaStoneBrick.getDefaultState());
		world.setBlockState(new BlockPos(i + 6, j + 8, k + 2), TriniaBlocks.triniaStoneBrick.getDefaultState());
		world.setBlockState(new BlockPos(i + 6, j + 8, k + 8), TriniaBlocks.triniaStoneBrick.getDefaultState());
		world.setBlockState(new BlockPos(i + 6, j + 8, k + 9), TriniaBlocks.triniaStoneBrick.getDefaultState());
		world.setBlockState(new BlockPos(i + 6, j + 9, k + 2), TriniaBlocks.triniaStoneBrick.getDefaultState());
		world.setBlockState(new BlockPos(i + 6, j + 9, k + 8), TriniaBlocks.triniaStoneBrick.getDefaultState());
		world.setBlockState(new BlockPos(i + 6, j + 10, k + 2), TriniaBlocks.triniaStoneBrick.getDefaultState());
		world.setBlockState(new BlockPos(i + 6, j + 10, k + 8), TriniaBlocks.triniaStoneBrick.getDefaultState());
		world.setBlockState(new BlockPos(i + 6, j + 11, k + 1), TriniaBlocks.triniaStoneBrick.getDefaultState());
		world.setBlockState(new BlockPos(i + 6, j + 11, k + 2), TriniaBlocks.triniaStoneBrick.getDefaultState());
		world.setBlockState(new BlockPos(i + 6, j + 11, k + 8), TriniaBlocks.triniaStoneBrick.getDefaultState());
		world.setBlockState(new BlockPos(i + 6, j + 11, k + 9), TriniaBlocks.triniaStoneBrick.getDefaultState());
		world.setBlockState(new BlockPos(i + 6, j + 12, k + 2), TriniaBlocks.triniaStoneBrick.getDefaultState());
		world.setBlockState(new BlockPos(i + 6, j + 12, k + 8), TriniaBlocks.triniaStoneBrick.getDefaultState());
		world.setBlockState(new BlockPos(i + 6, j + 13, k + 1), TriniaBlocks.triniaStoneBrick.getDefaultState());
		world.setBlockState(new BlockPos(i + 6, j + 13, k + 2), TriniaBlocks.triniaStoneBrick.getDefaultState());
		world.setBlockState(new BlockPos(i + 6, j + 13, k + 8), TriniaBlocks.triniaStoneBrick.getDefaultState());
		world.setBlockState(new BlockPos(i + 6, j + 13, k + 9), TriniaBlocks.triniaStoneBrick.getDefaultState());
		world.setBlockState(new BlockPos(i + 6, j + 14, k + 0), TriniaBlocks.triniaStoneBrick.getDefaultState());
		world.setBlockState(new BlockPos(i + 6, j + 14, k + 1), TriniaBlocks.triniaStoneBrick.getDefaultState());
		world.setBlockState(new BlockPos(i + 6, j + 14, k + 2), TriniaBlocks.triniaStoneBrick.getDefaultState());
		world.setBlockState(new BlockPos(i + 6, j + 14, k + 8), TriniaBlocks.triniaStoneBrick.getDefaultState());
		world.setBlockState(new BlockPos(i + 6, j + 14, k + 9), TriniaBlocks.triniaStoneBrick.getDefaultState());
		world.setBlockState(new BlockPos(i + 6, j + 14, k + 10), TriniaBlocks.triniaStoneBrick.getDefaultState());
		world.setBlockState(new BlockPos(i + 6, j + 15, k + 1), TriniaBlocks.triniaStoneBrick.getDefaultState());
		world.setBlockState(new BlockPos(i + 6, j + 15, k + 9), TriniaBlocks.triniaStoneBrick.getDefaultState());
		world.setBlockState(new BlockPos(i + 7, j + 1, k + 5), TriniaBlocks.triniaChiseledStoneBrick.getDefaultState());
		world.setBlockState(new BlockPos(i + 7, j + 2, k + 3), TriniaBlocks.triniaDirt.getDefaultState());
		world.setBlockState(new BlockPos(i + 7, j + 2, k + 4), TriniaBlocks.triniaChiseledStoneBrick.getDefaultState());
		world.setBlockState(new BlockPos(i + 7, j + 2, k + 5), TriniaBlocks.triniaChiseledStoneBrick.getDefaultState());
		world.setBlockState(new BlockPos(i + 7, j + 2, k + 6), TriniaBlocks.triniaChiseledStoneBrick.getDefaultState());
		world.setBlockState(new BlockPos(i + 7, j + 2, k + 7), TriniaBlocks.triniaDirt.getDefaultState());
		world.setBlockState(new BlockPos(i + 7, j + 3, k + 2), TriniaBlocks.triniaDirt.getDefaultState());
		world.setBlockState(new BlockPos(i + 7, j + 3, k + 3), TriniaBlocks.triniaDirt.getDefaultState());
		world.setBlockState(new BlockPos(i + 7, j + 3, k + 4), TriniaBlocks.triniaDirt.getDefaultState());
		world.setBlockState(new BlockPos(i + 7, j + 3, k + 5), TriniaBlocks.triniaDirt.getDefaultState());
		world.setBlockState(new BlockPos(i + 7, j + 3, k + 6), TriniaBlocks.triniaDirt.getDefaultState());
		world.setBlockState(new BlockPos(i + 7, j + 3, k + 7), TriniaBlocks.triniaDirt.getDefaultState());
		world.setBlockState(new BlockPos(i + 7, j + 4, k + 1), TriniaBlocks.triniaDirt.getDefaultState());
		world.setBlockState(new BlockPos(i + 7, j + 4, k + 2), TriniaBlocks.triniaDirt.getDefaultState());
		world.setBlockState(new BlockPos(i + 7, j + 4, k + 3), TriniaBlocks.triniaGrass.getDefaultState());
		world.setBlockState(new BlockPos(i + 7, j + 4, k + 4), TriniaBlocks.triniaGrass.getDefaultState());
		world.setBlockState(new BlockPos(i + 7, j + 4, k + 5), TriniaBlocks.triniaGrass.getDefaultState());
		world.setBlockState(new BlockPos(i + 7, j + 4, k + 6), TriniaBlocks.triniaGrass.getDefaultState());
		world.setBlockState(new BlockPos(i + 7, j + 4, k + 7), TriniaBlocks.triniaGrass.getDefaultState());
		world.setBlockState(new BlockPos(i + 7, j + 4, k + 8), TriniaBlocks.triniaDirt.getDefaultState());
		world.setBlockState(new BlockPos(i + 7, j + 4, k + 9), TriniaBlocks.triniaDirt.getDefaultState());
		world.setBlockState(new BlockPos(i + 7, j + 5, k + 1), TriniaBlocks.triniaDirt.getDefaultState());
		world.setBlockState(new BlockPos(i + 7, j + 5, k + 2), TriniaBlocks.triniaDirt.getDefaultState());
		world.setBlockState(new BlockPos(i + 7, j + 5, k + 3), TriniaBlocks.triniaStoneBrick.getDefaultState());
		world.setBlockState(new BlockPos(i + 7, j + 5, k + 4), TriniaBlocks.triniaStoneBrick.getDefaultState());
		world.setBlockState(new BlockPos(i + 7, j + 5, k + 5), TriniaBlocks.triniaStoneBrick.getDefaultState());
		world.setBlockState(new BlockPos(i + 7, j + 5, k + 6), TriniaBlocks.triniaStoneBrick.getDefaultState());
		world.setBlockState(new BlockPos(i + 7, j + 5, k + 7), TriniaBlocks.triniaStoneBrick.getDefaultState());
		world.setBlockState(new BlockPos(i + 7, j + 5, k + 8), TriniaBlocks.triniaDirt.getDefaultState());
		world.setBlockState(new BlockPos(i + 7, j + 5, k + 9), TriniaBlocks.triniaDirt.getDefaultState());
		world.setBlockState(new BlockPos(i + 7, j + 6, k + 1), TriniaBlocks.triniaStoneBrick.getDefaultState());
		world.setBlockState(new BlockPos(i + 7, j + 6, k + 2), TriniaBlocks.triniaStoneBrick.getDefaultState());
		world.setBlockState(new BlockPos(i + 7, j + 6, k + 8), TriniaBlocks.triniaStoneBrick.getDefaultState());
		world.setBlockState(new BlockPos(i + 7, j + 6, k + 9), TriniaBlocks.triniaStoneBrick.getDefaultState());
		world.setBlockState(new BlockPos(i + 7, j + 7, k + 1), TriniaBlocks.triniaStoneBrick.getDefaultState());
		world.setBlockState(new BlockPos(i + 7, j + 7, k + 2), TriniaBlocks.triniaStoneBrick.getDefaultState());
		world.setBlockState(new BlockPos(i + 7, j + 7, k + 8), TriniaBlocks.triniaStoneBrick.getDefaultState());
		world.setBlockState(new BlockPos(i + 7, j + 7, k + 9), TriniaBlocks.triniaStoneBrick.getDefaultState());
		world.setBlockState(new BlockPos(i + 7, j + 8, k + 2), TriniaBlocks.triniaStoneBrick.getDefaultState());
		world.setBlockState(new BlockPos(i + 7, j + 8, k + 8), TriniaBlocks.triniaStoneBrick.getDefaultState());
		world.setBlockState(new BlockPos(i + 7, j + 9, k + 3), TriniaBlocks.triniaStoneBrick.getDefaultState());
		world.setBlockState(new BlockPos(i + 7, j + 9, k + 7), TriniaBlocks.triniaStoneBrick.getDefaultState());
		world.setBlockState(new BlockPos(i + 7, j + 10, k + 3), TriniaBlocks.triniaStoneBrick.getDefaultState());
		world.setBlockState(new BlockPos(i + 7, j + 10, k + 7), TriniaBlocks.triniaStoneBrick.getDefaultState());
		world.setBlockState(new BlockPos(i + 7, j + 11, k + 2), TriniaBlocks.triniaStoneBrick.getDefaultState());
		world.setBlockState(new BlockPos(i + 7, j + 11, k + 3), TriniaBlocks.triniaStoneBrick.getDefaultState());
		world.setBlockState(new BlockPos(i + 7, j + 11, k + 7), TriniaBlocks.triniaStoneBrick.getDefaultState());
		world.setBlockState(new BlockPos(i + 7, j + 11, k + 8), TriniaBlocks.triniaStoneBrick.getDefaultState());
		world.setBlockState(new BlockPos(i + 7, j + 12, k + 2), TriniaBlocks.triniaStoneBrick.getDefaultState());
		world.setBlockState(new BlockPos(i + 7, j + 12, k + 8), TriniaBlocks.triniaStoneBrick.getDefaultState());
		world.setBlockState(new BlockPos(i + 7, j + 13, k + 2), TriniaBlocks.triniaStoneBrick.getDefaultState());
		world.setBlockState(new BlockPos(i + 7, j + 13, k + 8), TriniaBlocks.triniaStoneBrick.getDefaultState());
		world.setBlockState(new BlockPos(i + 7, j + 14, k + 1), TriniaBlocks.triniaStoneBrick.getDefaultState());
		world.setBlockState(new BlockPos(i + 7, j + 14, k + 2), TriniaBlocks.triniaStoneBrick.getDefaultState());
		world.setBlockState(new BlockPos(i + 7, j + 14, k + 8), TriniaBlocks.triniaStoneBrick.getDefaultState());
		world.setBlockState(new BlockPos(i + 7, j + 14, k + 9), TriniaBlocks.triniaStoneBrick.getDefaultState());
		world.setBlockState(new BlockPos(i + 7, j + 15, k + 2), TriniaBlocks.triniaStoneBrick.getDefaultState());
		world.setBlockState(new BlockPos(i + 7, j + 15, k + 8), TriniaBlocks.triniaStoneBrick.getDefaultState());
		world.setBlockState(new BlockPos(i + 8, j + 2, k + 4), TriniaBlocks.triniaDirt.getDefaultState());
		world.setBlockState(new BlockPos(i + 8, j + 2, k + 5), TriniaBlocks.triniaChiseledStoneBrick.getDefaultState());
		world.setBlockState(new BlockPos(i + 8, j + 3, k + 3), TriniaBlocks.triniaDirt.getDefaultState());
		world.setBlockState(new BlockPos(i + 8, j + 3, k + 4), TriniaBlocks.triniaDirt.getDefaultState());
		world.setBlockState(new BlockPos(i + 8, j + 3, k + 5), TriniaBlocks.triniaDirt.getDefaultState());
		world.setBlockState(new BlockPos(i + 8, j + 3, k + 6), TriniaBlocks.triniaDirt.getDefaultState());
		world.setBlockState(new BlockPos(i + 8, j + 3, k + 7), TriniaBlocks.triniaDirt.getDefaultState());
		world.setBlockState(new BlockPos(i + 8, j + 4, k + 2), TriniaBlocks.triniaDirt.getDefaultState());
		world.setBlockState(new BlockPos(i + 8, j + 4, k + 3), TriniaBlocks.triniaDirt.getDefaultState());
		world.setBlockState(new BlockPos(i + 8, j + 4, k + 4), TriniaBlocks.triniaGrass.getDefaultState());
		world.setBlockState(new BlockPos(i + 8, j + 4, k + 5), TriniaBlocks.triniaGrass.getDefaultState());
		world.setBlockState(new BlockPos(i + 8, j + 4, k + 6), TriniaBlocks.triniaGrass.getDefaultState());
		world.setBlockState(new BlockPos(i + 8, j + 4, k + 7), TriniaBlocks.triniaDirt.getDefaultState());
		world.setBlockState(new BlockPos(i + 8, j + 4, k + 8), TriniaBlocks.triniaDirt.getDefaultState());
		world.setBlockState(new BlockPos(i + 8, j + 5, k + 2), TriniaBlocks.triniaDirt.getDefaultState());
		world.setBlockState(new BlockPos(i + 8, j + 5, k + 3), TriniaBlocks.triniaDirt.getDefaultState());
		world.setBlockState(new BlockPos(i + 8, j + 5, k + 4), TriniaBlocks.triniaChiseledStoneBrick.getDefaultState());
		world.setBlockState(new BlockPos(i + 8, j + 5, k + 5), TriniaBlocks.triniaStoneBrick.getDefaultState());
		world.setBlockState(new BlockPos(i + 8, j + 5, k + 6), TriniaBlocks.triniaChiseledStoneBrick.getDefaultState());
		world.setBlockState(new BlockPos(i + 8, j + 5, k + 7), TriniaBlocks.triniaDirt.getDefaultState());
		world.setBlockState(new BlockPos(i + 8, j + 5, k + 8), TriniaBlocks.triniaDirt.getDefaultState());
		world.setBlockState(new BlockPos(i + 8, j + 6, k + 2), TriniaBlocks.triniaStoneBrick.getDefaultState());
		world.setBlockState(new BlockPos(i + 8, j + 6, k + 3), TriniaBlocks.triniaStoneBrick.getDefaultState());
		world.setBlockState(new BlockPos(i + 8, j + 6, k + 7), TriniaBlocks.triniaStoneBrick.getDefaultState());
		world.setBlockState(new BlockPos(i + 8, j + 6, k + 8), TriniaBlocks.triniaStoneBrick.getDefaultState());
		world.setBlockState(new BlockPos(i + 8, j + 7, k + 2), TriniaBlocks.triniaStoneBrick.getDefaultState());
		world.setBlockState(new BlockPos(i + 8, j + 7, k + 3), TriniaBlocks.triniaStoneBrick.getDefaultState());
		world.setBlockState(new BlockPos(i + 8, j + 7, k + 7), TriniaBlocks.triniaStoneBrick.getDefaultState());
		world.setBlockState(new BlockPos(i + 8, j + 7, k + 8), TriniaBlocks.triniaStoneBrick.getDefaultState());
		world.setBlockState(new BlockPos(i + 8, j + 8, k + 3), TriniaBlocks.triniaStoneBrick.getDefaultState());
		world.setBlockState(new BlockPos(i + 8, j + 8, k + 4), TriniaBlocks.triniaStoneBrick.getDefaultState());
		world.setBlockState(new BlockPos(i + 8, j + 8, k + 5), TriniaBlocks.triniaStoneBrick.getDefaultState());
		world.setBlockState(new BlockPos(i + 8, j + 8, k + 6), TriniaBlocks.triniaStoneBrick.getDefaultState());
		world.setBlockState(new BlockPos(i + 8, j + 8, k + 7), TriniaBlocks.triniaStoneBrick.getDefaultState());
		world.setBlockState(new BlockPos(i + 8, j + 9, k + 4), TriniaBlocks.triniaStoneBrick.getDefaultState());
		world.setBlockState(new BlockPos(i + 8, j + 9, k + 6), TriniaBlocks.triniaStoneBrick.getDefaultState());
		world.setBlockState(new BlockPos(i + 8, j + 10, k + 4), TriniaBlocks.triniaStoneBrick.getDefaultState());
		world.setBlockState(new BlockPos(i + 8, j + 10, k + 6), TriniaBlocks.triniaStoneBrick.getDefaultState());
		world.setBlockState(new BlockPos(i + 8, j + 11, k + 3), TriniaBlocks.triniaStoneBrick.getDefaultState());
		world.setBlockState(new BlockPos(i + 8, j + 11, k + 4), TriniaBlocks.triniaStoneBrick.getDefaultState());
		world.setBlockState(new BlockPos(i + 8, j + 11, k + 5), TriniaBlocks.triniaStoneBrick.getDefaultState());
		world.setBlockState(new BlockPos(i + 8, j + 11, k + 6), TriniaBlocks.triniaStoneBrick.getDefaultState());
		world.setBlockState(new BlockPos(i + 8, j + 11, k + 7), TriniaBlocks.triniaStoneBrick.getDefaultState());
		world.setBlockState(new BlockPos(i + 8, j + 12, k + 3), TriniaBlocks.triniaStoneBrick.getDefaultState());
		world.setBlockState(new BlockPos(i + 8, j + 12, k + 4), TriniaBlocks.triniaStoneBrick.getDefaultState());
		world.setBlockState(new BlockPos(i + 8, j + 12, k + 6), TriniaBlocks.triniaStoneBrick.getDefaultState());
		world.setBlockState(new BlockPos(i + 8, j + 12, k + 7), TriniaBlocks.triniaStoneBrick.getDefaultState());
		world.setBlockState(new BlockPos(i + 8, j + 13, k + 3), TriniaBlocks.triniaStoneBrick.getDefaultState());
		world.setBlockState(new BlockPos(i + 8, j + 13, k + 4), TriniaBlocks.triniaStoneBrick.getDefaultState());
		world.setBlockState(new BlockPos(i + 8, j + 13, k + 5), TriniaBlocks.triniaStoneBrick.getDefaultState());
		world.setBlockState(new BlockPos(i + 8, j + 13, k + 6), TriniaBlocks.triniaStoneBrick.getDefaultState());
		world.setBlockState(new BlockPos(i + 8, j + 13, k + 7), TriniaBlocks.triniaStoneBrick.getDefaultState());
		world.setBlockState(new BlockPos(i + 8, j + 14, k + 2), TriniaBlocks.triniaStoneBrick.getDefaultState());
		world.setBlockState(new BlockPos(i + 8, j + 14, k + 3), TriniaBlocks.triniaStoneBrick.getDefaultState());
		world.setBlockState(new BlockPos(i + 8, j + 14, k + 4), TriniaBlocks.triniaStoneBrick.getDefaultState());
		world.setBlockState(new BlockPos(i + 8, j + 14, k + 6), TriniaBlocks.triniaStoneBrick.getDefaultState());
		world.setBlockState(new BlockPos(i + 8, j + 14, k + 7), TriniaBlocks.triniaStoneBrick.getDefaultState());
		world.setBlockState(new BlockPos(i + 8, j + 14, k + 8), TriniaBlocks.triniaStoneBrick.getDefaultState());
		world.setBlockState(new BlockPos(i + 8, j + 15, k + 3), TriniaBlocks.triniaStoneBrick.getDefaultState());
		world.setBlockState(new BlockPos(i + 8, j + 15, k + 5), TriniaBlocks.triniaStoneBrick.getDefaultState());
		world.setBlockState(new BlockPos(i + 8, j + 15, k + 7), TriniaBlocks.triniaStoneBrick.getDefaultState());
		world.setBlockState(new BlockPos(i + 9, j + 3, k + 4), TriniaBlocks.triniaDirt.getDefaultState());
		world.setBlockState(new BlockPos(i + 9, j + 3, k + 5), TriniaBlocks.triniaDirt.getDefaultState());
		world.setBlockState(new BlockPos(i + 9, j + 4, k + 3), TriniaBlocks.triniaDirt.getDefaultState());
		world.setBlockState(new BlockPos(i + 9, j + 4, k + 4), TriniaBlocks.triniaGrass.getDefaultState());
		world.setBlockState(new BlockPos(i + 9, j + 4, k + 5), TriniaBlocks.triniaGrass.getDefaultState());
		world.setBlockState(new BlockPos(i + 9, j + 4, k + 6), TriniaBlocks.triniaGrass.getDefaultState());
		world.setBlockState(new BlockPos(i + 9, j + 4, k + 7), TriniaBlocks.triniaDirt.getDefaultState());
		world.setBlockState(new BlockPos(i + 9, j + 5, k + 3), TriniaBlocks.triniaDirt.getDefaultState());
		world.setBlockState(new BlockPos(i + 9, j + 5, k + 4), TriniaBlocks.triniaChiseledStoneBrick.getDefaultState());
		world.setBlockState(new BlockPos(i + 9, j + 5, k + 5), TriniaBlocks.triniaChiseledStoneBrick.getDefaultState());
		world.setBlockState(new BlockPos(i + 9, j + 5, k + 6), TriniaBlocks.triniaChiseledStoneBrick.getDefaultState());
		world.setBlockState(new BlockPos(i + 9, j + 5, k + 7), TriniaBlocks.triniaDirt.getDefaultState());
		world.setBlockState(new BlockPos(i + 9, j + 6, k + 3), TriniaBlocks.triniaStoneBrick.getDefaultState());
		world.setBlockState(new BlockPos(i + 9, j + 6, k + 7), TriniaBlocks.triniaStoneBrick.getDefaultState());
		world.setBlockState(new BlockPos(i + 9, j + 7, k + 3), TriniaBlocks.triniaStoneBrick.getDefaultState());
		world.setBlockState(new BlockPos(i + 9, j + 7, k + 7), TriniaBlocks.triniaStoneBrick.getDefaultState());
		world.setBlockState(new BlockPos(i + 9, j + 8, k + 4), TriniaBlocks.triniaStoneBrick.getDefaultState());
		world.setBlockState(new BlockPos(i + 9, j + 8, k + 5), TriniaBlocks.triniaStoneBrick.getDefaultState());
		world.setBlockState(new BlockPos(i + 9, j + 8, k + 6), TriniaBlocks.triniaStoneBrick.getDefaultState());
		world.setBlockState(new BlockPos(i + 9, j + 11, k + 4), TriniaBlocks.triniaStoneBrick.getDefaultState());
		world.setBlockState(new BlockPos(i + 9, j + 11, k + 5), TriniaBlocks.triniaStoneBrick.getDefaultState());
		world.setBlockState(new BlockPos(i + 9, j + 11, k + 6), TriniaBlocks.triniaStoneBrick.getDefaultState());
		world.setBlockState(new BlockPos(i + 9, j + 13, k + 4), TriniaBlocks.triniaStoneBrick.getDefaultState());
		world.setBlockState(new BlockPos(i + 9, j + 13, k + 5), TriniaBlocks.triniaStoneBrick.getDefaultState());
		world.setBlockState(new BlockPos(i + 9, j + 13, k + 6), TriniaBlocks.triniaStoneBrick.getDefaultState());
		world.setBlockState(new BlockPos(i + 9, j + 14, k + 3), TriniaBlocks.triniaStoneBrick.getDefaultState());
		world.setBlockState(new BlockPos(i + 9, j + 14, k + 4), TriniaBlocks.triniaStoneBrick.getDefaultState());
		world.setBlockState(new BlockPos(i + 9, j + 14, k + 5), TriniaBlocks.triniaStoneBrick.getDefaultState());
		world.setBlockState(new BlockPos(i + 9, j + 14, k + 6), TriniaBlocks.triniaStoneBrick.getDefaultState());
		world.setBlockState(new BlockPos(i + 9, j + 14, k + 7), TriniaBlocks.triniaStoneBrick.getDefaultState());
		world.setBlockState(new BlockPos(i + 9, j + 15, k + 4), TriniaBlocks.triniaStoneBrick.getDefaultState());
		world.setBlockState(new BlockPos(i + 9, j + 15, k + 5), TriniaBlocks.triniaStoneBrick.getDefaultState());
		world.setBlockState(new BlockPos(i + 9, j + 15, k + 6), TriniaBlocks.triniaStoneBrick.getDefaultState());
		world.setBlockState(new BlockPos(i + 10, j + 4, k + 5), TriniaBlocks.triniaGrass.getDefaultState());
		world.setBlockState(new BlockPos(i + 10, j + 14, k + 4), TriniaBlocks.triniaStoneBrick.getDefaultState());
		world.setBlockState(new BlockPos(i + 10, j + 14, k + 5), TriniaBlocks.triniaStoneBrick.getDefaultState());
		world.setBlockState(new BlockPos(i + 10, j + 14, k + 6), TriniaBlocks.triniaStoneBrick.getDefaultState());

		return true;
	}
}