package com.trinia.world.gen;

import java.util.Random;

import com.trinia.blocks.TriniaBlocks;

import net.minecraft.init.Blocks;
import net.minecraft.util.BlockPos;
import net.minecraft.world.World;
import net.minecraft.world.gen.feature.WorldGenerator;

public class WorldGenTemple extends WorldGenerator {
	
	@Override
	public boolean generate(World world, Random rand, BlockPos pos) {
		int i = pos.getX(), j = pos.getY(), k = pos.getZ();

		world.setBlockState(new BlockPos(i + 0, j + 1, k + 1), TriniaBlocks.cloud.getDefaultState());
		world.setBlockState(new BlockPos(i + 0, j + 1, k + 2), TriniaBlocks.cloud.getDefaultState());
		world.setBlockState(new BlockPos(i + 0, j + 1, k + 3), TriniaBlocks.cloud.getDefaultState());
		world.setBlockState(new BlockPos(i + 0, j + 1, k + 4), TriniaBlocks.cloud.getDefaultState());
		world.setBlockState(new BlockPos(i + 0, j + 1, k + 5), TriniaBlocks.cloud.getDefaultState());
		world.setBlockState(new BlockPos(i + 0, j + 1, k + 6), TriniaBlocks.cloud.getDefaultState());
		world.setBlockState(new BlockPos(i + 0, j + 1, k + 7), TriniaBlocks.cloud.getDefaultState());
		world.setBlockState(new BlockPos(i + 0, j + 1, k + 8), TriniaBlocks.cloud.getDefaultState());
		world.setBlockState(new BlockPos(i + 0, j + 1, k + 9), TriniaBlocks.cloud.getDefaultState());
		world.setBlockState(new BlockPos(i + 0, j + 1, k + 10), TriniaBlocks.cloud.getDefaultState());
		world.setBlockState(new BlockPos(i + 0, j + 1, k + 11), TriniaBlocks.cloud.getDefaultState());
		world.setBlockState(new BlockPos(i + 0, j + 1, k + 12), TriniaBlocks.cloud.getDefaultState());
		world.setBlockState(new BlockPos(i + 0, j + 1, k + 13), TriniaBlocks.cloud.getDefaultState());
		world.setBlockState(new BlockPos(i + 0, j + 1, k + 14), TriniaBlocks.cloud.getDefaultState());
		world.setBlockState(new BlockPos(i + 0, j + 1, k + 15), TriniaBlocks.cloud.getDefaultState());
		world.setBlockState(new BlockPos(i + 0, j + 1, k + 16), TriniaBlocks.cloud.getDefaultState());
		world.setBlockState(new BlockPos(i + 0, j + 1, k + 17), TriniaBlocks.cloud.getDefaultState());
		world.setBlockState(new BlockPos(i + 0, j + 1, k + 18), TriniaBlocks.cloud.getDefaultState());
		world.setBlockState(new BlockPos(i + 0, j + 1, k + 19), TriniaBlocks.cloud.getDefaultState());
		world.setBlockState(new BlockPos(i + 0, j + 1, k + 20), TriniaBlocks.cloud.getDefaultState());
		world.setBlockState(new BlockPos(i + 0, j + 1, k + 21), TriniaBlocks.cloud.getDefaultState());
		world.setBlockState(new BlockPos(i + 0, j + 1, k + 22), TriniaBlocks.cloud.getDefaultState());
		world.setBlockState(new BlockPos(i + 0, j + 1, k + 23), TriniaBlocks.cloud.getDefaultState());
		world.setBlockState(new BlockPos(i + 0, j + 1, k + 24), TriniaBlocks.cloud.getDefaultState());
		world.setBlockState(new BlockPos(i + 0, j + 1, k + 25), TriniaBlocks.cloud.getDefaultState());
		world.setBlockState(new BlockPos(i + 0, j + 1, k + 26), TriniaBlocks.cloud.getDefaultState());
		world.setBlockState(new BlockPos(i + 0, j + 1, k + 27), TriniaBlocks.cloud.getDefaultState());
		world.setBlockState(new BlockPos(i + 0, j + 1, k + 28), TriniaBlocks.cloud.getDefaultState());
		world.setBlockState(new BlockPos(i + 0, j + 1, k + 29), TriniaBlocks.cloud.getDefaultState());
		world.setBlockState(new BlockPos(i + 0, j + 1, k + 30), TriniaBlocks.cloud.getDefaultState());
		world.setBlockState(new BlockPos(i + 0, j + 1, k + 31), TriniaBlocks.cloud.getDefaultState());
		world.setBlockState(new BlockPos(i + 0, j + 1, k + 32), TriniaBlocks.cloud.getDefaultState());
		world.setBlockState(new BlockPos(i + 0, j + 1, k + 33), TriniaBlocks.cloud.getDefaultState());
		world.setBlockState(new BlockPos(i + 0, j + 1, k + 34), TriniaBlocks.cloud.getDefaultState());
		world.setBlockState(new BlockPos(i + 0, j + 1, k + 35), TriniaBlocks.cloud.getDefaultState());
		world.setBlockState(new BlockPos(i + 0, j + 2, k + 1), TriniaBlocks.cloud.getDefaultState());
		world.setBlockState(new BlockPos(i + 0, j + 2, k + 2), TriniaBlocks.cloud.getDefaultState());
		world.setBlockState(new BlockPos(i + 0, j + 2, k + 3), TriniaBlocks.cloud.getDefaultState());
		world.setBlockState(new BlockPos(i + 0, j + 2, k + 4), TriniaBlocks.cloud.getDefaultState());
		world.setBlockState(new BlockPos(i + 0, j + 2, k + 5), TriniaBlocks.cloud.getDefaultState());
		world.setBlockState(new BlockPos(i + 0, j + 2, k + 6), TriniaBlocks.cloud.getDefaultState());
		world.setBlockState(new BlockPos(i + 0, j + 2, k + 30), TriniaBlocks.cloud.getDefaultState());
		world.setBlockState(new BlockPos(i + 0, j + 2, k + 31), TriniaBlocks.cloud.getDefaultState());
		world.setBlockState(new BlockPos(i + 0, j + 2, k + 32), TriniaBlocks.cloud.getDefaultState());
		world.setBlockState(new BlockPos(i + 0, j + 2, k + 33), TriniaBlocks.cloud.getDefaultState());
		world.setBlockState(new BlockPos(i + 0, j + 2, k + 34), TriniaBlocks.cloud.getDefaultState());
		world.setBlockState(new BlockPos(i + 0, j + 3, k + 1), TriniaBlocks.cloud.getDefaultState());
		world.setBlockState(new BlockPos(i + 0, j + 3, k + 2), TriniaBlocks.cloud.getDefaultState());
		world.setBlockState(new BlockPos(i + 1, j + 0, k + 1), TriniaBlocks.cloud.getDefaultState());
		world.setBlockState(new BlockPos(i + 1, j + 0, k + 2), TriniaBlocks.cloud.getDefaultState());
		world.setBlockState(new BlockPos(i + 1, j + 0, k + 3), TriniaBlocks.cloud.getDefaultState());
		world.setBlockState(new BlockPos(i + 1, j + 0, k + 4), TriniaBlocks.cloud.getDefaultState());
		world.setBlockState(new BlockPos(i + 1, j + 0, k + 5), TriniaBlocks.cloud.getDefaultState());
		world.setBlockState(new BlockPos(i + 1, j + 0, k + 6), TriniaBlocks.cloud.getDefaultState());
		world.setBlockState(new BlockPos(i + 1, j + 0, k + 7), TriniaBlocks.cloud.getDefaultState());
		world.setBlockState(new BlockPos(i + 1, j + 0, k + 8), TriniaBlocks.cloud.getDefaultState());
		world.setBlockState(new BlockPos(i + 1, j + 0, k + 9), TriniaBlocks.cloud.getDefaultState());
		world.setBlockState(new BlockPos(i + 1, j + 0, k + 10), TriniaBlocks.cloud.getDefaultState());
		world.setBlockState(new BlockPos(i + 1, j + 0, k + 11), TriniaBlocks.cloud.getDefaultState());
		world.setBlockState(new BlockPos(i + 1, j + 0, k + 12), TriniaBlocks.cloud.getDefaultState());
		world.setBlockState(new BlockPos(i + 1, j + 0, k + 13), TriniaBlocks.cloud.getDefaultState());
		world.setBlockState(new BlockPos(i + 1, j + 0, k + 14), TriniaBlocks.cloud.getDefaultState());
		world.setBlockState(new BlockPos(i + 1, j + 0, k + 15), TriniaBlocks.cloud.getDefaultState());
		world.setBlockState(new BlockPos(i + 1, j + 0, k + 16), TriniaBlocks.cloud.getDefaultState());
		world.setBlockState(new BlockPos(i + 1, j + 0, k + 17), TriniaBlocks.cloud.getDefaultState());
		world.setBlockState(new BlockPos(i + 1, j + 0, k + 18), TriniaBlocks.cloud.getDefaultState());
		world.setBlockState(new BlockPos(i + 1, j + 0, k + 19), TriniaBlocks.cloud.getDefaultState());
		world.setBlockState(new BlockPos(i + 1, j + 0, k + 20), TriniaBlocks.cloud.getDefaultState());
		world.setBlockState(new BlockPos(i + 1, j + 0, k + 21), TriniaBlocks.cloud.getDefaultState());
		world.setBlockState(new BlockPos(i + 1, j + 0, k + 22), TriniaBlocks.cloud.getDefaultState());
		world.setBlockState(new BlockPos(i + 1, j + 0, k + 23), TriniaBlocks.cloud.getDefaultState());
		world.setBlockState(new BlockPos(i + 1, j + 0, k + 24), TriniaBlocks.cloud.getDefaultState());
		world.setBlockState(new BlockPos(i + 1, j + 0, k + 25), TriniaBlocks.cloud.getDefaultState());
		world.setBlockState(new BlockPos(i + 1, j + 0, k + 26), TriniaBlocks.cloud.getDefaultState());
		world.setBlockState(new BlockPos(i + 1, j + 0, k + 27), TriniaBlocks.cloud.getDefaultState());
		world.setBlockState(new BlockPos(i + 1, j + 0, k + 28), TriniaBlocks.cloud.getDefaultState());
		world.setBlockState(new BlockPos(i + 1, j + 0, k + 29), TriniaBlocks.cloud.getDefaultState());
		world.setBlockState(new BlockPos(i + 1, j + 0, k + 30), TriniaBlocks.cloud.getDefaultState());
		world.setBlockState(new BlockPos(i + 1, j + 0, k + 31), TriniaBlocks.cloud.getDefaultState());
		world.setBlockState(new BlockPos(i + 1, j + 0, k + 32), TriniaBlocks.cloud.getDefaultState());
		world.setBlockState(new BlockPos(i + 1, j + 0, k + 33), TriniaBlocks.cloud.getDefaultState());
		world.setBlockState(new BlockPos(i + 1, j + 0, k + 34), TriniaBlocks.cloud.getDefaultState());
		world.setBlockState(new BlockPos(i + 1, j + 0, k + 35), TriniaBlocks.cloud.getDefaultState());
		world.setBlockState(new BlockPos(i + 1, j + 1, k + 0), TriniaBlocks.cloud.getDefaultState());
		world.setBlockState(new BlockPos(i + 1, j + 1, k + 1), TriniaBlocks.cloud.getDefaultState());
		world.setBlockState(new BlockPos(i + 1, j + 1, k + 2), TriniaBlocks.cloud.getDefaultState());
		world.setBlockState(new BlockPos(i + 1, j + 1, k + 3), TriniaBlocks.cloud.getDefaultState());
		world.setBlockState(new BlockPos(i + 1, j + 1, k + 4), TriniaBlocks.cloud.getDefaultState());
		world.setBlockState(new BlockPos(i + 1, j + 1, k + 5), TriniaBlocks.cloud.getDefaultState());
		world.setBlockState(new BlockPos(i + 1, j + 1, k + 6), TriniaBlocks.cloud.getDefaultState());
		world.setBlockState(new BlockPos(i + 1, j + 1, k + 7), TriniaBlocks.cloud.getDefaultState());
		world.setBlockState(new BlockPos(i + 1, j + 1, k + 8), TriniaBlocks.cloud.getDefaultState());
		world.setBlockState(new BlockPos(i + 1, j + 1, k + 9), TriniaBlocks.cloud.getDefaultState());
		world.setBlockState(new BlockPos(i + 1, j + 1, k + 10), TriniaBlocks.cloud.getDefaultState());
		world.setBlockState(new BlockPos(i + 1, j + 1, k + 11), TriniaBlocks.cloud.getDefaultState());
		world.setBlockState(new BlockPos(i + 1, j + 1, k + 12), TriniaBlocks.cloud.getDefaultState());
		world.setBlockState(new BlockPos(i + 1, j + 1, k + 13), TriniaBlocks.cloud.getDefaultState());
		world.setBlockState(new BlockPos(i + 1, j + 1, k + 14), TriniaBlocks.cloud.getDefaultState());
		world.setBlockState(new BlockPos(i + 1, j + 1, k + 15), TriniaBlocks.cloud.getDefaultState());
		world.setBlockState(new BlockPos(i + 1, j + 1, k + 16), TriniaBlocks.cloud.getDefaultState());
		world.setBlockState(new BlockPos(i + 1, j + 1, k + 17), TriniaBlocks.cloud.getDefaultState());
		world.setBlockState(new BlockPos(i + 1, j + 1, k + 18), TriniaBlocks.cloud.getDefaultState());
		world.setBlockState(new BlockPos(i + 1, j + 1, k + 19), TriniaBlocks.cloud.getDefaultState());
		world.setBlockState(new BlockPos(i + 1, j + 1, k + 20), TriniaBlocks.cloud.getDefaultState());
		world.setBlockState(new BlockPos(i + 1, j + 1, k + 21), TriniaBlocks.cloud.getDefaultState());
		world.setBlockState(new BlockPos(i + 1, j + 1, k + 22), TriniaBlocks.cloud.getDefaultState());
		world.setBlockState(new BlockPos(i + 1, j + 1, k + 23), TriniaBlocks.cloud.getDefaultState());
		world.setBlockState(new BlockPos(i + 1, j + 1, k + 24), TriniaBlocks.cloud.getDefaultState());
		world.setBlockState(new BlockPos(i + 1, j + 1, k + 25), TriniaBlocks.cloud.getDefaultState());
		world.setBlockState(new BlockPos(i + 1, j + 1, k + 26), TriniaBlocks.cloud.getDefaultState());
		world.setBlockState(new BlockPos(i + 1, j + 1, k + 27), TriniaBlocks.cloud.getDefaultState());
		world.setBlockState(new BlockPos(i + 1, j + 1, k + 28), TriniaBlocks.cloud.getDefaultState());
		world.setBlockState(new BlockPos(i + 1, j + 1, k + 29), TriniaBlocks.cloud.getDefaultState());
		world.setBlockState(new BlockPos(i + 1, j + 1, k + 30), TriniaBlocks.cloud.getDefaultState());
		world.setBlockState(new BlockPos(i + 1, j + 1, k + 31), TriniaBlocks.cloud.getDefaultState());
		world.setBlockState(new BlockPos(i + 1, j + 1, k + 32), TriniaBlocks.cloud.getDefaultState());
		world.setBlockState(new BlockPos(i + 1, j + 1, k + 33), TriniaBlocks.cloud.getDefaultState());
		world.setBlockState(new BlockPos(i + 1, j + 1, k + 34), TriniaBlocks.cloud.getDefaultState());
		world.setBlockState(new BlockPos(i + 1, j + 1, k + 35), TriniaBlocks.cloud.getDefaultState());
		world.setBlockState(new BlockPos(i + 1, j + 1, k + 36), TriniaBlocks.cloud.getDefaultState());
		world.setBlockState(new BlockPos(i + 1, j + 2, k + 0), TriniaBlocks.cloud.getDefaultState());
		world.setBlockState(new BlockPos(i + 1, j + 2, k + 1), TriniaBlocks.cloud.getDefaultState());
		world.setBlockState(new BlockPos(i + 1, j + 2, k + 2), TriniaBlocks.cloud.getDefaultState());
		world.setBlockState(new BlockPos(i + 1, j + 2, k + 3), TriniaBlocks.cloud.getDefaultState());
		world.setBlockState(new BlockPos(i + 1, j + 2, k + 4), TriniaBlocks.cloud.getDefaultState());
		world.setBlockState(new BlockPos(i + 1, j + 2, k + 5), TriniaBlocks.cloud.getDefaultState());
		world.setBlockState(new BlockPos(i + 1, j + 2, k + 6), TriniaBlocks.cloud.getDefaultState());
		world.setBlockState(new BlockPos(i + 1, j + 2, k + 7), TriniaBlocks.cloud.getDefaultState());
		world.setBlockState(new BlockPos(i + 1, j + 2, k + 8), TriniaBlocks.cloud.getDefaultState());
		world.setBlockState(new BlockPos(i + 1, j + 2, k + 9), TriniaBlocks.cloud.getDefaultState());
		world.setBlockState(new BlockPos(i + 1, j + 2, k + 10), TriniaBlocks.cloud.getDefaultState());
		world.setBlockState(new BlockPos(i + 1, j + 2, k + 11), TriniaBlocks.cloud.getDefaultState());
		world.setBlockState(new BlockPos(i + 1, j + 2, k + 12), TriniaBlocks.cloud.getDefaultState());
		world.setBlockState(new BlockPos(i + 1, j + 2, k + 13), TriniaBlocks.cloud.getDefaultState());
		world.setBlockState(new BlockPos(i + 1, j + 2, k + 14), TriniaBlocks.cloud.getDefaultState());
		world.setBlockState(new BlockPos(i + 1, j + 2, k + 15), TriniaBlocks.cloud.getDefaultState());
		world.setBlockState(new BlockPos(i + 1, j + 2, k + 16), TriniaBlocks.cloud.getDefaultState());
		world.setBlockState(new BlockPos(i + 1, j + 2, k + 17), TriniaBlocks.cloud.getDefaultState());
		world.setBlockState(new BlockPos(i + 1, j + 2, k + 18), TriniaBlocks.cloud.getDefaultState());
		world.setBlockState(new BlockPos(i + 1, j + 2, k + 19), TriniaBlocks.cloud.getDefaultState());
		world.setBlockState(new BlockPos(i + 1, j + 2, k + 20), TriniaBlocks.cloud.getDefaultState());
		world.setBlockState(new BlockPos(i + 1, j + 2, k + 21), TriniaBlocks.cloud.getDefaultState());
		world.setBlockState(new BlockPos(i + 1, j + 2, k + 22), TriniaBlocks.cloud.getDefaultState());
		world.setBlockState(new BlockPos(i + 1, j + 2, k + 23), TriniaBlocks.cloud.getDefaultState());
		world.setBlockState(new BlockPos(i + 1, j + 2, k + 24), TriniaBlocks.cloud.getDefaultState());
		world.setBlockState(new BlockPos(i + 1, j + 2, k + 25), TriniaBlocks.cloud.getDefaultState());
		world.setBlockState(new BlockPos(i + 1, j + 2, k + 26), TriniaBlocks.cloud.getDefaultState());
		world.setBlockState(new BlockPos(i + 1, j + 2, k + 27), TriniaBlocks.cloud.getDefaultState());
		world.setBlockState(new BlockPos(i + 1, j + 2, k + 28), TriniaBlocks.cloud.getDefaultState());
		world.setBlockState(new BlockPos(i + 1, j + 2, k + 29), TriniaBlocks.cloud.getDefaultState());
		world.setBlockState(new BlockPos(i + 1, j + 2, k + 30), TriniaBlocks.cloud.getDefaultState());
		world.setBlockState(new BlockPos(i + 1, j + 2, k + 31), TriniaBlocks.cloud.getDefaultState());
		world.setBlockState(new BlockPos(i + 1, j + 2, k + 32), TriniaBlocks.cloud.getDefaultState());
		world.setBlockState(new BlockPos(i + 1, j + 2, k + 33), TriniaBlocks.cloud.getDefaultState());
		world.setBlockState(new BlockPos(i + 1, j + 2, k + 34), TriniaBlocks.cloud.getDefaultState());
		world.setBlockState(new BlockPos(i + 1, j + 2, k + 35), TriniaBlocks.cloud.getDefaultState());
		world.setBlockState(new BlockPos(i + 1, j + 3, k + 0), TriniaBlocks.cloud.getDefaultState());
		world.setBlockState(new BlockPos(i + 1, j + 3, k + 1), TriniaBlocks.cloud.getDefaultState());
		world.setBlockState(new BlockPos(i + 1, j + 3, k + 2), TriniaBlocks.cloud.getDefaultState());
		world.setBlockState(new BlockPos(i + 1, j + 3, k + 3), TriniaBlocks.cloud.getDefaultState());
		world.setBlockState(new BlockPos(i + 1, j + 3, k + 4), TriniaBlocks.cloud.getDefaultState());
		world.setBlockState(new BlockPos(i + 1, j + 3, k + 5), TriniaBlocks.cloud.getDefaultState());
		world.setBlockState(new BlockPos(i + 1, j + 3, k + 6), TriniaBlocks.cloud.getDefaultState());
		world.setBlockState(new BlockPos(i + 1, j + 3, k + 7), TriniaBlocks.cloud.getDefaultState());
		world.setBlockState(new BlockPos(i + 1, j + 3, k + 8), TriniaBlocks.cloud.getDefaultState());
		world.setBlockState(new BlockPos(i + 1, j + 3, k + 33), TriniaBlocks.cloud.getDefaultState());
		world.setBlockState(new BlockPos(i + 1, j + 3, k + 34), TriniaBlocks.cloud.getDefaultState());
		world.setBlockState(new BlockPos(i + 1, j + 4, k + 2), TriniaBlocks.cloud.getDefaultState());
		world.setBlockState(new BlockPos(i + 1, j + 4, k + 3), TriniaBlocks.cloud.getDefaultState());
		world.setBlockState(new BlockPos(i + 1, j + 10, k + 2), Blocks.quartz_block.getDefaultState());
		world.setBlockState(new BlockPos(i + 1, j + 10, k + 3), Blocks.quartz_block.getDefaultState());
		world.setBlockState(new BlockPos(i + 1, j + 10, k + 4), Blocks.quartz_block.getDefaultState());
		world.setBlockState(new BlockPos(i + 1, j + 10, k + 5), Blocks.quartz_block.getDefaultState());
		world.setBlockState(new BlockPos(i + 1, j + 10, k + 6), Blocks.quartz_block.getDefaultState());
		world.setBlockState(new BlockPos(i + 1, j + 10, k + 7), Blocks.quartz_block.getDefaultState());
		world.setBlockState(new BlockPos(i + 1, j + 10, k + 8), Blocks.quartz_block.getDefaultState());
		world.setBlockState(new BlockPos(i + 1, j + 10, k + 9), Blocks.quartz_block.getDefaultState());
		world.setBlockState(new BlockPos(i + 1, j + 10, k + 10), Blocks.quartz_block.getDefaultState());
		world.setBlockState(new BlockPos(i + 1, j + 10, k + 11), Blocks.quartz_block.getDefaultState());
		world.setBlockState(new BlockPos(i + 1, j + 10, k + 12), Blocks.quartz_block.getDefaultState());
		world.setBlockState(new BlockPos(i + 1, j + 10, k + 13), Blocks.quartz_block.getDefaultState());
		world.setBlockState(new BlockPos(i + 1, j + 10, k + 14), Blocks.quartz_block.getDefaultState());
		world.setBlockState(new BlockPos(i + 1, j + 10, k + 15), Blocks.quartz_block.getDefaultState());
		world.setBlockState(new BlockPos(i + 1, j + 10, k + 16), Blocks.quartz_block.getDefaultState());
		world.setBlockState(new BlockPos(i + 1, j + 10, k + 17), Blocks.quartz_block.getDefaultState());
		world.setBlockState(new BlockPos(i + 1, j + 10, k + 18), Blocks.quartz_block.getDefaultState());
		world.setBlockState(new BlockPos(i + 1, j + 10, k + 19), Blocks.quartz_block.getDefaultState());
		world.setBlockState(new BlockPos(i + 1, j + 10, k + 20), Blocks.quartz_block.getDefaultState());
		world.setBlockState(new BlockPos(i + 1, j + 10, k + 21), Blocks.quartz_block.getDefaultState());
		world.setBlockState(new BlockPos(i + 1, j + 10, k + 22), Blocks.quartz_block.getDefaultState());
		world.setBlockState(new BlockPos(i + 1, j + 10, k + 23), Blocks.quartz_block.getDefaultState());
		world.setBlockState(new BlockPos(i + 1, j + 10, k + 24), Blocks.quartz_block.getDefaultState());
		world.setBlockState(new BlockPos(i + 1, j + 10, k + 25), Blocks.quartz_block.getDefaultState());
		world.setBlockState(new BlockPos(i + 1, j + 10, k + 26), Blocks.quartz_block.getDefaultState());
		world.setBlockState(new BlockPos(i + 1, j + 10, k + 27), Blocks.quartz_block.getDefaultState());
		world.setBlockState(new BlockPos(i + 1, j + 10, k + 28), Blocks.quartz_block.getDefaultState());
		world.setBlockState(new BlockPos(i + 1, j + 10, k + 29), Blocks.quartz_block.getDefaultState());
		world.setBlockState(new BlockPos(i + 1, j + 10, k + 30), Blocks.quartz_block.getDefaultState());
		world.setBlockState(new BlockPos(i + 1, j + 10, k + 31), Blocks.quartz_block.getDefaultState());
		world.setBlockState(new BlockPos(i + 1, j + 10, k + 32), Blocks.quartz_block.getDefaultState());
		world.setBlockState(new BlockPos(i + 1, j + 10, k + 33), Blocks.quartz_block.getDefaultState());
		world.setBlockState(new BlockPos(i + 1, j + 10, k + 34), Blocks.quartz_block.getDefaultState());
		world.setBlockState(new BlockPos(i + 1, j + 10, k + 35), Blocks.quartz_block.getDefaultState());
		world.setBlockState(new BlockPos(i + 1, j + 11, k + 2), Blocks.quartz_block.getDefaultState());
		world.setBlockState(new BlockPos(i + 1, j + 11, k + 3), Blocks.quartz_block.getDefaultState());
		world.setBlockState(new BlockPos(i + 1, j + 11, k + 4), Blocks.quartz_block.getDefaultState());
		world.setBlockState(new BlockPos(i + 1, j + 11, k + 5), Blocks.quartz_block.getDefaultState());
		world.setBlockState(new BlockPos(i + 1, j + 11, k + 6), Blocks.quartz_block.getDefaultState());
		world.setBlockState(new BlockPos(i + 1, j + 11, k + 7), Blocks.quartz_block.getDefaultState());
		world.setBlockState(new BlockPos(i + 1, j + 11, k + 8), Blocks.quartz_block.getDefaultState());
		world.setBlockState(new BlockPos(i + 1, j + 11, k + 9), Blocks.quartz_block.getDefaultState());
		world.setBlockState(new BlockPos(i + 1, j + 11, k + 10), Blocks.quartz_block.getDefaultState());
		world.setBlockState(new BlockPos(i + 1, j + 11, k + 11), Blocks.quartz_block.getDefaultState());
		world.setBlockState(new BlockPos(i + 1, j + 11, k + 12), Blocks.quartz_block.getDefaultState());
		world.setBlockState(new BlockPos(i + 1, j + 11, k + 13), Blocks.quartz_block.getDefaultState());
		world.setBlockState(new BlockPos(i + 1, j + 11, k + 14), Blocks.quartz_block.getDefaultState());
		world.setBlockState(new BlockPos(i + 1, j + 11, k + 15), Blocks.quartz_block.getDefaultState());
		world.setBlockState(new BlockPos(i + 1, j + 11, k + 16), Blocks.quartz_block.getDefaultState());
		world.setBlockState(new BlockPos(i + 1, j + 11, k + 17), Blocks.quartz_block.getDefaultState());
		world.setBlockState(new BlockPos(i + 1, j + 11, k + 18), Blocks.quartz_block.getDefaultState());
		world.setBlockState(new BlockPos(i + 1, j + 11, k + 19), Blocks.quartz_block.getDefaultState());
		world.setBlockState(new BlockPos(i + 1, j + 11, k + 20), Blocks.quartz_block.getDefaultState());
		world.setBlockState(new BlockPos(i + 1, j + 11, k + 21), Blocks.quartz_block.getDefaultState());
		world.setBlockState(new BlockPos(i + 1, j + 11, k + 22), Blocks.quartz_block.getDefaultState());
		world.setBlockState(new BlockPos(i + 1, j + 11, k + 23), Blocks.quartz_block.getDefaultState());
		world.setBlockState(new BlockPos(i + 1, j + 11, k + 24), Blocks.quartz_block.getDefaultState());
		world.setBlockState(new BlockPos(i + 1, j + 11, k + 25), Blocks.quartz_block.getDefaultState());
		world.setBlockState(new BlockPos(i + 1, j + 11, k + 26), Blocks.quartz_block.getDefaultState());
		world.setBlockState(new BlockPos(i + 1, j + 11, k + 27), Blocks.quartz_block.getDefaultState());
		world.setBlockState(new BlockPos(i + 1, j + 11, k + 28), Blocks.quartz_block.getDefaultState());
		world.setBlockState(new BlockPos(i + 1, j + 11, k + 29), Blocks.quartz_block.getDefaultState());
		world.setBlockState(new BlockPos(i + 1, j + 11, k + 30), Blocks.quartz_block.getDefaultState());
		world.setBlockState(new BlockPos(i + 1, j + 11, k + 31), Blocks.quartz_block.getDefaultState());
		world.setBlockState(new BlockPos(i + 1, j + 11, k + 32), Blocks.quartz_block.getDefaultState());
		world.setBlockState(new BlockPos(i + 1, j + 11, k + 33), Blocks.quartz_block.getDefaultState());
		world.setBlockState(new BlockPos(i + 1, j + 11, k + 34), Blocks.quartz_block.getDefaultState());
		world.setBlockState(new BlockPos(i + 1, j + 11, k + 35), Blocks.quartz_block.getDefaultState());
		world.setBlockState(new BlockPos(i + 2, j + 0, k + 1), TriniaBlocks.cloud.getDefaultState());
		world.setBlockState(new BlockPos(i + 2, j + 0, k + 2), TriniaBlocks.cloud.getDefaultState());
		world.setBlockState(new BlockPos(i + 2, j + 0, k + 3), TriniaBlocks.cloud.getDefaultState());
		world.setBlockState(new BlockPos(i + 2, j + 0, k + 4), TriniaBlocks.cloud.getDefaultState());
		world.setBlockState(new BlockPos(i + 2, j + 0, k + 5), TriniaBlocks.cloud.getDefaultState());
		world.setBlockState(new BlockPos(i + 2, j + 0, k + 6), TriniaBlocks.cloud.getDefaultState());
		world.setBlockState(new BlockPos(i + 2, j + 0, k + 7), TriniaBlocks.cloud.getDefaultState());
		world.setBlockState(new BlockPos(i + 2, j + 0, k + 8), TriniaBlocks.cloud.getDefaultState());
		world.setBlockState(new BlockPos(i + 2, j + 0, k + 9), TriniaBlocks.cloud.getDefaultState());
		world.setBlockState(new BlockPos(i + 2, j + 0, k + 10), TriniaBlocks.cloud.getDefaultState());
		world.setBlockState(new BlockPos(i + 2, j + 0, k + 11), TriniaBlocks.cloud.getDefaultState());
		world.setBlockState(new BlockPos(i + 2, j + 0, k + 12), TriniaBlocks.cloud.getDefaultState());
		world.setBlockState(new BlockPos(i + 2, j + 0, k + 13), TriniaBlocks.cloud.getDefaultState());
		world.setBlockState(new BlockPos(i + 2, j + 0, k + 14), TriniaBlocks.cloud.getDefaultState());
		world.setBlockState(new BlockPos(i + 2, j + 0, k + 15), TriniaBlocks.cloud.getDefaultState());
		world.setBlockState(new BlockPos(i + 2, j + 0, k + 16), TriniaBlocks.cloud.getDefaultState());
		world.setBlockState(new BlockPos(i + 2, j + 0, k + 17), TriniaBlocks.cloud.getDefaultState());
		world.setBlockState(new BlockPos(i + 2, j + 0, k + 18), TriniaBlocks.cloud.getDefaultState());
		world.setBlockState(new BlockPos(i + 2, j + 0, k + 19), TriniaBlocks.cloud.getDefaultState());
		world.setBlockState(new BlockPos(i + 2, j + 0, k + 20), TriniaBlocks.cloud.getDefaultState());
		world.setBlockState(new BlockPos(i + 2, j + 0, k + 21), TriniaBlocks.cloud.getDefaultState());
		world.setBlockState(new BlockPos(i + 2, j + 0, k + 22), TriniaBlocks.cloud.getDefaultState());
		world.setBlockState(new BlockPos(i + 2, j + 0, k + 23), TriniaBlocks.cloud.getDefaultState());
		world.setBlockState(new BlockPos(i + 2, j + 0, k + 24), TriniaBlocks.cloud.getDefaultState());
		world.setBlockState(new BlockPos(i + 2, j + 0, k + 25), TriniaBlocks.cloud.getDefaultState());
		world.setBlockState(new BlockPos(i + 2, j + 0, k + 26), TriniaBlocks.cloud.getDefaultState());
		world.setBlockState(new BlockPos(i + 2, j + 0, k + 27), TriniaBlocks.cloud.getDefaultState());
		world.setBlockState(new BlockPos(i + 2, j + 0, k + 28), TriniaBlocks.cloud.getDefaultState());
		world.setBlockState(new BlockPos(i + 2, j + 0, k + 29), TriniaBlocks.cloud.getDefaultState());
		world.setBlockState(new BlockPos(i + 2, j + 0, k + 30), TriniaBlocks.cloud.getDefaultState());
		world.setBlockState(new BlockPos(i + 2, j + 0, k + 31), TriniaBlocks.cloud.getDefaultState());
		world.setBlockState(new BlockPos(i + 2, j + 0, k + 32), TriniaBlocks.cloud.getDefaultState());
		world.setBlockState(new BlockPos(i + 2, j + 0, k + 33), TriniaBlocks.cloud.getDefaultState());
		world.setBlockState(new BlockPos(i + 2, j + 0, k + 34), TriniaBlocks.cloud.getDefaultState());
		world.setBlockState(new BlockPos(i + 2, j + 0, k + 35), TriniaBlocks.cloud.getDefaultState());
		world.setBlockState(new BlockPos(i + 2, j + 1, k + 0), TriniaBlocks.cloud.getDefaultState());
		world.setBlockState(new BlockPos(i + 2, j + 1, k + 1), TriniaBlocks.cloud.getDefaultState());
		world.setBlockState(new BlockPos(i + 2, j + 1, k + 2), TriniaBlocks.cloud.getDefaultState());
		world.setBlockState(new BlockPos(i + 2, j + 1, k + 3), TriniaBlocks.cloud.getDefaultState());
		world.setBlockState(new BlockPos(i + 2, j + 1, k + 4), TriniaBlocks.cloud.getDefaultState());
		world.setBlockState(new BlockPos(i + 2, j + 1, k + 5), TriniaBlocks.cloud.getDefaultState());
		world.setBlockState(new BlockPos(i + 2, j + 1, k + 6), TriniaBlocks.cloud.getDefaultState());
		world.setBlockState(new BlockPos(i + 2, j + 1, k + 7), TriniaBlocks.cloud.getDefaultState());
		world.setBlockState(new BlockPos(i + 2, j + 1, k + 8), TriniaBlocks.cloud.getDefaultState());
		world.setBlockState(new BlockPos(i + 2, j + 1, k + 9), TriniaBlocks.cloud.getDefaultState());
		world.setBlockState(new BlockPos(i + 2, j + 1, k + 10), TriniaBlocks.cloud.getDefaultState());
		world.setBlockState(new BlockPos(i + 2, j + 1, k + 11), TriniaBlocks.cloud.getDefaultState());
		world.setBlockState(new BlockPos(i + 2, j + 1, k + 12), TriniaBlocks.cloud.getDefaultState());
		world.setBlockState(new BlockPos(i + 2, j + 1, k + 13), TriniaBlocks.cloud.getDefaultState());
		world.setBlockState(new BlockPos(i + 2, j + 1, k + 14), TriniaBlocks.cloud.getDefaultState());
		world.setBlockState(new BlockPos(i + 2, j + 1, k + 15), TriniaBlocks.cloud.getDefaultState());
		world.setBlockState(new BlockPos(i + 2, j + 1, k + 16), TriniaBlocks.cloud.getDefaultState());
		world.setBlockState(new BlockPos(i + 2, j + 1, k + 17), TriniaBlocks.cloud.getDefaultState());
		world.setBlockState(new BlockPos(i + 2, j + 1, k + 18), TriniaBlocks.cloud.getDefaultState());
		world.setBlockState(new BlockPos(i + 2, j + 1, k + 19), TriniaBlocks.cloud.getDefaultState());
		world.setBlockState(new BlockPos(i + 2, j + 1, k + 20), TriniaBlocks.cloud.getDefaultState());
		world.setBlockState(new BlockPos(i + 2, j + 1, k + 21), TriniaBlocks.cloud.getDefaultState());
		world.setBlockState(new BlockPos(i + 2, j + 1, k + 22), TriniaBlocks.cloud.getDefaultState());
		world.setBlockState(new BlockPos(i + 2, j + 1, k + 23), TriniaBlocks.cloud.getDefaultState());
		world.setBlockState(new BlockPos(i + 2, j + 1, k + 24), TriniaBlocks.cloud.getDefaultState());
		world.setBlockState(new BlockPos(i + 2, j + 1, k + 25), TriniaBlocks.cloud.getDefaultState());
		world.setBlockState(new BlockPos(i + 2, j + 1, k + 26), TriniaBlocks.cloud.getDefaultState());
		world.setBlockState(new BlockPos(i + 2, j + 1, k + 27), TriniaBlocks.cloud.getDefaultState());
		world.setBlockState(new BlockPos(i + 2, j + 1, k + 28), TriniaBlocks.cloud.getDefaultState());
		world.setBlockState(new BlockPos(i + 2, j + 1, k + 29), TriniaBlocks.cloud.getDefaultState());
		world.setBlockState(new BlockPos(i + 2, j + 1, k + 30), TriniaBlocks.cloud.getDefaultState());
		world.setBlockState(new BlockPos(i + 2, j + 1, k + 31), TriniaBlocks.cloud.getDefaultState());
		world.setBlockState(new BlockPos(i + 2, j + 1, k + 32), TriniaBlocks.cloud.getDefaultState());
		world.setBlockState(new BlockPos(i + 2, j + 1, k + 33), TriniaBlocks.cloud.getDefaultState());
		world.setBlockState(new BlockPos(i + 2, j + 1, k + 34), TriniaBlocks.cloud.getDefaultState());
		world.setBlockState(new BlockPos(i + 2, j + 1, k + 35), TriniaBlocks.cloud.getDefaultState());
		world.setBlockState(new BlockPos(i + 2, j + 1, k + 36), TriniaBlocks.cloud.getDefaultState());
		world.setBlockState(new BlockPos(i + 2, j + 2, k + 0), TriniaBlocks.cloud.getDefaultState());
		world.setBlockState(new BlockPos(i + 2, j + 2, k + 1), TriniaBlocks.cloud.getDefaultState());
		world.setBlockState(new BlockPos(i + 2, j + 2, k + 2), TriniaBlocks.cloud.getDefaultState());
		world.setBlockState(new BlockPos(i + 2, j + 2, k + 3), TriniaBlocks.cloud.getDefaultState());
		world.setBlockState(new BlockPos(i + 2, j + 2, k + 4), TriniaBlocks.cloud.getDefaultState());
		world.setBlockState(new BlockPos(i + 2, j + 2, k + 5), TriniaBlocks.cloud.getDefaultState());
		world.setBlockState(new BlockPos(i + 2, j + 2, k + 6), TriniaBlocks.cloud.getDefaultState());
		world.setBlockState(new BlockPos(i + 2, j + 2, k + 7), TriniaBlocks.cloud.getDefaultState());
		world.setBlockState(new BlockPos(i + 2, j + 2, k + 8), TriniaBlocks.cloud.getDefaultState());
		world.setBlockState(new BlockPos(i + 2, j + 2, k + 9), TriniaBlocks.cloud.getDefaultState());
		world.setBlockState(new BlockPos(i + 2, j + 2, k + 10), TriniaBlocks.cloud.getDefaultState());
		world.setBlockState(new BlockPos(i + 2, j + 2, k + 11), TriniaBlocks.cloud.getDefaultState());
		world.setBlockState(new BlockPos(i + 2, j + 2, k + 12), TriniaBlocks.cloud.getDefaultState());
		world.setBlockState(new BlockPos(i + 2, j + 2, k + 13), TriniaBlocks.cloud.getDefaultState());
		world.setBlockState(new BlockPos(i + 2, j + 2, k + 14), TriniaBlocks.cloud.getDefaultState());
		world.setBlockState(new BlockPos(i + 2, j + 2, k + 15), TriniaBlocks.cloud.getDefaultState());
		world.setBlockState(new BlockPos(i + 2, j + 2, k + 16), TriniaBlocks.cloud.getDefaultState());
		world.setBlockState(new BlockPos(i + 2, j + 2, k + 17), TriniaBlocks.cloud.getDefaultState());
		world.setBlockState(new BlockPos(i + 2, j + 2, k + 18), TriniaBlocks.cloud.getDefaultState());
		world.setBlockState(new BlockPos(i + 2, j + 2, k + 19), TriniaBlocks.cloud.getDefaultState());
		world.setBlockState(new BlockPos(i + 2, j + 2, k + 20), TriniaBlocks.cloud.getDefaultState());
		world.setBlockState(new BlockPos(i + 2, j + 2, k + 21), TriniaBlocks.cloud.getDefaultState());
		world.setBlockState(new BlockPos(i + 2, j + 2, k + 22), TriniaBlocks.cloud.getDefaultState());
		world.setBlockState(new BlockPos(i + 2, j + 2, k + 23), TriniaBlocks.cloud.getDefaultState());
		world.setBlockState(new BlockPos(i + 2, j + 2, k + 24), TriniaBlocks.cloud.getDefaultState());
		world.setBlockState(new BlockPos(i + 2, j + 2, k + 25), TriniaBlocks.cloud.getDefaultState());
		world.setBlockState(new BlockPos(i + 2, j + 2, k + 26), TriniaBlocks.cloud.getDefaultState());
		world.setBlockState(new BlockPos(i + 2, j + 2, k + 27), TriniaBlocks.cloud.getDefaultState());
		world.setBlockState(new BlockPos(i + 2, j + 2, k + 28), TriniaBlocks.cloud.getDefaultState());
		world.setBlockState(new BlockPos(i + 2, j + 2, k + 29), TriniaBlocks.cloud.getDefaultState());
		world.setBlockState(new BlockPos(i + 2, j + 2, k + 30), TriniaBlocks.cloud.getDefaultState());
		world.setBlockState(new BlockPos(i + 2, j + 2, k + 31), TriniaBlocks.cloud.getDefaultState());
		world.setBlockState(new BlockPos(i + 2, j + 2, k + 32), TriniaBlocks.cloud.getDefaultState());
		world.setBlockState(new BlockPos(i + 2, j + 2, k + 33), TriniaBlocks.cloud.getDefaultState());
		world.setBlockState(new BlockPos(i + 2, j + 2, k + 34), TriniaBlocks.cloud.getDefaultState());
		world.setBlockState(new BlockPos(i + 2, j + 2, k + 35), TriniaBlocks.cloud.getDefaultState());
		world.setBlockState(new BlockPos(i + 2, j + 2, k + 36), TriniaBlocks.cloud.getDefaultState());
		world.setBlockState(new BlockPos(i + 2, j + 3, k + 0), TriniaBlocks.cloud.getDefaultState());
		world.setBlockState(new BlockPos(i + 2, j + 3, k + 1), TriniaBlocks.cloud.getDefaultState());
		world.setBlockState(new BlockPos(i + 2, j + 3, k + 2), Blocks.quartz_block.getDefaultState());
		world.setBlockState(new BlockPos(i + 2, j + 3, k + 3), Blocks.quartz_block.getDefaultState());
		world.setBlockState(new BlockPos(i + 2, j + 3, k + 4), Blocks.quartz_block.getDefaultState());
		world.setBlockState(new BlockPos(i + 2, j + 3, k + 5), Blocks.quartz_block.getDefaultState());
		world.setBlockState(new BlockPos(i + 2, j + 3, k + 6), Blocks.quartz_block.getDefaultState());
		world.setBlockState(new BlockPos(i + 2, j + 3, k + 7), Blocks.quartz_block.getDefaultState());
		world.setBlockState(new BlockPos(i + 2, j + 3, k + 8), Blocks.quartz_block.getDefaultState());
		world.setBlockState(new BlockPos(i + 2, j + 3, k + 9), Blocks.quartz_block.getDefaultState());
		world.setBlockState(new BlockPos(i + 2, j + 3, k + 10), Blocks.quartz_block.getDefaultState());
		world.setBlockState(new BlockPos(i + 2, j + 3, k + 11), Blocks.quartz_block.getDefaultState());
		world.setBlockState(new BlockPos(i + 2, j + 3, k + 12), Blocks.quartz_block.getDefaultState());
		world.setBlockState(new BlockPos(i + 2, j + 3, k + 13), Blocks.quartz_block.getDefaultState());
		world.setBlockState(new BlockPos(i + 2, j + 3, k + 14), Blocks.quartz_block.getDefaultState());
		world.setBlockState(new BlockPos(i + 2, j + 3, k + 15), Blocks.quartz_block.getDefaultState());
		world.setBlockState(new BlockPos(i + 2, j + 3, k + 16), Blocks.quartz_block.getDefaultState());
		world.setBlockState(new BlockPos(i + 2, j + 3, k + 17), Blocks.quartz_block.getDefaultState());
		world.setBlockState(new BlockPos(i + 2, j + 3, k + 18), Blocks.quartz_block.getDefaultState());
		world.setBlockState(new BlockPos(i + 2, j + 3, k + 19), Blocks.quartz_block.getDefaultState());
		world.setBlockState(new BlockPos(i + 2, j + 3, k + 20), Blocks.quartz_block.getDefaultState());
		world.setBlockState(new BlockPos(i + 2, j + 3, k + 21), Blocks.quartz_block.getDefaultState());
		world.setBlockState(new BlockPos(i + 2, j + 3, k + 22), Blocks.quartz_block.getDefaultState());
		world.setBlockState(new BlockPos(i + 2, j + 3, k + 23), Blocks.quartz_block.getDefaultState());
		world.setBlockState(new BlockPos(i + 2, j + 3, k + 24), Blocks.quartz_block.getDefaultState());
		world.setBlockState(new BlockPos(i + 2, j + 3, k + 25), Blocks.quartz_block.getDefaultState());
		world.setBlockState(new BlockPos(i + 2, j + 3, k + 26), Blocks.quartz_block.getDefaultState());
		world.setBlockState(new BlockPos(i + 2, j + 3, k + 27), Blocks.quartz_block.getDefaultState());
		world.setBlockState(new BlockPos(i + 2, j + 3, k + 28), Blocks.quartz_block.getDefaultState());
		world.setBlockState(new BlockPos(i + 2, j + 3, k + 29), Blocks.quartz_block.getDefaultState());
		world.setBlockState(new BlockPos(i + 2, j + 3, k + 30), Blocks.quartz_block.getDefaultState());
		world.setBlockState(new BlockPos(i + 2, j + 3, k + 31), Blocks.quartz_block.getDefaultState());
		world.setBlockState(new BlockPos(i + 2, j + 3, k + 32), Blocks.quartz_block.getDefaultState());
		world.setBlockState(new BlockPos(i + 2, j + 3, k + 33), Blocks.quartz_block.getDefaultState());
		world.setBlockState(new BlockPos(i + 2, j + 3, k + 34), Blocks.quartz_block.getDefaultState());
		world.setBlockState(new BlockPos(i + 2, j + 3, k + 35), TriniaBlocks.cloud.getDefaultState());
		world.setBlockState(new BlockPos(i + 2, j + 4, k + 1), TriniaBlocks.cloud.getDefaultState());
		world.setBlockState(new BlockPos(i + 2, j + 4, k + 2), Blocks.quartz_block.getDefaultState());
		world.setBlockState(new BlockPos(i + 2, j + 4, k + 3), Blocks.quartz_block.getDefaultState());
		world.setBlockState(new BlockPos(i + 2, j + 4, k + 4), Blocks.quartz_block.getDefaultState());
		world.setBlockState(new BlockPos(i + 2, j + 4, k + 5), Blocks.quartz_block.getDefaultState());
		world.setBlockState(new BlockPos(i + 2, j + 4, k + 6), Blocks.quartz_block.getDefaultState());
		world.setBlockState(new BlockPos(i + 2, j + 4, k + 7), Blocks.quartz_block.getDefaultState());
		world.setBlockState(new BlockPos(i + 2, j + 4, k + 8), Blocks.quartz_block.getDefaultState());
		world.setBlockState(new BlockPos(i + 2, j + 4, k + 9), Blocks.quartz_block.getDefaultState());
		world.setBlockState(new BlockPos(i + 2, j + 4, k + 10), Blocks.quartz_block.getDefaultState());
		world.setBlockState(new BlockPos(i + 2, j + 4, k + 11), Blocks.quartz_block.getDefaultState());
		world.setBlockState(new BlockPos(i + 2, j + 4, k + 12), Blocks.quartz_block.getDefaultState());
		world.setBlockState(new BlockPos(i + 2, j + 4, k + 13), Blocks.quartz_block.getDefaultState());
		world.setBlockState(new BlockPos(i + 2, j + 4, k + 14), Blocks.quartz_block.getDefaultState());
		world.setBlockState(new BlockPos(i + 2, j + 4, k + 15), Blocks.quartz_block.getDefaultState());
		world.setBlockState(new BlockPos(i + 2, j + 4, k + 16), Blocks.quartz_block.getDefaultState());
		world.setBlockState(new BlockPos(i + 2, j + 4, k + 17), Blocks.quartz_block.getDefaultState());
		world.setBlockState(new BlockPos(i + 2, j + 4, k + 18), Blocks.quartz_block.getDefaultState());
		world.setBlockState(new BlockPos(i + 2, j + 4, k + 19), Blocks.quartz_block.getDefaultState());
		world.setBlockState(new BlockPos(i + 2, j + 4, k + 20), Blocks.quartz_block.getDefaultState());
		world.setBlockState(new BlockPos(i + 2, j + 4, k + 21), Blocks.quartz_block.getDefaultState());
		world.setBlockState(new BlockPos(i + 2, j + 4, k + 22), Blocks.quartz_block.getDefaultState());
		world.setBlockState(new BlockPos(i + 2, j + 4, k + 23), Blocks.quartz_block.getDefaultState());
		world.setBlockState(new BlockPos(i + 2, j + 4, k + 24), Blocks.quartz_block.getDefaultState());
		world.setBlockState(new BlockPos(i + 2, j + 4, k + 25), Blocks.quartz_block.getDefaultState());
		world.setBlockState(new BlockPos(i + 2, j + 4, k + 26), Blocks.quartz_block.getDefaultState());
		world.setBlockState(new BlockPos(i + 2, j + 4, k + 27), Blocks.quartz_block.getDefaultState());
		world.setBlockState(new BlockPos(i + 2, j + 4, k + 28), Blocks.quartz_block.getDefaultState());
		world.setBlockState(new BlockPos(i + 2, j + 4, k + 29), Blocks.quartz_block.getDefaultState());
		world.setBlockState(new BlockPos(i + 2, j + 4, k + 30), Blocks.quartz_block.getDefaultState());
		world.setBlockState(new BlockPos(i + 2, j + 4, k + 31), Blocks.quartz_block.getDefaultState());
		world.setBlockState(new BlockPos(i + 2, j + 4, k + 32), Blocks.quartz_block.getDefaultState());
		world.setBlockState(new BlockPos(i + 2, j + 4, k + 33), Blocks.quartz_block.getDefaultState());
		world.setBlockState(new BlockPos(i + 2, j + 4, k + 34), Blocks.quartz_block.getDefaultState());
		world.setBlockState(new BlockPos(i + 2, j + 5, k + 5), Blocks.quartz_block.getDefaultState());
		world.setBlockState(new BlockPos(i + 2, j + 5, k + 6), Blocks.quartz_block.getDefaultState());
		world.setBlockState(new BlockPos(i + 2, j + 5, k + 7), Blocks.quartz_block.getDefaultState());
		world.setBlockState(new BlockPos(i + 2, j + 5, k + 8), Blocks.quartz_block.getDefaultState());
		world.setBlockState(new BlockPos(i + 2, j + 5, k + 9), Blocks.quartz_block.getDefaultState());
		world.setBlockState(new BlockPos(i + 2, j + 5, k + 10), Blocks.quartz_block.getDefaultState());
		world.setBlockState(new BlockPos(i + 2, j + 5, k + 11), Blocks.quartz_block.getDefaultState());
		world.setBlockState(new BlockPos(i + 2, j + 5, k + 12), Blocks.quartz_block.getDefaultState());
		world.setBlockState(new BlockPos(i + 2, j + 5, k + 13), Blocks.quartz_block.getDefaultState());
		world.setBlockState(new BlockPos(i + 2, j + 5, k + 14), Blocks.quartz_block.getDefaultState());
		world.setBlockState(new BlockPos(i + 2, j + 5, k + 15), Blocks.quartz_block.getDefaultState());
		world.setBlockState(new BlockPos(i + 2, j + 5, k + 16), Blocks.quartz_block.getDefaultState());
		world.setBlockState(new BlockPos(i + 2, j + 5, k + 17), Blocks.quartz_block.getDefaultState());
		world.setBlockState(new BlockPos(i + 2, j + 5, k + 18), Blocks.quartz_block.getDefaultState());
		world.setBlockState(new BlockPos(i + 2, j + 5, k + 19), Blocks.quartz_block.getDefaultState());
		world.setBlockState(new BlockPos(i + 2, j + 5, k + 20), Blocks.quartz_block.getDefaultState());
		world.setBlockState(new BlockPos(i + 2, j + 5, k + 21), Blocks.quartz_block.getDefaultState());
		world.setBlockState(new BlockPos(i + 2, j + 5, k + 22), Blocks.quartz_block.getDefaultState());
		world.setBlockState(new BlockPos(i + 2, j + 5, k + 23), Blocks.quartz_block.getDefaultState());
		world.setBlockState(new BlockPos(i + 2, j + 5, k + 24), Blocks.quartz_block.getDefaultState());
		world.setBlockState(new BlockPos(i + 2, j + 5, k + 25), Blocks.quartz_block.getDefaultState());
		world.setBlockState(new BlockPos(i + 2, j + 5, k + 26), Blocks.quartz_block.getDefaultState());
		world.setBlockState(new BlockPos(i + 2, j + 5, k + 27), Blocks.quartz_block.getDefaultState());
		world.setBlockState(new BlockPos(i + 2, j + 5, k + 28), Blocks.quartz_block.getDefaultState());
		world.setBlockState(new BlockPos(i + 2, j + 5, k + 29), Blocks.quartz_block.getDefaultState());
		world.setBlockState(new BlockPos(i + 2, j + 5, k + 30), Blocks.quartz_block.getDefaultState());
		world.setBlockState(new BlockPos(i + 2, j + 5, k + 31), Blocks.quartz_block.getDefaultState());
		world.setBlockState(new BlockPos(i + 2, j + 5, k + 32), Blocks.quartz_block.getDefaultState());
		world.setBlockState(new BlockPos(i + 2, j + 5, k + 33), Blocks.quartz_block.getDefaultState());
		world.setBlockState(new BlockPos(i + 2, j + 5, k + 34), Blocks.quartz_block.getDefaultState());
		world.setBlockState(new BlockPos(i + 2, j + 6, k + 5), Blocks.quartz_block.getDefaultState());
		world.setBlockState(new BlockPos(i + 2, j + 6, k + 6), Blocks.quartz_block.getDefaultState());
		world.setBlockState(new BlockPos(i + 2, j + 6, k + 7), Blocks.quartz_block.getDefaultState());
		world.setBlockState(new BlockPos(i + 2, j + 6, k + 8), Blocks.quartz_block.getDefaultState());
		world.setBlockState(new BlockPos(i + 2, j + 6, k + 9), Blocks.quartz_block.getDefaultState());
		world.setBlockState(new BlockPos(i + 2, j + 6, k + 10), Blocks.quartz_block.getDefaultState());
		world.setBlockState(new BlockPos(i + 2, j + 6, k + 11), Blocks.quartz_block.getDefaultState());
		world.setBlockState(new BlockPos(i + 2, j + 6, k + 12), Blocks.quartz_block.getDefaultState());
		world.setBlockState(new BlockPos(i + 2, j + 6, k + 13), Blocks.quartz_block.getDefaultState());
		world.setBlockState(new BlockPos(i + 2, j + 6, k + 14), Blocks.quartz_block.getDefaultState());
		world.setBlockState(new BlockPos(i + 2, j + 6, k + 15), Blocks.quartz_block.getDefaultState());
		world.setBlockState(new BlockPos(i + 2, j + 6, k + 16), Blocks.quartz_block.getDefaultState());
		world.setBlockState(new BlockPos(i + 2, j + 6, k + 17), Blocks.quartz_block.getDefaultState());
		world.setBlockState(new BlockPos(i + 2, j + 6, k + 18), Blocks.quartz_block.getDefaultState());
		world.setBlockState(new BlockPos(i + 2, j + 6, k + 19), Blocks.quartz_block.getDefaultState());
		world.setBlockState(new BlockPos(i + 2, j + 6, k + 20), Blocks.quartz_block.getDefaultState());
		world.setBlockState(new BlockPos(i + 2, j + 6, k + 21), Blocks.quartz_block.getDefaultState());
		world.setBlockState(new BlockPos(i + 2, j + 6, k + 22), Blocks.quartz_block.getDefaultState());
		world.setBlockState(new BlockPos(i + 2, j + 6, k + 23), Blocks.quartz_block.getDefaultState());
		world.setBlockState(new BlockPos(i + 2, j + 6, k + 24), Blocks.quartz_block.getDefaultState());
		world.setBlockState(new BlockPos(i + 2, j + 6, k + 25), Blocks.quartz_block.getDefaultState());
		world.setBlockState(new BlockPos(i + 2, j + 6, k + 26), Blocks.quartz_block.getDefaultState());
		world.setBlockState(new BlockPos(i + 2, j + 6, k + 27), Blocks.quartz_block.getDefaultState());
		world.setBlockState(new BlockPos(i + 2, j + 6, k + 28), Blocks.quartz_block.getDefaultState());
		world.setBlockState(new BlockPos(i + 2, j + 6, k + 29), Blocks.quartz_block.getDefaultState());
		world.setBlockState(new BlockPos(i + 2, j + 6, k + 30), Blocks.quartz_block.getDefaultState());
		world.setBlockState(new BlockPos(i + 2, j + 6, k + 31), Blocks.quartz_block.getDefaultState());
		world.setBlockState(new BlockPos(i + 2, j + 6, k + 32), Blocks.quartz_block.getDefaultState());
		world.setBlockState(new BlockPos(i + 2, j + 6, k + 33), Blocks.quartz_block.getDefaultState());
		world.setBlockState(new BlockPos(i + 2, j + 6, k + 34), Blocks.quartz_block.getDefaultState());
		world.setBlockState(new BlockPos(i + 2, j + 7, k + 5), Blocks.quartz_block.getDefaultState());
		world.setBlockState(new BlockPos(i + 2, j + 7, k + 6), Blocks.quartz_block.getDefaultState());
		world.setBlockState(new BlockPos(i + 2, j + 7, k + 7), Blocks.quartz_block.getDefaultState());
		world.setBlockState(new BlockPos(i + 2, j + 7, k + 8), Blocks.quartz_block.getDefaultState());
		world.setBlockState(new BlockPos(i + 2, j + 7, k + 9), Blocks.quartz_block.getDefaultState());
		world.setBlockState(new BlockPos(i + 2, j + 7, k + 10), Blocks.quartz_block.getDefaultState());
		world.setBlockState(new BlockPos(i + 2, j + 7, k + 11), Blocks.quartz_block.getDefaultState());
		world.setBlockState(new BlockPos(i + 2, j + 7, k + 12), Blocks.quartz_block.getDefaultState());
		world.setBlockState(new BlockPos(i + 2, j + 7, k + 13), Blocks.quartz_block.getDefaultState());
		world.setBlockState(new BlockPos(i + 2, j + 7, k + 14), Blocks.quartz_block.getDefaultState());
		world.setBlockState(new BlockPos(i + 2, j + 7, k + 15), Blocks.quartz_block.getDefaultState());
		world.setBlockState(new BlockPos(i + 2, j + 7, k + 16), Blocks.quartz_block.getDefaultState());
		world.setBlockState(new BlockPos(i + 2, j + 7, k + 17), Blocks.quartz_block.getDefaultState());
		world.setBlockState(new BlockPos(i + 2, j + 7, k + 18), Blocks.quartz_block.getDefaultState());
		world.setBlockState(new BlockPos(i + 2, j + 7, k + 19), Blocks.quartz_block.getDefaultState());
		world.setBlockState(new BlockPos(i + 2, j + 7, k + 20), Blocks.quartz_block.getDefaultState());
		world.setBlockState(new BlockPos(i + 2, j + 7, k + 21), Blocks.quartz_block.getDefaultState());
		world.setBlockState(new BlockPos(i + 2, j + 7, k + 22), Blocks.quartz_block.getDefaultState());
		world.setBlockState(new BlockPos(i + 2, j + 7, k + 23), Blocks.quartz_block.getDefaultState());
		world.setBlockState(new BlockPos(i + 2, j + 7, k + 24), Blocks.quartz_block.getDefaultState());
		world.setBlockState(new BlockPos(i + 2, j + 7, k + 25), Blocks.quartz_block.getDefaultState());
		world.setBlockState(new BlockPos(i + 2, j + 7, k + 26), Blocks.quartz_block.getDefaultState());
		world.setBlockState(new BlockPos(i + 2, j + 7, k + 27), Blocks.quartz_block.getDefaultState());
		world.setBlockState(new BlockPos(i + 2, j + 7, k + 28), Blocks.quartz_block.getDefaultState());
		world.setBlockState(new BlockPos(i + 2, j + 7, k + 29), Blocks.quartz_block.getDefaultState());
		world.setBlockState(new BlockPos(i + 2, j + 7, k + 30), Blocks.quartz_block.getDefaultState());
		world.setBlockState(new BlockPos(i + 2, j + 7, k + 31), Blocks.quartz_block.getDefaultState());
		world.setBlockState(new BlockPos(i + 2, j + 7, k + 32), Blocks.quartz_block.getDefaultState());
		world.setBlockState(new BlockPos(i + 2, j + 7, k + 33), Blocks.quartz_block.getDefaultState());
		world.setBlockState(new BlockPos(i + 2, j + 7, k + 34), Blocks.quartz_block.getDefaultState());
		world.setBlockState(new BlockPos(i + 2, j + 8, k + 5), Blocks.quartz_block.getDefaultState());
		world.setBlockState(new BlockPos(i + 2, j + 8, k + 6), Blocks.quartz_block.getDefaultState());
		world.setBlockState(new BlockPos(i + 2, j + 8, k + 7), Blocks.quartz_block.getDefaultState());
		world.setBlockState(new BlockPos(i + 2, j + 8, k + 8), Blocks.quartz_block.getDefaultState());
		world.setBlockState(new BlockPos(i + 2, j + 8, k + 9), Blocks.quartz_block.getDefaultState());
		world.setBlockState(new BlockPos(i + 2, j + 8, k + 10), Blocks.quartz_block.getDefaultState());
		world.setBlockState(new BlockPos(i + 2, j + 8, k + 11), Blocks.quartz_block.getDefaultState());
		world.setBlockState(new BlockPos(i + 2, j + 8, k + 12), Blocks.quartz_block.getDefaultState());
		world.setBlockState(new BlockPos(i + 2, j + 8, k + 13), Blocks.quartz_block.getDefaultState());
		world.setBlockState(new BlockPos(i + 2, j + 8, k + 14), Blocks.quartz_block.getDefaultState());
		world.setBlockState(new BlockPos(i + 2, j + 8, k + 15), Blocks.quartz_block.getDefaultState());
		world.setBlockState(new BlockPos(i + 2, j + 8, k + 16), Blocks.quartz_block.getDefaultState());
		world.setBlockState(new BlockPos(i + 2, j + 8, k + 17), Blocks.quartz_block.getDefaultState());
		world.setBlockState(new BlockPos(i + 2, j + 8, k + 18), Blocks.quartz_block.getDefaultState());
		world.setBlockState(new BlockPos(i + 2, j + 8, k + 19), Blocks.quartz_block.getDefaultState());
		world.setBlockState(new BlockPos(i + 2, j + 8, k + 20), Blocks.quartz_block.getDefaultState());
		world.setBlockState(new BlockPos(i + 2, j + 8, k + 21), Blocks.quartz_block.getDefaultState());
		world.setBlockState(new BlockPos(i + 2, j + 8, k + 22), Blocks.quartz_block.getDefaultState());
		world.setBlockState(new BlockPos(i + 2, j + 8, k + 23), Blocks.quartz_block.getDefaultState());
		world.setBlockState(new BlockPos(i + 2, j + 8, k + 24), Blocks.quartz_block.getDefaultState());
		world.setBlockState(new BlockPos(i + 2, j + 8, k + 25), Blocks.quartz_block.getDefaultState());
		world.setBlockState(new BlockPos(i + 2, j + 8, k + 26), Blocks.quartz_block.getDefaultState());
		world.setBlockState(new BlockPos(i + 2, j + 8, k + 27), Blocks.quartz_block.getDefaultState());
		world.setBlockState(new BlockPos(i + 2, j + 8, k + 28), Blocks.quartz_block.getDefaultState());
		world.setBlockState(new BlockPos(i + 2, j + 8, k + 29), Blocks.quartz_block.getDefaultState());
		world.setBlockState(new BlockPos(i + 2, j + 8, k + 30), Blocks.quartz_block.getDefaultState());
		world.setBlockState(new BlockPos(i + 2, j + 8, k + 31), Blocks.quartz_block.getDefaultState());
		world.setBlockState(new BlockPos(i + 2, j + 8, k + 32), Blocks.quartz_block.getDefaultState());
		world.setBlockState(new BlockPos(i + 2, j + 8, k + 33), Blocks.quartz_block.getDefaultState());
		world.setBlockState(new BlockPos(i + 2, j + 8, k + 34), Blocks.quartz_block.getDefaultState());
		world.setBlockState(new BlockPos(i + 2, j + 9, k + 5), Blocks.quartz_block.getDefaultState());
		world.setBlockState(new BlockPos(i + 2, j + 9, k + 6), Blocks.quartz_block.getDefaultState());
		world.setBlockState(new BlockPos(i + 2, j + 9, k + 7), Blocks.quartz_block.getDefaultState());
		world.setBlockState(new BlockPos(i + 2, j + 9, k + 8), Blocks.quartz_block.getDefaultState());
		world.setBlockState(new BlockPos(i + 2, j + 9, k + 9), Blocks.quartz_block.getDefaultState());
		world.setBlockState(new BlockPos(i + 2, j + 9, k + 10), Blocks.quartz_block.getDefaultState());
		world.setBlockState(new BlockPos(i + 2, j + 9, k + 11), Blocks.quartz_block.getDefaultState());
		world.setBlockState(new BlockPos(i + 2, j + 9, k + 12), Blocks.quartz_block.getDefaultState());
		world.setBlockState(new BlockPos(i + 2, j + 9, k + 13), Blocks.quartz_block.getDefaultState());
		world.setBlockState(new BlockPos(i + 2, j + 9, k + 14), Blocks.quartz_block.getDefaultState());
		world.setBlockState(new BlockPos(i + 2, j + 9, k + 15), Blocks.quartz_block.getDefaultState());
		world.setBlockState(new BlockPos(i + 2, j + 9, k + 16), Blocks.quartz_block.getDefaultState());
		world.setBlockState(new BlockPos(i + 2, j + 9, k + 17), Blocks.quartz_block.getDefaultState());
		world.setBlockState(new BlockPos(i + 2, j + 9, k + 18), Blocks.quartz_block.getDefaultState());
		world.setBlockState(new BlockPos(i + 2, j + 9, k + 19), Blocks.quartz_block.getDefaultState());
		world.setBlockState(new BlockPos(i + 2, j + 9, k + 20), Blocks.quartz_block.getDefaultState());
		world.setBlockState(new BlockPos(i + 2, j + 9, k + 21), Blocks.quartz_block.getDefaultState());
		world.setBlockState(new BlockPos(i + 2, j + 9, k + 22), Blocks.quartz_block.getDefaultState());
		world.setBlockState(new BlockPos(i + 2, j + 9, k + 23), Blocks.quartz_block.getDefaultState());
		world.setBlockState(new BlockPos(i + 2, j + 9, k + 24), Blocks.quartz_block.getDefaultState());
		world.setBlockState(new BlockPos(i + 2, j + 9, k + 25), Blocks.quartz_block.getDefaultState());
		world.setBlockState(new BlockPos(i + 2, j + 9, k + 26), Blocks.quartz_block.getDefaultState());
		world.setBlockState(new BlockPos(i + 2, j + 9, k + 27), Blocks.quartz_block.getDefaultState());
		world.setBlockState(new BlockPos(i + 2, j + 9, k + 28), Blocks.quartz_block.getDefaultState());
		world.setBlockState(new BlockPos(i + 2, j + 9, k + 29), Blocks.quartz_block.getDefaultState());
		world.setBlockState(new BlockPos(i + 2, j + 9, k + 30), Blocks.quartz_block.getDefaultState());
		world.setBlockState(new BlockPos(i + 2, j + 9, k + 31), Blocks.quartz_block.getDefaultState());
		world.setBlockState(new BlockPos(i + 2, j + 9, k + 32), Blocks.quartz_block.getDefaultState());
		world.setBlockState(new BlockPos(i + 2, j + 9, k + 33), Blocks.quartz_block.getDefaultState());
		world.setBlockState(new BlockPos(i + 2, j + 9, k + 34), Blocks.quartz_block.getDefaultState());
		world.setBlockState(new BlockPos(i + 2, j + 10, k + 2), Blocks.quartz_block.getDefaultState());
		world.setBlockState(new BlockPos(i + 2, j + 10, k + 3), Blocks.quartz_block.getDefaultState());
		world.setBlockState(new BlockPos(i + 2, j + 10, k + 4), Blocks.quartz_block.getDefaultState());
		world.setBlockState(new BlockPos(i + 2, j + 10, k + 5), Blocks.quartz_block.getDefaultState());
		world.setBlockState(new BlockPos(i + 2, j + 10, k + 6), Blocks.quartz_block.getDefaultState());
		world.setBlockState(new BlockPos(i + 2, j + 10, k + 7), Blocks.quartz_block.getDefaultState());
		world.setBlockState(new BlockPos(i + 2, j + 10, k + 8), Blocks.quartz_block.getDefaultState());
		world.setBlockState(new BlockPos(i + 2, j + 10, k + 9), Blocks.quartz_block.getDefaultState());
		world.setBlockState(new BlockPos(i + 2, j + 10, k + 10), Blocks.quartz_block.getDefaultState());
		world.setBlockState(new BlockPos(i + 2, j + 10, k + 11), Blocks.quartz_block.getDefaultState());
		world.setBlockState(new BlockPos(i + 2, j + 10, k + 12), Blocks.quartz_block.getDefaultState());
		world.setBlockState(new BlockPos(i + 2, j + 10, k + 13), Blocks.quartz_block.getDefaultState());
		world.setBlockState(new BlockPos(i + 2, j + 10, k + 14), Blocks.quartz_block.getDefaultState());
		world.setBlockState(new BlockPos(i + 2, j + 10, k + 15), Blocks.quartz_block.getDefaultState());
		world.setBlockState(new BlockPos(i + 2, j + 10, k + 16), Blocks.quartz_block.getDefaultState());
		world.setBlockState(new BlockPos(i + 2, j + 10, k + 17), Blocks.quartz_block.getDefaultState());
		world.setBlockState(new BlockPos(i + 2, j + 10, k + 18), Blocks.quartz_block.getDefaultState());
		world.setBlockState(new BlockPos(i + 2, j + 10, k + 19), Blocks.quartz_block.getDefaultState());
		world.setBlockState(new BlockPos(i + 2, j + 10, k + 20), Blocks.quartz_block.getDefaultState());
		world.setBlockState(new BlockPos(i + 2, j + 10, k + 21), Blocks.quartz_block.getDefaultState());
		world.setBlockState(new BlockPos(i + 2, j + 10, k + 22), Blocks.quartz_block.getDefaultState());
		world.setBlockState(new BlockPos(i + 2, j + 10, k + 23), Blocks.quartz_block.getDefaultState());
		world.setBlockState(new BlockPos(i + 2, j + 10, k + 24), Blocks.quartz_block.getDefaultState());
		world.setBlockState(new BlockPos(i + 2, j + 10, k + 25), Blocks.quartz_block.getDefaultState());
		world.setBlockState(new BlockPos(i + 2, j + 10, k + 26), Blocks.quartz_block.getDefaultState());
		world.setBlockState(new BlockPos(i + 2, j + 10, k + 27), Blocks.quartz_block.getDefaultState());
		world.setBlockState(new BlockPos(i + 2, j + 10, k + 28), Blocks.quartz_block.getDefaultState());
		world.setBlockState(new BlockPos(i + 2, j + 10, k + 29), Blocks.quartz_block.getDefaultState());
		world.setBlockState(new BlockPos(i + 2, j + 10, k + 30), Blocks.quartz_block.getDefaultState());
		world.setBlockState(new BlockPos(i + 2, j + 10, k + 31), Blocks.quartz_block.getDefaultState());
		world.setBlockState(new BlockPos(i + 2, j + 10, k + 32), Blocks.quartz_block.getDefaultState());
		world.setBlockState(new BlockPos(i + 2, j + 10, k + 33), Blocks.quartz_block.getDefaultState());
		world.setBlockState(new BlockPos(i + 2, j + 10, k + 34), Blocks.quartz_block.getDefaultState());
		world.setBlockState(new BlockPos(i + 2, j + 10, k + 35), Blocks.quartz_block.getDefaultState());

		world.setBlockState(new BlockPos(i + 2, j + 11, k + 4), Blocks.quartz_block.getDefaultState());
		world.setBlockState(new BlockPos(i + 2, j + 11, k + 5), Blocks.quartz_block.getDefaultState());
		world.setBlockState(new BlockPos(i + 2, j + 11, k + 6), Blocks.quartz_block.getDefaultState());
		world.setBlockState(new BlockPos(i + 2, j + 11, k + 7), Blocks.quartz_block.getDefaultState());
		world.setBlockState(new BlockPos(i + 2, j + 11, k + 8), Blocks.quartz_block.getDefaultState());
		world.setBlockState(new BlockPos(i + 2, j + 11, k + 9), Blocks.quartz_block.getDefaultState());
		world.setBlockState(new BlockPos(i + 2, j + 11, k + 10), Blocks.quartz_block.getDefaultState());
		world.setBlockState(new BlockPos(i + 2, j + 11, k + 11), Blocks.quartz_block.getDefaultState());
		world.setBlockState(new BlockPos(i + 2, j + 11, k + 12), Blocks.quartz_block.getDefaultState());
		world.setBlockState(new BlockPos(i + 2, j + 11, k + 13), Blocks.quartz_block.getDefaultState());
		world.setBlockState(new BlockPos(i + 2, j + 11, k + 14), Blocks.quartz_block.getDefaultState());
		world.setBlockState(new BlockPos(i + 2, j + 11, k + 15), Blocks.quartz_block.getDefaultState());
		world.setBlockState(new BlockPos(i + 2, j + 11, k + 16), Blocks.quartz_block.getDefaultState());
		world.setBlockState(new BlockPos(i + 2, j + 11, k + 17), Blocks.quartz_block.getDefaultState());
		world.setBlockState(new BlockPos(i + 2, j + 11, k + 18), Blocks.quartz_block.getDefaultState());
		world.setBlockState(new BlockPos(i + 2, j + 11, k + 19), Blocks.quartz_block.getDefaultState());
		world.setBlockState(new BlockPos(i + 2, j + 11, k + 20), Blocks.quartz_block.getDefaultState());
		world.setBlockState(new BlockPos(i + 2, j + 11, k + 21), Blocks.quartz_block.getDefaultState());
		world.setBlockState(new BlockPos(i + 2, j + 11, k + 22), Blocks.quartz_block.getDefaultState());
		world.setBlockState(new BlockPos(i + 2, j + 11, k + 23), Blocks.quartz_block.getDefaultState());
		world.setBlockState(new BlockPos(i + 2, j + 11, k + 24), Blocks.quartz_block.getDefaultState());
		world.setBlockState(new BlockPos(i + 2, j + 11, k + 25), Blocks.quartz_block.getDefaultState());
		world.setBlockState(new BlockPos(i + 2, j + 11, k + 26), Blocks.quartz_block.getDefaultState());
		world.setBlockState(new BlockPos(i + 2, j + 11, k + 27), Blocks.quartz_block.getDefaultState());
		world.setBlockState(new BlockPos(i + 2, j + 11, k + 28), Blocks.quartz_block.getDefaultState());
		world.setBlockState(new BlockPos(i + 2, j + 11, k + 29), Blocks.quartz_block.getDefaultState());
		world.setBlockState(new BlockPos(i + 2, j + 11, k + 30), Blocks.quartz_block.getDefaultState());
		world.setBlockState(new BlockPos(i + 2, j + 11, k + 31), Blocks.quartz_block.getDefaultState());
		world.setBlockState(new BlockPos(i + 2, j + 11, k + 32), Blocks.quartz_block.getDefaultState());
		world.setBlockState(new BlockPos(i + 2, j + 11, k + 33), Blocks.quartz_block.getDefaultState());
		world.setBlockState(new BlockPos(i + 2, j + 12, k + 2), Blocks.quartz_block.getDefaultState());
		world.setBlockState(new BlockPos(i + 2, j + 12, k + 3), Blocks.quartz_block.getDefaultState());
		world.setBlockState(new BlockPos(i + 2, j + 12, k + 4), Blocks.quartz_block.getDefaultState());
		world.setBlockState(new BlockPos(i + 2, j + 12, k + 5), Blocks.quartz_block.getDefaultState());
		world.setBlockState(new BlockPos(i + 2, j + 12, k + 6), Blocks.quartz_block.getDefaultState());
		world.setBlockState(new BlockPos(i + 2, j + 12, k + 7), Blocks.quartz_block.getDefaultState());
		world.setBlockState(new BlockPos(i + 2, j + 12, k + 8), Blocks.quartz_block.getDefaultState());
		world.setBlockState(new BlockPos(i + 2, j + 12, k + 9), Blocks.quartz_block.getDefaultState());
		world.setBlockState(new BlockPos(i + 2, j + 12, k + 10), Blocks.quartz_block.getDefaultState());
		world.setBlockState(new BlockPos(i + 2, j + 12, k + 11), Blocks.quartz_block.getDefaultState());
		world.setBlockState(new BlockPos(i + 2, j + 12, k + 12), Blocks.quartz_block.getDefaultState());
		world.setBlockState(new BlockPos(i + 2, j + 12, k + 13), Blocks.quartz_block.getDefaultState());
		world.setBlockState(new BlockPos(i + 2, j + 12, k + 14), Blocks.quartz_block.getDefaultState());
		world.setBlockState(new BlockPos(i + 2, j + 12, k + 15), Blocks.quartz_block.getDefaultState());
		world.setBlockState(new BlockPos(i + 2, j + 12, k + 16), Blocks.quartz_block.getDefaultState());
		world.setBlockState(new BlockPos(i + 2, j + 12, k + 17), Blocks.quartz_block.getDefaultState());
		world.setBlockState(new BlockPos(i + 2, j + 12, k + 18), Blocks.quartz_block.getDefaultState());
		world.setBlockState(new BlockPos(i + 2, j + 12, k + 19), Blocks.quartz_block.getDefaultState());
		world.setBlockState(new BlockPos(i + 2, j + 12, k + 20), Blocks.quartz_block.getDefaultState());
		world.setBlockState(new BlockPos(i + 2, j + 12, k + 21), Blocks.quartz_block.getDefaultState());
		world.setBlockState(new BlockPos(i + 2, j + 12, k + 22), Blocks.quartz_block.getDefaultState());
		world.setBlockState(new BlockPos(i + 2, j + 12, k + 23), Blocks.quartz_block.getDefaultState());
		world.setBlockState(new BlockPos(i + 2, j + 12, k + 24), Blocks.quartz_block.getDefaultState());
		world.setBlockState(new BlockPos(i + 2, j + 12, k + 25), Blocks.quartz_block.getDefaultState());
		world.setBlockState(new BlockPos(i + 2, j + 12, k + 26), Blocks.quartz_block.getDefaultState());
		world.setBlockState(new BlockPos(i + 2, j + 12, k + 27), Blocks.quartz_block.getDefaultState());
		world.setBlockState(new BlockPos(i + 2, j + 12, k + 28), Blocks.quartz_block.getDefaultState());
		world.setBlockState(new BlockPos(i + 2, j + 12, k + 29), Blocks.quartz_block.getDefaultState());
		world.setBlockState(new BlockPos(i + 2, j + 12, k + 30), Blocks.quartz_block.getDefaultState());
		world.setBlockState(new BlockPos(i + 2, j + 12, k + 31), Blocks.quartz_block.getDefaultState());
		world.setBlockState(new BlockPos(i + 2, j + 12, k + 32), Blocks.quartz_block.getDefaultState());
		world.setBlockState(new BlockPos(i + 2, j + 12, k + 33), Blocks.quartz_block.getDefaultState());
		world.setBlockState(new BlockPos(i + 2, j + 12, k + 34), Blocks.quartz_block.getDefaultState());
		world.setBlockState(new BlockPos(i + 2, j + 12, k + 35), Blocks.quartz_block.getDefaultState());
		world.setBlockState(new BlockPos(i + 3, j + 0, k + 1), TriniaBlocks.cloud.getDefaultState());
		world.setBlockState(new BlockPos(i + 3, j + 0, k + 2), TriniaBlocks.cloud.getDefaultState());
		world.setBlockState(new BlockPos(i + 3, j + 0, k + 3), TriniaBlocks.cloud.getDefaultState());
		world.setBlockState(new BlockPos(i + 3, j + 0, k + 4), TriniaBlocks.cloud.getDefaultState());
		world.setBlockState(new BlockPos(i + 3, j + 0, k + 5), TriniaBlocks.cloud.getDefaultState());
		world.setBlockState(new BlockPos(i + 3, j + 0, k + 6), TriniaBlocks.cloud.getDefaultState());
		world.setBlockState(new BlockPos(i + 3, j + 0, k + 7), TriniaBlocks.cloud.getDefaultState());
		world.setBlockState(new BlockPos(i + 3, j + 0, k + 8), TriniaBlocks.cloud.getDefaultState());
		world.setBlockState(new BlockPos(i + 3, j + 0, k + 9), TriniaBlocks.cloud.getDefaultState());
		world.setBlockState(new BlockPos(i + 3, j + 0, k + 10), TriniaBlocks.cloud.getDefaultState());
		world.setBlockState(new BlockPos(i + 3, j + 0, k + 11), TriniaBlocks.cloud.getDefaultState());
		world.setBlockState(new BlockPos(i + 3, j + 0, k + 12), TriniaBlocks.cloud.getDefaultState());
		world.setBlockState(new BlockPos(i + 3, j + 0, k + 13), TriniaBlocks.cloud.getDefaultState());
		world.setBlockState(new BlockPos(i + 3, j + 0, k + 14), TriniaBlocks.cloud.getDefaultState());
		world.setBlockState(new BlockPos(i + 3, j + 0, k + 15), TriniaBlocks.cloud.getDefaultState());
		world.setBlockState(new BlockPos(i + 3, j + 0, k + 16), TriniaBlocks.cloud.getDefaultState());
		world.setBlockState(new BlockPos(i + 3, j + 0, k + 17), TriniaBlocks.cloud.getDefaultState());
		world.setBlockState(new BlockPos(i + 3, j + 0, k + 18), TriniaBlocks.cloud.getDefaultState());
		world.setBlockState(new BlockPos(i + 3, j + 0, k + 19), TriniaBlocks.cloud.getDefaultState());
		world.setBlockState(new BlockPos(i + 3, j + 0, k + 20), TriniaBlocks.cloud.getDefaultState());
		world.setBlockState(new BlockPos(i + 3, j + 0, k + 21), TriniaBlocks.cloud.getDefaultState());
		world.setBlockState(new BlockPos(i + 3, j + 0, k + 22), TriniaBlocks.cloud.getDefaultState());
		world.setBlockState(new BlockPos(i + 3, j + 0, k + 23), TriniaBlocks.cloud.getDefaultState());
		world.setBlockState(new BlockPos(i + 3, j + 0, k + 24), TriniaBlocks.cloud.getDefaultState());
		world.setBlockState(new BlockPos(i + 3, j + 0, k + 25), TriniaBlocks.cloud.getDefaultState());
		world.setBlockState(new BlockPos(i + 3, j + 0, k + 26), TriniaBlocks.cloud.getDefaultState());
		world.setBlockState(new BlockPos(i + 3, j + 0, k + 27), TriniaBlocks.cloud.getDefaultState());
		world.setBlockState(new BlockPos(i + 3, j + 0, k + 28), TriniaBlocks.cloud.getDefaultState());
		world.setBlockState(new BlockPos(i + 3, j + 0, k + 29), TriniaBlocks.cloud.getDefaultState());
		world.setBlockState(new BlockPos(i + 3, j + 0, k + 30), TriniaBlocks.cloud.getDefaultState());
		world.setBlockState(new BlockPos(i + 3, j + 0, k + 31), TriniaBlocks.cloud.getDefaultState());
		world.setBlockState(new BlockPos(i + 3, j + 0, k + 32), TriniaBlocks.cloud.getDefaultState());
		world.setBlockState(new BlockPos(i + 3, j + 0, k + 33), TriniaBlocks.cloud.getDefaultState());
		world.setBlockState(new BlockPos(i + 3, j + 0, k + 34), TriniaBlocks.cloud.getDefaultState());
		world.setBlockState(new BlockPos(i + 3, j + 0, k + 35), TriniaBlocks.cloud.getDefaultState());
		world.setBlockState(new BlockPos(i + 3, j + 1, k + 0), TriniaBlocks.cloud.getDefaultState());
		world.setBlockState(new BlockPos(i + 3, j + 1, k + 1), TriniaBlocks.cloud.getDefaultState());
		world.setBlockState(new BlockPos(i + 3, j + 1, k + 2), TriniaBlocks.cloud.getDefaultState());
		world.setBlockState(new BlockPos(i + 3, j + 1, k + 3), TriniaBlocks.cloud.getDefaultState());
		world.setBlockState(new BlockPos(i + 3, j + 1, k + 4), TriniaBlocks.cloud.getDefaultState());
		world.setBlockState(new BlockPos(i + 3, j + 1, k + 5), TriniaBlocks.cloud.getDefaultState());
		world.setBlockState(new BlockPos(i + 3, j + 1, k + 6), TriniaBlocks.cloud.getDefaultState());
		world.setBlockState(new BlockPos(i + 3, j + 1, k + 7), TriniaBlocks.cloud.getDefaultState());
		world.setBlockState(new BlockPos(i + 3, j + 1, k + 8), TriniaBlocks.cloud.getDefaultState());
		world.setBlockState(new BlockPos(i + 3, j + 1, k + 9), TriniaBlocks.cloud.getDefaultState());
		world.setBlockState(new BlockPos(i + 3, j + 1, k + 10), TriniaBlocks.cloud.getDefaultState());
		world.setBlockState(new BlockPos(i + 3, j + 1, k + 11), TriniaBlocks.cloud.getDefaultState());
		world.setBlockState(new BlockPos(i + 3, j + 1, k + 12), TriniaBlocks.cloud.getDefaultState());
		world.setBlockState(new BlockPos(i + 3, j + 1, k + 13), TriniaBlocks.cloud.getDefaultState());
		world.setBlockState(new BlockPos(i + 3, j + 1, k + 14), TriniaBlocks.cloud.getDefaultState());
		world.setBlockState(new BlockPos(i + 3, j + 1, k + 15), TriniaBlocks.cloud.getDefaultState());
		world.setBlockState(new BlockPos(i + 3, j + 1, k + 16), TriniaBlocks.cloud.getDefaultState());
		world.setBlockState(new BlockPos(i + 3, j + 1, k + 17), TriniaBlocks.cloud.getDefaultState());
		world.setBlockState(new BlockPos(i + 3, j + 1, k + 18), TriniaBlocks.cloud.getDefaultState());
		world.setBlockState(new BlockPos(i + 3, j + 1, k + 19), TriniaBlocks.cloud.getDefaultState());
		world.setBlockState(new BlockPos(i + 3, j + 1, k + 20), TriniaBlocks.cloud.getDefaultState());
		world.setBlockState(new BlockPos(i + 3, j + 1, k + 21), TriniaBlocks.cloud.getDefaultState());
		world.setBlockState(new BlockPos(i + 3, j + 1, k + 22), TriniaBlocks.cloud.getDefaultState());
		world.setBlockState(new BlockPos(i + 3, j + 1, k + 23), TriniaBlocks.cloud.getDefaultState());
		world.setBlockState(new BlockPos(i + 3, j + 1, k + 24), TriniaBlocks.cloud.getDefaultState());
		world.setBlockState(new BlockPos(i + 3, j + 1, k + 25), TriniaBlocks.cloud.getDefaultState());
		world.setBlockState(new BlockPos(i + 3, j + 1, k + 26), TriniaBlocks.cloud.getDefaultState());
		world.setBlockState(new BlockPos(i + 3, j + 1, k + 27), TriniaBlocks.cloud.getDefaultState());
		world.setBlockState(new BlockPos(i + 3, j + 1, k + 28), TriniaBlocks.cloud.getDefaultState());
		world.setBlockState(new BlockPos(i + 3, j + 1, k + 29), TriniaBlocks.cloud.getDefaultState());
		world.setBlockState(new BlockPos(i + 3, j + 1, k + 30), TriniaBlocks.cloud.getDefaultState());
		world.setBlockState(new BlockPos(i + 3, j + 1, k + 31), TriniaBlocks.cloud.getDefaultState());
		world.setBlockState(new BlockPos(i + 3, j + 1, k + 32), TriniaBlocks.cloud.getDefaultState());
		world.setBlockState(new BlockPos(i + 3, j + 1, k + 33), TriniaBlocks.cloud.getDefaultState());
		world.setBlockState(new BlockPos(i + 3, j + 1, k + 34), TriniaBlocks.cloud.getDefaultState());
		world.setBlockState(new BlockPos(i + 3, j + 1, k + 35), TriniaBlocks.cloud.getDefaultState());
		world.setBlockState(new BlockPos(i + 3, j + 1, k + 36), TriniaBlocks.cloud.getDefaultState());
		world.setBlockState(new BlockPos(i + 3, j + 2, k + 0), TriniaBlocks.cloud.getDefaultState());
		world.setBlockState(new BlockPos(i + 3, j + 2, k + 1), TriniaBlocks.cloud.getDefaultState());
		world.setBlockState(new BlockPos(i + 3, j + 2, k + 2), TriniaBlocks.cloud.getDefaultState());
		world.setBlockState(new BlockPos(i + 3, j + 2, k + 3), TriniaBlocks.cloud.getDefaultState());
		world.setBlockState(new BlockPos(i + 3, j + 2, k + 4), TriniaBlocks.cloud.getDefaultState());
		world.setBlockState(new BlockPos(i + 3, j + 2, k + 5), TriniaBlocks.cloud.getDefaultState());
		world.setBlockState(new BlockPos(i + 3, j + 2, k + 6), TriniaBlocks.cloud.getDefaultState());
		world.setBlockState(new BlockPos(i + 3, j + 2, k + 7), TriniaBlocks.cloud.getDefaultState());
		world.setBlockState(new BlockPos(i + 3, j + 2, k + 8), TriniaBlocks.cloud.getDefaultState());
		world.setBlockState(new BlockPos(i + 3, j + 2, k + 9), TriniaBlocks.cloud.getDefaultState());
		world.setBlockState(new BlockPos(i + 3, j + 2, k + 10), TriniaBlocks.cloud.getDefaultState());
		world.setBlockState(new BlockPos(i + 3, j + 2, k + 11), TriniaBlocks.cloud.getDefaultState());
		world.setBlockState(new BlockPos(i + 3, j + 2, k + 12), TriniaBlocks.cloud.getDefaultState());
		world.setBlockState(new BlockPos(i + 3, j + 2, k + 13), TriniaBlocks.cloud.getDefaultState());
		world.setBlockState(new BlockPos(i + 3, j + 2, k + 14), TriniaBlocks.cloud.getDefaultState());
		world.setBlockState(new BlockPos(i + 3, j + 2, k + 15), TriniaBlocks.cloud.getDefaultState());
		world.setBlockState(new BlockPos(i + 3, j + 2, k + 16), TriniaBlocks.cloud.getDefaultState());
		world.setBlockState(new BlockPos(i + 3, j + 2, k + 17), TriniaBlocks.cloud.getDefaultState());
		world.setBlockState(new BlockPos(i + 3, j + 2, k + 18), TriniaBlocks.cloud.getDefaultState());
		world.setBlockState(new BlockPos(i + 3, j + 2, k + 19), TriniaBlocks.cloud.getDefaultState());
		world.setBlockState(new BlockPos(i + 3, j + 2, k + 20), TriniaBlocks.cloud.getDefaultState());
		world.setBlockState(new BlockPos(i + 3, j + 2, k + 21), TriniaBlocks.cloud.getDefaultState());
		world.setBlockState(new BlockPos(i + 3, j + 2, k + 22), TriniaBlocks.cloud.getDefaultState());
		world.setBlockState(new BlockPos(i + 3, j + 2, k + 23), TriniaBlocks.cloud.getDefaultState());
		world.setBlockState(new BlockPos(i + 3, j + 2, k + 24), TriniaBlocks.cloud.getDefaultState());
		world.setBlockState(new BlockPos(i + 3, j + 2, k + 25), TriniaBlocks.cloud.getDefaultState());
		world.setBlockState(new BlockPos(i + 3, j + 2, k + 26), TriniaBlocks.cloud.getDefaultState());
		world.setBlockState(new BlockPos(i + 3, j + 2, k + 27), TriniaBlocks.cloud.getDefaultState());
		world.setBlockState(new BlockPos(i + 3, j + 2, k + 28), TriniaBlocks.cloud.getDefaultState());
		world.setBlockState(new BlockPos(i + 3, j + 2, k + 29), TriniaBlocks.cloud.getDefaultState());
		world.setBlockState(new BlockPos(i + 3, j + 2, k + 30), TriniaBlocks.cloud.getDefaultState());
		world.setBlockState(new BlockPos(i + 3, j + 2, k + 31), TriniaBlocks.cloud.getDefaultState());
		world.setBlockState(new BlockPos(i + 3, j + 2, k + 32), TriniaBlocks.cloud.getDefaultState());
		world.setBlockState(new BlockPos(i + 3, j + 2, k + 33), TriniaBlocks.cloud.getDefaultState());
		world.setBlockState(new BlockPos(i + 3, j + 2, k + 34), TriniaBlocks.cloud.getDefaultState());
		world.setBlockState(new BlockPos(i + 3, j + 2, k + 35), TriniaBlocks.cloud.getDefaultState());
		world.setBlockState(new BlockPos(i + 3, j + 2, k + 36), TriniaBlocks.cloud.getDefaultState());
		world.setBlockState(new BlockPos(i + 3, j + 3, k + 1), TriniaBlocks.cloud.getDefaultState());
		world.setBlockState(new BlockPos(i + 3, j + 3, k + 2), Blocks.quartz_block.getDefaultState());
		world.setBlockState(new BlockPos(i + 3, j + 3, k + 3), Blocks.quartz_block.getDefaultState());
		world.setBlockState(new BlockPos(i + 3, j + 3, k + 4), Blocks.quartz_block.getDefaultState());
		world.setBlockState(new BlockPos(i + 3, j + 3, k + 5), Blocks.quartz_block.getDefaultState());
		world.setBlockState(new BlockPos(i + 3, j + 3, k + 6), Blocks.quartz_block.getDefaultState());
		world.setBlockState(new BlockPos(i + 3, j + 3, k + 7), Blocks.quartz_block.getDefaultState());
		world.setBlockState(new BlockPos(i + 3, j + 3, k + 8), Blocks.quartz_block.getDefaultState());
		world.setBlockState(new BlockPos(i + 3, j + 3, k + 9), Blocks.quartz_block.getDefaultState());
		world.setBlockState(new BlockPos(i + 3, j + 3, k + 10), Blocks.quartz_block.getDefaultState());
		world.setBlockState(new BlockPos(i + 3, j + 3, k + 11), Blocks.quartz_block.getDefaultState());
		world.setBlockState(new BlockPos(i + 3, j + 3, k + 12), Blocks.quartz_block.getDefaultState());
		world.setBlockState(new BlockPos(i + 3, j + 3, k + 13), Blocks.quartz_block.getDefaultState());
		world.setBlockState(new BlockPos(i + 3, j + 3, k + 14), Blocks.quartz_block.getDefaultState());
		world.setBlockState(new BlockPos(i + 3, j + 3, k + 15), Blocks.quartz_block.getDefaultState());
		world.setBlockState(new BlockPos(i + 3, j + 3, k + 16), Blocks.quartz_block.getDefaultState());
		world.setBlockState(new BlockPos(i + 3, j + 3, k + 17), Blocks.quartz_block.getDefaultState());
		world.setBlockState(new BlockPos(i + 3, j + 3, k + 18), Blocks.quartz_block.getDefaultState());
		world.setBlockState(new BlockPos(i + 3, j + 3, k + 19), Blocks.quartz_block.getDefaultState());
		world.setBlockState(new BlockPos(i + 3, j + 3, k + 20), Blocks.quartz_block.getDefaultState());

		world.setBlockState(new BlockPos(i + 3, j + 3, k + 34), Blocks.quartz_block.getDefaultState());
		world.setBlockState(new BlockPos(i + 3, j + 3, k + 35), TriniaBlocks.cloud.getDefaultState());
		world.setBlockState(new BlockPos(i + 3, j + 4, k + 2), Blocks.quartz_block.getDefaultState());
		world.setBlockState(new BlockPos(i + 3, j + 4, k + 3), Blocks.quartz_block.getDefaultState());
		world.setBlockState(new BlockPos(i + 3, j + 4, k + 4), Blocks.quartz_block.getDefaultState());
		world.setBlockState(new BlockPos(i + 3, j + 4, k + 5), Blocks.quartz_block.getDefaultState());
		world.setBlockState(new BlockPos(i + 3, j + 4, k + 6), Blocks.quartz_block.getDefaultState());
		world.setBlockState(new BlockPos(i + 3, j + 4, k + 7), Blocks.quartz_block.getDefaultState());
		world.setBlockState(new BlockPos(i + 3, j + 4, k + 8), Blocks.quartz_block.getDefaultState());
		world.setBlockState(new BlockPos(i + 3, j + 4, k + 9), Blocks.quartz_block.getDefaultState());
		world.setBlockState(new BlockPos(i + 3, j + 4, k + 10), Blocks.quartz_block.getDefaultState());
		world.setBlockState(new BlockPos(i + 3, j + 4, k + 11), Blocks.quartz_block.getDefaultState());
		world.setBlockState(new BlockPos(i + 3, j + 4, k + 12), Blocks.quartz_block.getDefaultState());
		world.setBlockState(new BlockPos(i + 3, j + 4, k + 13), Blocks.quartz_block.getDefaultState());
		world.setBlockState(new BlockPos(i + 3, j + 4, k + 14), Blocks.quartz_block.getDefaultState());
		world.setBlockState(new BlockPos(i + 3, j + 4, k + 15), Blocks.quartz_block.getDefaultState());
		world.setBlockState(new BlockPos(i + 3, j + 4, k + 20), Blocks.quartz_block.getDefaultState());
		world.setBlockState(new BlockPos(i + 3, j + 4, k + 31), Blocks.quartz_block.getDefaultState());
		world.setBlockState(new BlockPos(i + 3, j + 4, k + 32), Blocks.quartz_block.getDefaultState());
		
		world.setBlockState(new BlockPos(i + 3, j + 4, k + 34), Blocks.quartz_block.getDefaultState());
		
		world.setBlockState(new BlockPos(i + 3, j + 5, k + 5), Blocks.quartz_block.getDefaultState());
		world.setBlockState(new BlockPos(i + 3, j + 5, k + 6), Blocks.quartz_block.getDefaultState());
		world.setBlockState(new BlockPos(i + 3, j + 5, k + 7), Blocks.quartz_block.getDefaultState());
		world.setBlockState(new BlockPos(i + 3, j + 5, k + 8), Blocks.quartz_block.getDefaultState());
		world.setBlockState(new BlockPos(i + 3, j + 5, k + 9), Blocks.quartz_block.getDefaultState());
		world.setBlockState(new BlockPos(i + 3, j + 5, k + 11), Blocks.quartz_block.getDefaultState());
		world.setBlockState(new BlockPos(i + 3, j + 5, k + 20), Blocks.quartz_block.getDefaultState());
		
		world.setBlockState(new BlockPos(i + 3, j + 5, k + 34), Blocks.quartz_block.getDefaultState());
		
		world.setBlockState(new BlockPos(i + 3, j + 6, k + 5), Blocks.quartz_block.getDefaultState());
		
		world.setBlockState(new BlockPos(i + 3, j + 6, k + 9), Blocks.quartz_block.getDefaultState());
		world.setBlockState(new BlockPos(i + 3, j + 6, k + 20), Blocks.quartz_block.getDefaultState());
		
		world.setBlockState(new BlockPos(i + 3, j + 6, k + 34), Blocks.quartz_block.getDefaultState());
		
		world.setBlockState(new BlockPos(i + 3, j + 7, k + 5), Blocks.quartz_block.getDefaultState());
	
		world.setBlockState(new BlockPos(i + 3, j + 7, k + 10), Blocks.quartz_block.getDefaultState());
		world.setBlockState(new BlockPos(i + 3, j + 7, k + 12), Blocks.quartz_block.getDefaultState());
		world.setBlockState(new BlockPos(i + 3, j + 7, k + 13), Blocks.quartz_block.getDefaultState());
		world.setBlockState(new BlockPos(i + 3, j + 7, k + 14), Blocks.quartz_block.getDefaultState());
		world.setBlockState(new BlockPos(i + 3, j + 7, k + 15), Blocks.quartz_block.getDefaultState());
		world.setBlockState(new BlockPos(i + 3, j + 7, k + 16), Blocks.quartz_block.getDefaultState());
		world.setBlockState(new BlockPos(i + 3, j + 7, k + 17), Blocks.quartz_block.getDefaultState());
		world.setBlockState(new BlockPos(i + 3, j + 7, k + 18), Blocks.quartz_block.getDefaultState());
		world.setBlockState(new BlockPos(i + 3, j + 7, k + 19), Blocks.quartz_block.getDefaultState());
		world.setBlockState(new BlockPos(i + 3, j + 7, k + 20), Blocks.quartz_block.getDefaultState());
		
		world.setBlockState(new BlockPos(i + 3, j + 7, k + 34), Blocks.quartz_block.getDefaultState());
		
		world.setBlockState(new BlockPos(i + 3, j + 8, k + 5), Blocks.quartz_block.getDefaultState());
		
		world.setBlockState(new BlockPos(i + 3, j + 8, k + 11), Blocks.quartz_block.getDefaultState());
		world.setBlockState(new BlockPos(i + 3, j + 8, k + 12), Blocks.quartz_block.getDefaultState());
		world.setBlockState(new BlockPos(i + 3, j + 8, k + 13), Blocks.quartz_block.getDefaultState());

		world.setBlockState(new BlockPos(i + 3, j + 8, k + 19), Blocks.quartz_block.getDefaultState());
		world.setBlockState(new BlockPos(i + 3, j + 8, k + 20), Blocks.quartz_block.getDefaultState());

		world.setBlockState(new BlockPos(i + 3, j + 8, k + 34), Blocks.quartz_block.getDefaultState());

		world.setBlockState(new BlockPos(i + 3, j + 9, k + 5), Blocks.quartz_block.getDefaultState());
		world.setBlockState(new BlockPos(i + 3, j + 9, k + 19), Blocks.quartz_block.getDefaultState());
		world.setBlockState(new BlockPos(i + 3, j + 9, k + 20), Blocks.quartz_block.getDefaultState());
	
		world.setBlockState(new BlockPos(i + 3, j + 9, k + 34), Blocks.quartz_block.getDefaultState());
		world.setBlockState(new BlockPos(i + 3, j + 10, k + 2), Blocks.quartz_block.getDefaultState());
		world.setBlockState(new BlockPos(i + 3, j + 10, k + 3), Blocks.quartz_block.getDefaultState());
		world.setBlockState(new BlockPos(i + 3, j + 10, k + 4), Blocks.quartz_block.getDefaultState());
		world.setBlockState(new BlockPos(i + 3, j + 10, k + 5), Blocks.quartz_block.getDefaultState());
		world.setBlockState(new BlockPos(i + 3, j + 10, k + 19), Blocks.quartz_block.getDefaultState());
		world.setBlockState(new BlockPos(i + 3, j + 10, k + 20), Blocks.quartz_block.getDefaultState());
	
		world.setBlockState(new BlockPos(i + 3, j + 10, k + 34), Blocks.quartz_block.getDefaultState());
		world.setBlockState(new BlockPos(i + 3, j + 10, k + 35), Blocks.quartz_block.getDefaultState());

		world.setBlockState(new BlockPos(i + 3, j + 11, k + 4), Blocks.quartz_block.getDefaultState());
		world.setBlockState(new BlockPos(i + 3, j + 11, k + 5), Blocks.quartz_block.getDefaultState());
		world.setBlockState(new BlockPos(i + 3, j + 11, k + 19), Blocks.quartz_block.getDefaultState());
		world.setBlockState(new BlockPos(i + 3, j + 11, k + 20), Blocks.quartz_block.getDefaultState());

		world.setBlockState(new BlockPos(i + 3, j + 12, k + 10), Blocks.quartz_block.getDefaultState());
		world.setBlockState(new BlockPos(i + 3, j + 12, k + 11), Blocks.quartz_block.getDefaultState());
		world.setBlockState(new BlockPos(i + 3, j + 12, k + 12), Blocks.quartz_block.getDefaultState());
		world.setBlockState(new BlockPos(i + 3, j + 12, k + 13), Blocks.quartz_block.getDefaultState());
		world.setBlockState(new BlockPos(i + 3, j + 12, k + 14), Blocks.quartz_block.getDefaultState());
		world.setBlockState(new BlockPos(i + 3, j + 12, k + 15), Blocks.quartz_block.getDefaultState());
		world.setBlockState(new BlockPos(i + 3, j + 12, k + 16), Blocks.quartz_block.getDefaultState());
		world.setBlockState(new BlockPos(i + 3, j + 12, k + 17), Blocks.quartz_block.getDefaultState());
		world.setBlockState(new BlockPos(i + 3, j + 12, k + 18), Blocks.quartz_block.getDefaultState());
		world.setBlockState(new BlockPos(i + 3, j + 12, k + 21), Blocks.quartz_block.getDefaultState());

		world.setBlockState(new BlockPos(i + 3, j + 13, k + 2), Blocks.quartz_block.getDefaultState());
		world.setBlockState(new BlockPos(i + 3, j + 13, k + 3), Blocks.quartz_block.getDefaultState());
		world.setBlockState(new BlockPos(i + 3, j + 13, k + 4), Blocks.quartz_block.getDefaultState());
		world.setBlockState(new BlockPos(i + 3, j + 13, k + 5), Blocks.quartz_block.getDefaultState());
		world.setBlockState(new BlockPos(i + 3, j + 13, k + 6), Blocks.quartz_block.getDefaultState());
		world.setBlockState(new BlockPos(i + 3, j + 13, k + 7), Blocks.quartz_block.getDefaultState());
		world.setBlockState(new BlockPos(i + 3, j + 13, k + 8), Blocks.quartz_block.getDefaultState());
		world.setBlockState(new BlockPos(i + 3, j + 13, k + 9), Blocks.quartz_block.getDefaultState());
		world.setBlockState(new BlockPos(i + 3, j + 13, k + 10), Blocks.quartz_block.getDefaultState());
		world.setBlockState(new BlockPos(i + 3, j + 13, k + 11), Blocks.quartz_block.getDefaultState());
		world.setBlockState(new BlockPos(i + 3, j + 13, k + 12), Blocks.quartz_block.getDefaultState());
		world.setBlockState(new BlockPos(i + 3, j + 13, k + 13), Blocks.quartz_block.getDefaultState());
		world.setBlockState(new BlockPos(i + 3, j + 13, k + 14), Blocks.quartz_block.getDefaultState());
		world.setBlockState(new BlockPos(i + 3, j + 13, k + 15), Blocks.quartz_block.getDefaultState());
		world.setBlockState(new BlockPos(i + 3, j + 13, k + 16), Blocks.quartz_block.getDefaultState());
		world.setBlockState(new BlockPos(i + 3, j + 13, k + 17), Blocks.quartz_block.getDefaultState());
		world.setBlockState(new BlockPos(i + 3, j + 13, k + 18), Blocks.quartz_block.getDefaultState());
		world.setBlockState(new BlockPos(i + 3, j + 13, k + 19), Blocks.quartz_block.getDefaultState());
		world.setBlockState(new BlockPos(i + 3, j + 13, k + 20), Blocks.quartz_block.getDefaultState());
		world.setBlockState(new BlockPos(i + 3, j + 13, k + 21), Blocks.quartz_block.getDefaultState());
		world.setBlockState(new BlockPos(i + 3, j + 13, k + 22), Blocks.quartz_block.getDefaultState());
		world.setBlockState(new BlockPos(i + 3, j + 13, k + 23), Blocks.quartz_block.getDefaultState());
		world.setBlockState(new BlockPos(i + 3, j + 13, k + 24), Blocks.quartz_block.getDefaultState());
		world.setBlockState(new BlockPos(i + 3, j + 13, k + 25), Blocks.quartz_block.getDefaultState());
		world.setBlockState(new BlockPos(i + 3, j + 13, k + 26), Blocks.quartz_block.getDefaultState());
		world.setBlockState(new BlockPos(i + 3, j + 13, k + 27), Blocks.quartz_block.getDefaultState());
		world.setBlockState(new BlockPos(i + 3, j + 13, k + 28), Blocks.quartz_block.getDefaultState());
		world.setBlockState(new BlockPos(i + 3, j + 13, k + 29), Blocks.quartz_block.getDefaultState());
		world.setBlockState(new BlockPos(i + 3, j + 13, k + 30), Blocks.quartz_block.getDefaultState());
		world.setBlockState(new BlockPos(i + 3, j + 13, k + 31), Blocks.quartz_block.getDefaultState());
		world.setBlockState(new BlockPos(i + 3, j + 13, k + 32), Blocks.quartz_block.getDefaultState());
		world.setBlockState(new BlockPos(i + 3, j + 13, k + 33), Blocks.quartz_block.getDefaultState());
		world.setBlockState(new BlockPos(i + 3, j + 13, k + 34), Blocks.quartz_block.getDefaultState());
		world.setBlockState(new BlockPos(i + 3, j + 13, k + 35), Blocks.quartz_block.getDefaultState());
		world.setBlockState(new BlockPos(i + 4, j + 0, k + 1), TriniaBlocks.cloud.getDefaultState());
		world.setBlockState(new BlockPos(i + 4, j + 0, k + 2), TriniaBlocks.cloud.getDefaultState());
		world.setBlockState(new BlockPos(i + 4, j + 0, k + 3), TriniaBlocks.cloud.getDefaultState());
		world.setBlockState(new BlockPos(i + 4, j + 0, k + 4), TriniaBlocks.cloud.getDefaultState());
		world.setBlockState(new BlockPos(i + 4, j + 0, k + 5), TriniaBlocks.cloud.getDefaultState());
		world.setBlockState(new BlockPos(i + 4, j + 0, k + 6), TriniaBlocks.cloud.getDefaultState());
		world.setBlockState(new BlockPos(i + 4, j + 0, k + 7), TriniaBlocks.cloud.getDefaultState());
		world.setBlockState(new BlockPos(i + 4, j + 0, k + 8), TriniaBlocks.cloud.getDefaultState());
		world.setBlockState(new BlockPos(i + 4, j + 0, k + 9), TriniaBlocks.cloud.getDefaultState());
		world.setBlockState(new BlockPos(i + 4, j + 0, k + 10), TriniaBlocks.cloud.getDefaultState());
		world.setBlockState(new BlockPos(i + 4, j + 0, k + 11), TriniaBlocks.cloud.getDefaultState());
		world.setBlockState(new BlockPos(i + 4, j + 0, k + 12), TriniaBlocks.cloud.getDefaultState());
		world.setBlockState(new BlockPos(i + 4, j + 0, k + 13), TriniaBlocks.cloud.getDefaultState());
		world.setBlockState(new BlockPos(i + 4, j + 0, k + 14), TriniaBlocks.cloud.getDefaultState());
		world.setBlockState(new BlockPos(i + 4, j + 0, k + 15), TriniaBlocks.cloud.getDefaultState());
		world.setBlockState(new BlockPos(i + 4, j + 0, k + 16), TriniaBlocks.cloud.getDefaultState());
		world.setBlockState(new BlockPos(i + 4, j + 0, k + 17), TriniaBlocks.cloud.getDefaultState());
		world.setBlockState(new BlockPos(i + 4, j + 0, k + 18), TriniaBlocks.cloud.getDefaultState());
		world.setBlockState(new BlockPos(i + 4, j + 0, k + 19), TriniaBlocks.cloud.getDefaultState());
		world.setBlockState(new BlockPos(i + 4, j + 0, k + 20), TriniaBlocks.cloud.getDefaultState());
		world.setBlockState(new BlockPos(i + 4, j + 0, k + 21), TriniaBlocks.cloud.getDefaultState());
		world.setBlockState(new BlockPos(i + 4, j + 0, k + 22), TriniaBlocks.cloud.getDefaultState());
		world.setBlockState(new BlockPos(i + 4, j + 0, k + 23), TriniaBlocks.cloud.getDefaultState());
		world.setBlockState(new BlockPos(i + 4, j + 0, k + 24), TriniaBlocks.cloud.getDefaultState());
		world.setBlockState(new BlockPos(i + 4, j + 0, k + 25), TriniaBlocks.cloud.getDefaultState());
		world.setBlockState(new BlockPos(i + 4, j + 0, k + 26), TriniaBlocks.cloud.getDefaultState());
		world.setBlockState(new BlockPos(i + 4, j + 0, k + 27), TriniaBlocks.cloud.getDefaultState());
		world.setBlockState(new BlockPos(i + 4, j + 0, k + 28), TriniaBlocks.cloud.getDefaultState());
		world.setBlockState(new BlockPos(i + 4, j + 0, k + 29), TriniaBlocks.cloud.getDefaultState());
		world.setBlockState(new BlockPos(i + 4, j + 0, k + 30), TriniaBlocks.cloud.getDefaultState());
		world.setBlockState(new BlockPos(i + 4, j + 0, k + 31), TriniaBlocks.cloud.getDefaultState());
		world.setBlockState(new BlockPos(i + 4, j + 0, k + 32), TriniaBlocks.cloud.getDefaultState());
		world.setBlockState(new BlockPos(i + 4, j + 0, k + 33), TriniaBlocks.cloud.getDefaultState());
		world.setBlockState(new BlockPos(i + 4, j + 0, k + 34), TriniaBlocks.cloud.getDefaultState());
		world.setBlockState(new BlockPos(i + 4, j + 0, k + 35), TriniaBlocks.cloud.getDefaultState());
		world.setBlockState(new BlockPos(i + 4, j + 1, k + 0), TriniaBlocks.cloud.getDefaultState());
		world.setBlockState(new BlockPos(i + 4, j + 1, k + 1), TriniaBlocks.cloud.getDefaultState());
		world.setBlockState(new BlockPos(i + 4, j + 1, k + 2), TriniaBlocks.cloud.getDefaultState());
		world.setBlockState(new BlockPos(i + 4, j + 1, k + 3), TriniaBlocks.cloud.getDefaultState());
		world.setBlockState(new BlockPos(i + 4, j + 1, k + 4), TriniaBlocks.cloud.getDefaultState());
		world.setBlockState(new BlockPos(i + 4, j + 1, k + 5), TriniaBlocks.cloud.getDefaultState());
		world.setBlockState(new BlockPos(i + 4, j + 1, k + 6), TriniaBlocks.cloud.getDefaultState());
		world.setBlockState(new BlockPos(i + 4, j + 1, k + 7), TriniaBlocks.cloud.getDefaultState());
		world.setBlockState(new BlockPos(i + 4, j + 1, k + 8), TriniaBlocks.cloud.getDefaultState());
		world.setBlockState(new BlockPos(i + 4, j + 1, k + 9), TriniaBlocks.cloud.getDefaultState());
		world.setBlockState(new BlockPos(i + 4, j + 1, k + 10), TriniaBlocks.cloud.getDefaultState());
		world.setBlockState(new BlockPos(i + 4, j + 1, k + 11), TriniaBlocks.cloud.getDefaultState());
		world.setBlockState(new BlockPos(i + 4, j + 1, k + 12), TriniaBlocks.cloud.getDefaultState());
		world.setBlockState(new BlockPos(i + 4, j + 1, k + 13), TriniaBlocks.cloud.getDefaultState());
		world.setBlockState(new BlockPos(i + 4, j + 1, k + 14), TriniaBlocks.cloud.getDefaultState());
		world.setBlockState(new BlockPos(i + 4, j + 1, k + 15), TriniaBlocks.cloud.getDefaultState());
		world.setBlockState(new BlockPos(i + 4, j + 1, k + 16), TriniaBlocks.cloud.getDefaultState());
		world.setBlockState(new BlockPos(i + 4, j + 1, k + 17), TriniaBlocks.cloud.getDefaultState());
		world.setBlockState(new BlockPos(i + 4, j + 1, k + 18), TriniaBlocks.cloud.getDefaultState());
		world.setBlockState(new BlockPos(i + 4, j + 1, k + 19), TriniaBlocks.cloud.getDefaultState());
		world.setBlockState(new BlockPos(i + 4, j + 1, k + 20), TriniaBlocks.cloud.getDefaultState());
		world.setBlockState(new BlockPos(i + 4, j + 1, k + 21), TriniaBlocks.cloud.getDefaultState());
		world.setBlockState(new BlockPos(i + 4, j + 1, k + 22), TriniaBlocks.cloud.getDefaultState());
		world.setBlockState(new BlockPos(i + 4, j + 1, k + 23), TriniaBlocks.cloud.getDefaultState());
		world.setBlockState(new BlockPos(i + 4, j + 1, k + 24), TriniaBlocks.cloud.getDefaultState());
		world.setBlockState(new BlockPos(i + 4, j + 1, k + 25), TriniaBlocks.cloud.getDefaultState());
		world.setBlockState(new BlockPos(i + 4, j + 1, k + 26), TriniaBlocks.cloud.getDefaultState());
		world.setBlockState(new BlockPos(i + 4, j + 1, k + 27), TriniaBlocks.cloud.getDefaultState());
		world.setBlockState(new BlockPos(i + 4, j + 1, k + 28), TriniaBlocks.cloud.getDefaultState());
		world.setBlockState(new BlockPos(i + 4, j + 1, k + 29), TriniaBlocks.cloud.getDefaultState());
		world.setBlockState(new BlockPos(i + 4, j + 1, k + 30), TriniaBlocks.cloud.getDefaultState());
		world.setBlockState(new BlockPos(i + 4, j + 1, k + 31), TriniaBlocks.cloud.getDefaultState());
		world.setBlockState(new BlockPos(i + 4, j + 1, k + 32), TriniaBlocks.cloud.getDefaultState());
		world.setBlockState(new BlockPos(i + 4, j + 1, k + 33), TriniaBlocks.cloud.getDefaultState());
		world.setBlockState(new BlockPos(i + 4, j + 1, k + 34), TriniaBlocks.cloud.getDefaultState());
		world.setBlockState(new BlockPos(i + 4, j + 1, k + 35), TriniaBlocks.cloud.getDefaultState());
		world.setBlockState(new BlockPos(i + 4, j + 1, k + 36), TriniaBlocks.cloud.getDefaultState());
		world.setBlockState(new BlockPos(i + 4, j + 2, k + 0), TriniaBlocks.cloud.getDefaultState());
		world.setBlockState(new BlockPos(i + 4, j + 2, k + 1), TriniaBlocks.cloud.getDefaultState());
		world.setBlockState(new BlockPos(i + 4, j + 2, k + 2), TriniaBlocks.cloud.getDefaultState());
		world.setBlockState(new BlockPos(i + 4, j + 2, k + 3), TriniaBlocks.cloud.getDefaultState());
		world.setBlockState(new BlockPos(i + 4, j + 2, k + 4), TriniaBlocks.cloud.getDefaultState());
		world.setBlockState(new BlockPos(i + 4, j + 2, k + 5), TriniaBlocks.cloud.getDefaultState());
		world.setBlockState(new BlockPos(i + 4, j + 2, k + 6), TriniaBlocks.cloud.getDefaultState());
		world.setBlockState(new BlockPos(i + 4, j + 2, k + 7), TriniaBlocks.cloud.getDefaultState());
		world.setBlockState(new BlockPos(i + 4, j + 2, k + 8), TriniaBlocks.cloud.getDefaultState());
		world.setBlockState(new BlockPos(i + 4, j + 2, k + 9), TriniaBlocks.cloud.getDefaultState());
		world.setBlockState(new BlockPos(i + 4, j + 2, k + 10), TriniaBlocks.cloud.getDefaultState());
		world.setBlockState(new BlockPos(i + 4, j + 2, k + 11), TriniaBlocks.cloud.getDefaultState());
		world.setBlockState(new BlockPos(i + 4, j + 2, k + 12), TriniaBlocks.cloud.getDefaultState());
		world.setBlockState(new BlockPos(i + 4, j + 2, k + 13), TriniaBlocks.cloud.getDefaultState());
		world.setBlockState(new BlockPos(i + 4, j + 2, k + 14), TriniaBlocks.cloud.getDefaultState());
		world.setBlockState(new BlockPos(i + 4, j + 2, k + 15), TriniaBlocks.cloud.getDefaultState());
		world.setBlockState(new BlockPos(i + 4, j + 2, k + 16), TriniaBlocks.cloud.getDefaultState());
		world.setBlockState(new BlockPos(i + 4, j + 2, k + 17), TriniaBlocks.cloud.getDefaultState());
		world.setBlockState(new BlockPos(i + 4, j + 2, k + 18), TriniaBlocks.cloud.getDefaultState());
		world.setBlockState(new BlockPos(i + 4, j + 2, k + 19), TriniaBlocks.cloud.getDefaultState());
		world.setBlockState(new BlockPos(i + 4, j + 2, k + 20), TriniaBlocks.cloud.getDefaultState());
		world.setBlockState(new BlockPos(i + 4, j + 2, k + 21), TriniaBlocks.cloud.getDefaultState());
		world.setBlockState(new BlockPos(i + 4, j + 2, k + 22), TriniaBlocks.cloud.getDefaultState());
		world.setBlockState(new BlockPos(i + 4, j + 2, k + 23), TriniaBlocks.cloud.getDefaultState());
		world.setBlockState(new BlockPos(i + 4, j + 2, k + 24), TriniaBlocks.cloud.getDefaultState());
		world.setBlockState(new BlockPos(i + 4, j + 2, k + 25), TriniaBlocks.cloud.getDefaultState());
		world.setBlockState(new BlockPos(i + 4, j + 2, k + 26), TriniaBlocks.cloud.getDefaultState());
		world.setBlockState(new BlockPos(i + 4, j + 2, k + 27), TriniaBlocks.cloud.getDefaultState());
		world.setBlockState(new BlockPos(i + 4, j + 2, k + 28), TriniaBlocks.cloud.getDefaultState());
		world.setBlockState(new BlockPos(i + 4, j + 2, k + 29), TriniaBlocks.cloud.getDefaultState());
		world.setBlockState(new BlockPos(i + 4, j + 2, k + 30), TriniaBlocks.cloud.getDefaultState());
		world.setBlockState(new BlockPos(i + 4, j + 2, k + 31), TriniaBlocks.cloud.getDefaultState());
		world.setBlockState(new BlockPos(i + 4, j + 2, k + 32), TriniaBlocks.cloud.getDefaultState());
		world.setBlockState(new BlockPos(i + 4, j + 2, k + 33), TriniaBlocks.cloud.getDefaultState());
		world.setBlockState(new BlockPos(i + 4, j + 2, k + 34), TriniaBlocks.cloud.getDefaultState());
		world.setBlockState(new BlockPos(i + 4, j + 2, k + 35), TriniaBlocks.cloud.getDefaultState());
		world.setBlockState(new BlockPos(i + 4, j + 2, k + 36), TriniaBlocks.cloud.getDefaultState());
		world.setBlockState(new BlockPos(i + 4, j + 3, k + 1), TriniaBlocks.cloud.getDefaultState());
		world.setBlockState(new BlockPos(i + 4, j + 3, k + 2), Blocks.quartz_block.getDefaultState());
		world.setBlockState(new BlockPos(i + 4, j + 3, k + 3), Blocks.quartz_block.getDefaultState());
		world.setBlockState(new BlockPos(i + 4, j + 3, k + 4), Blocks.quartz_block.getDefaultState());
		world.setBlockState(new BlockPos(i + 4, j + 3, k + 5), Blocks.quartz_block.getDefaultState());
		world.setBlockState(new BlockPos(i + 4, j + 3, k + 6), Blocks.quartz_block.getDefaultState());
		world.setBlockState(new BlockPos(i + 4, j + 3, k + 7), Blocks.quartz_block.getDefaultState());
		world.setBlockState(new BlockPos(i + 4, j + 3, k + 8), Blocks.quartz_block.getDefaultState());
