package com.trinia.world.gen;

import java.util.Random;

import com.google.common.collect.Lists;
import com.trinia.blocks.TriniaBlocks;
import com.trinia.items.TriniaItems;

import net.minecraft.block.Block;
import net.minecraft.block.state.IBlockState;
import net.minecraft.init.Blocks;
import net.minecraft.tileentity.TileEntityChest;
import net.minecraft.util.BlockPos;
import net.minecraft.util.WeightedRandomChestContent;
import net.minecraft.world.World;
import net.minecraft.world.gen.feature.WorldGenerator;

public class WorldGenGoldenDungeon extends WorldGenerator {
	
	private static WeightedRandomChestContent[] loot = {
			new WeightedRandomChestContent(TriniaItems.angelHalo, 0, 1, 5, 10), 
			new WeightedRandomChestContent(TriniaItems.angelWings, 0, 1, 10, 40), 
			new WeightedRandomChestContent(TriniaItems.waterAmulat, 0, 1, 5, 40)};
	@Override
	public boolean generate(World world, Random rand, BlockPos pos) {
		int i = pos.getX(), j = pos.getY(), k = pos.getZ();
		i-=5;
		k-=5;
		world.setBlockState(new BlockPos(i + 0, j + 4, k + 3), TriniaBlocks.goldenPillar.getDefaultState());
		world.setBlockState(new BlockPos(i + 0, j + 4, k + 5), TriniaBlocks.goldenPillar.getDefaultState());
		world.setBlockState(new BlockPos(i + 1, j + 0, k + 3), TriniaBlocks.copperBlock.getDefaultState());
		world.setBlockState(new BlockPos(i + 1, j + 0, k + 4), TriniaBlocks.copperBlock.getDefaultState());
		world.setBlockState(new BlockPos(i + 1, j + 0, k + 5), TriniaBlocks.copperBlock.getDefaultState());
		world.setBlockState(new BlockPos(i + 1, j + 1, k + 3), TriniaBlocks.goldenBrick.getDefaultState());
		world.setBlockState(new BlockPos(i + 1, j + 1, k + 4), TriniaBlocks.goldenBrick.getDefaultState());
		world.setBlockState(new BlockPos(i + 1, j + 1, k + 5), TriniaBlocks.goldenBrick.getDefaultState());
		world.setBlockState(new BlockPos(i + 1, j + 2, k + 3), TriniaBlocks.goldenBrick.getDefaultState());
		world.setBlockState(new BlockPos(i + 1, j + 2, k + 4), TriniaBlocks.goldenDoor.getDefaultState());
		world.setBlockState(new BlockPos(i + 1, j + 2, k + 5), TriniaBlocks.goldenBrick.getDefaultState());
		world.setBlockState(new BlockPos(i + 1, j + 3, k + 3), TriniaBlocks.goldenBrick.getDefaultState());
		world.setBlockState(new BlockPos(i + 1, j + 3, k + 4), TriniaBlocks.goldenDoor.getDefaultState());
		world.setBlockState(new BlockPos(i + 1, j + 3, k + 5), TriniaBlocks.goldenBrick.getDefaultState());
		world.setBlockState(new BlockPos(i + 1, j + 4, k + 2), TriniaBlocks.goldenPillar.getDefaultState());
		world.setBlockState(new BlockPos(i + 1, j + 4, k + 3), TriniaBlocks.goldenBrick.getDefaultState());
		world.setBlockState(new BlockPos(i + 1, j + 4, k + 4), TriniaBlocks.goldenBrick.getDefaultState());
		world.setBlockState(new BlockPos(i + 1, j + 4, k + 5), TriniaBlocks.goldenBrick.getDefaultState());
		world.setBlockState(new BlockPos(i + 1, j + 4, k + 6), TriniaBlocks.goldenPillar.getDefaultState());
		world.setBlockState(new BlockPos(i + 2, j + 0, k + 2), TriniaBlocks.copperBlock.getDefaultState());
		world.setBlockState(new BlockPos(i + 2, j + 0, k + 3), TriniaBlocks.copperBlock.getDefaultState());
		world.setBlockState(new BlockPos(i + 2, j + 0, k + 4), TriniaBlocks.copperBlock.getDefaultState());
		world.setBlockState(new BlockPos(i + 2, j + 0, k + 5), TriniaBlocks.copperBlock.getDefaultState());
		world.setBlockState(new BlockPos(i + 2, j + 0, k + 6), TriniaBlocks.copperBlock.getDefaultState());
		world.setBlockState(new BlockPos(i + 2, j + 1, k + 2), TriniaBlocks.goldenBrick.getDefaultState());
		world.setBlockState(new BlockPos(i + 2, j + 1, k + 6), TriniaBlocks.goldenBrick.getDefaultState());
		world.setBlockState(new BlockPos(i + 2, j + 2, k + 2), TriniaBlocks.goldenBrick.getDefaultState());
		world.setBlockState(new BlockPos(i + 2, j + 2, k + 6), TriniaBlocks.goldenBrick.getDefaultState());
		world.setBlockState(new BlockPos(i + 2, j + 3, k + 2), TriniaBlocks.goldenBrick.getDefaultState());
		world.setBlockState(new BlockPos(i + 2, j + 3, k + 6), TriniaBlocks.goldenBrick.getDefaultState());
		world.setBlockState(new BlockPos(i + 2, j + 4, k + 1), TriniaBlocks.goldenPillar.getDefaultState());
		world.setBlockState(new BlockPos(i + 2, j + 4, k + 2), TriniaBlocks.goldenBrick.getDefaultState());
		world.setBlockState(new BlockPos(i + 2, j + 4, k + 6), TriniaBlocks.goldenBrick.getDefaultState());
		world.setBlockState(new BlockPos(i + 2, j + 4, k + 7), TriniaBlocks.goldenPillar.getDefaultState());
		world.setBlockState(new BlockPos(i + 2, j + 5, k + 3), TriniaBlocks.goldenBrick.getDefaultState());
		world.setBlockState(new BlockPos(i + 2, j + 5, k + 4), TriniaBlocks.goldenBrick.getDefaultState());
		world.setBlockState(new BlockPos(i + 2, j + 5, k + 5), TriniaBlocks.goldenBrick.getDefaultState());
		world.setBlockState(new BlockPos(i + 2, j + 6, k + 3), TriniaBlocks.goldenBrick.getDefaultState());
		world.setBlockState(new BlockPos(i + 2, j + 6, k + 5), TriniaBlocks.goldenBrick.getDefaultState());
		world.setBlockState(new BlockPos(i + 3, j + 0, k + 1), TriniaBlocks.copperBlock.getDefaultState());
		world.setBlockState(new BlockPos(i + 3, j + 0, k + 2), TriniaBlocks.copperBlock.getDefaultState());
		world.setBlockState(new BlockPos(i + 3, j + 0, k + 3), TriniaBlocks.copperBlock.getDefaultState());
		world.setBlockState(new BlockPos(i + 3, j + 0, k + 4), TriniaBlocks.copperBlock.getDefaultState());
		world.setBlockState(new BlockPos(i + 3, j + 0, k + 5), TriniaBlocks.copperBlock.getDefaultState());
		world.setBlockState(new BlockPos(i + 3, j + 0, k + 6), TriniaBlocks.copperBlock.getDefaultState());
		world.setBlockState(new BlockPos(i + 3, j + 0, k + 7), TriniaBlocks.copperBlock.getDefaultState());
		world.setBlockState(new BlockPos(i + 3, j + 1, k + 1), TriniaBlocks.goldenBrick.getDefaultState());
		world.setBlockState(new BlockPos(i + 3, j + 1, k + 7), TriniaBlocks.goldenBrick.getDefaultState());
		world.setBlockState(new BlockPos(i + 3, j + 2, k + 1), TriniaBlocks.goldenBrick.getDefaultState());
		world.setBlockState(new BlockPos(i + 3, j + 2, k + 7), TriniaBlocks.goldenBrick.getDefaultState());
		world.setBlockState(new BlockPos(i + 3, j + 3, k + 1), TriniaBlocks.goldenBrick.getDefaultState());
		world.setBlockState(new BlockPos(i + 3, j + 3, k + 7), TriniaBlocks.goldenBrick.getDefaultState());
		world.setBlockState(new BlockPos(i + 3, j + 4, k + 0), TriniaBlocks.goldenPillar.getDefaultState());
		world.setBlockState(new BlockPos(i + 3, j + 4, k + 1), TriniaBlocks.goldenBrick.getDefaultState());
		world.setBlockState(new BlockPos(i + 3, j + 4, k + 7), TriniaBlocks.goldenBrick.getDefaultState());
		world.setBlockState(new BlockPos(i + 3, j + 4, k + 8), TriniaBlocks.goldenPillar.getDefaultState());
		world.setBlockState(new BlockPos(i + 3, j + 5, k + 2), TriniaBlocks.goldenBrick.getDefaultState());
		world.setBlockState(new BlockPos(i + 3, j + 5, k + 3), TriniaBlocks.goldenBrick.getDefaultState());
		world.setBlockState(new BlockPos(i + 3, j + 5, k + 4), TriniaBlocks.goldenBrick.getDefaultState());
		world.setBlockState(new BlockPos(i + 3, j + 5, k + 5), TriniaBlocks.goldenBrick.getDefaultState());
		world.setBlockState(new BlockPos(i + 3, j + 5, k + 6), TriniaBlocks.goldenBrick.getDefaultState());
		world.setBlockState(new BlockPos(i + 3, j + 6, k + 2), TriniaBlocks.goldenBrick.getDefaultState());
		world.setBlockState(new BlockPos(i + 3, j + 6, k + 6), TriniaBlocks.goldenBrick.getDefaultState());
		world.setBlockState(new BlockPos(i + 4, j + 0, k + 1), TriniaBlocks.copperBlock.getDefaultState());
		world.setBlockState(new BlockPos(i + 4, j + 0, k + 2), TriniaBlocks.copperBlock.getDefaultState());
		world.setBlockState(new BlockPos(i + 4, j + 0, k + 3), TriniaBlocks.copperBlock.getDefaultState());
		world.setBlockState(new BlockPos(i + 4, j + 0, k + 4), TriniaBlocks.copperBlock.getDefaultState());
		world.setBlockState(new BlockPos(i + 4, j + 0, k + 5), TriniaBlocks.copperBlock.getDefaultState());
		world.setBlockState(new BlockPos(i + 4, j + 0, k + 6), TriniaBlocks.copperBlock.getDefaultState());
		world.setBlockState(new BlockPos(i + 4, j + 0, k + 7), TriniaBlocks.copperBlock.getDefaultState());
		world.setBlockState(new BlockPos(i + 4, j + 1, k + 1), TriniaBlocks.goldenDoor.getDefaultState());
		world.setBlockState(new BlockPos(i + 4, j + 1, k + 7), TriniaBlocks.goldenDoor.getDefaultState());
		world.setBlockState(new BlockPos(i + 4, j + 2, k + 1), TriniaBlocks.goldenDoor.getDefaultState());
		world.setBlockState(new BlockPos(i + 4, j + 2, k + 7), TriniaBlocks.goldenDoor.getDefaultState());
		world.setBlockState(new BlockPos(i + 4, j + 3, k + 1), TriniaBlocks.goldenDoor.getDefaultState());
		world.setBlockState(new BlockPos(i + 4, j + 3, k + 7), TriniaBlocks.goldenDoor.getDefaultState());
		world.setBlockState(new BlockPos(i + 4, j + 4, k + 1), TriniaBlocks.goldenBrick.getDefaultState());
		world.setBlockState(new BlockPos(i + 4, j + 4, k + 7), TriniaBlocks.goldenBrick.getDefaultState());
		world.setBlockState(new BlockPos(i + 4, j + 5, k + 2), TriniaBlocks.goldenBrick.getDefaultState());
		world.setBlockState(new BlockPos(i + 4, j + 5, k + 3), TriniaBlocks.goldenBrick.getDefaultState());
		world.setBlockState(new BlockPos(i + 4, j + 5, k + 4), TriniaBlocks.goldenBrick.getDefaultState());
		world.setBlockState(new BlockPos(i + 4, j + 5, k + 5), TriniaBlocks.goldenBrick.getDefaultState());
		world.setBlockState(new BlockPos(i + 4, j + 5, k + 6), TriniaBlocks.goldenBrick.getDefaultState());
		world.setBlockState(new BlockPos(i + 5, j + 0, k + 1), TriniaBlocks.copperBlock.getDefaultState());
		world.setBlockState(new BlockPos(i + 5, j + 0, k + 2), TriniaBlocks.copperBlock.getDefaultState());
		world.setBlockState(new BlockPos(i + 5, j + 0, k + 3), TriniaBlocks.copperBlock.getDefaultState());
		world.setBlockState(new BlockPos(i + 5, j + 0, k + 4), TriniaBlocks.copperBlock.getDefaultState());
		world.setBlockState(new BlockPos(i + 5, j + 0, k + 5), TriniaBlocks.copperBlock.getDefaultState());
		world.setBlockState(new BlockPos(i + 5, j + 0, k + 6), TriniaBlocks.copperBlock.getDefaultState());
		world.setBlockState(new BlockPos(i + 5, j + 0, k + 7), TriniaBlocks.copperBlock.getDefaultState());
		world.setBlockState(new BlockPos(i + 5, j + 1, k + 1), TriniaBlocks.goldenDoor.getDefaultState());
		world.setBlockState(new BlockPos(i + 5, j + 1, k + 4), Blocks.chest.getStateFromMeta(2));
		world.setBlockState(new BlockPos(i + 5, j + 1, k + 7), TriniaBlocks.goldenDoor.getDefaultState());
		world.setBlockState(new BlockPos(i + 5, j + 2, k + 1), TriniaBlocks.goldenKeyHole.getDefaultState());
		TileEntityChest te = (TileEntityChest)world.getTileEntity(new BlockPos(i + 5, j + 2, k + 4));
		if(te != null) {
			WeightedRandomChestContent.generateChestContents(rand, Lists.newArrayList(loot), te, 4);
		}
		
		world.setBlockState(new BlockPos(i + 5, j + 2, k + 7), TriniaBlocks.goldenDoor.getDefaultState());
		world.setBlockState(new BlockPos(i + 5, j + 3, k + 1), TriniaBlocks.goldenDoor.getDefaultState());
		world.setBlockState(new BlockPos(i + 5, j + 3, k + 7), TriniaBlocks.goldenDoor.getDefaultState());
		world.setBlockState(new BlockPos(i + 5, j + 4, k + 0), TriniaBlocks.goldenPillar.getDefaultState());
		world.setBlockState(new BlockPos(i + 5, j + 4, k + 1), TriniaBlocks.goldenBrick.getDefaultState());
		world.setBlockState(new BlockPos(i + 5, j + 4, k + 7), TriniaBlocks.goldenBrick.getDefaultState());
		world.setBlockState(new BlockPos(i + 5, j + 4, k + 8), TriniaBlocks.goldenPillar.getDefaultState());
		world.setBlockState(new BlockPos(i + 5, j + 5, k + 2), TriniaBlocks.goldenBrick.getDefaultState());
		world.setBlockState(new BlockPos(i + 5, j + 5, k + 3), TriniaBlocks.goldenBrick.getDefaultState());
		world.setBlockState(new BlockPos(i + 5, j + 5, k + 4), TriniaBlocks.goldenBrick.getDefaultState());
		world.setBlockState(new BlockPos(i + 5, j + 5, k + 5), TriniaBlocks.goldenBrick.getDefaultState());
		world.setBlockState(new BlockPos(i + 5, j + 5, k + 6), TriniaBlocks.goldenBrick.getDefaultState());
		world.setBlockState(new BlockPos(i + 5, j + 6, k + 2), TriniaBlocks.goldenBrick.getDefaultState());
		world.setBlockState(new BlockPos(i + 5, j + 6, k + 6), TriniaBlocks.goldenBrick.getDefaultState());
		world.setBlockState(new BlockPos(i + 6, j + 0, k + 1), TriniaBlocks.copperBlock.getDefaultState());
		world.setBlockState(new BlockPos(i + 6, j + 0, k + 2), TriniaBlocks.copperBlock.getDefaultState());
		world.setBlockState(new BlockPos(i + 6, j + 0, k + 3), TriniaBlocks.copperBlock.getDefaultState());
		world.setBlockState(new BlockPos(i + 6, j + 0, k + 4), TriniaBlocks.copperBlock.getDefaultState());
		world.setBlockState(new BlockPos(i + 6, j + 0, k + 5), TriniaBlocks.copperBlock.getDefaultState());
		world.setBlockState(new BlockPos(i + 6, j + 0, k + 6), TriniaBlocks.copperBlock.getDefaultState());
		world.setBlockState(new BlockPos(i + 6, j + 0, k + 7), TriniaBlocks.copperBlock.getDefaultState());
		world.setBlockState(new BlockPos(i + 6, j + 1, k + 1), TriniaBlocks.goldenDoor.getDefaultState());
		world.setBlockState(new BlockPos(i + 6, j + 1, k + 7), TriniaBlocks.goldenDoor.getDefaultState());
		world.setBlockState(new BlockPos(i + 6, j + 2, k + 1), TriniaBlocks.goldenDoor.getDefaultState());
		world.setBlockState(new BlockPos(i + 6, j + 2, k + 7), TriniaBlocks.goldenDoor.getDefaultState());
		world.setBlockState(new BlockPos(i + 6, j + 3, k + 1), TriniaBlocks.goldenDoor.getDefaultState());
		world.setBlockState(new BlockPos(i + 6, j + 3, k + 7), TriniaBlocks.goldenDoor.getDefaultState());
		world.setBlockState(new BlockPos(i + 6, j + 4, k + 1), TriniaBlocks.goldenBrick.getDefaultState());
		world.setBlockState(new BlockPos(i + 6, j + 4, k + 7), TriniaBlocks.goldenBrick.getDefaultState());
		world.setBlockState(new BlockPos(i + 6, j + 5, k + 2), TriniaBlocks.goldenBrick.getDefaultState());
		world.setBlockState(new BlockPos(i + 6, j + 5, k + 3), TriniaBlocks.goldenBrick.getDefaultState());
		world.setBlockState(new BlockPos(i + 6, j + 5, k + 4), TriniaBlocks.goldenBrick.getDefaultState());
		world.setBlockState(new BlockPos(i + 6, j + 5, k + 5), TriniaBlocks.goldenBrick.getDefaultState());
		world.setBlockState(new BlockPos(i + 6, j + 5, k + 6), TriniaBlocks.goldenBrick.getDefaultState());
		world.setBlockState(new BlockPos(i + 7, j + 0, k + 1), TriniaBlocks.copperBlock.getDefaultState());
		world.setBlockState(new BlockPos(i + 7, j + 0, k + 2), TriniaBlocks.copperBlock.getDefaultState());
		world.setBlockState(new BlockPos(i + 7, j + 0, k + 3), TriniaBlocks.copperBlock.getDefaultState());
		world.setBlockState(new BlockPos(i + 7, j + 0, k + 4), TriniaBlocks.copperBlock.getDefaultState());
		world.setBlockState(new BlockPos(i + 7, j + 0, k + 5), TriniaBlocks.copperBlock.getDefaultState());
		world.setBlockState(new BlockPos(i + 7, j + 0, k + 6), TriniaBlocks.copperBlock.getDefaultState());
		world.setBlockState(new BlockPos(i + 7, j + 0, k + 7), TriniaBlocks.copperBlock.getDefaultState());
		world.setBlockState(new BlockPos(i + 7, j + 1, k + 1), TriniaBlocks.goldenBrick.getDefaultState());
		world.setBlockState(new BlockPos(i + 7, j + 1, k + 7), TriniaBlocks.goldenBrick.getDefaultState());
		world.setBlockState(new BlockPos(i + 7, j + 2, k + 1), TriniaBlocks.goldenBrick.getDefaultState());
		world.setBlockState(new BlockPos(i + 7, j + 2, k + 7), TriniaBlocks.goldenBrick.getDefaultState());
		world.setBlockState(new BlockPos(i + 7, j + 3, k + 1), TriniaBlocks.goldenBrick.getDefaultState());
		world.setBlockState(new BlockPos(i + 7, j + 3, k + 7), TriniaBlocks.goldenBrick.getDefaultState());
		world.setBlockState(new BlockPos(i + 7, j + 4, k + 0), TriniaBlocks.goldenPillar.getDefaultState());
		world.setBlockState(new BlockPos(i + 7, j + 4, k + 1), TriniaBlocks.goldenBrick.getDefaultState());
		world.setBlockState(new BlockPos(i + 7, j + 4, k + 7), TriniaBlocks.goldenBrick.getDefaultState());
		world.setBlockState(new BlockPos(i + 7, j + 4, k + 8), TriniaBlocks.goldenPillar.getDefaultState());
		world.setBlockState(new BlockPos(i + 7, j + 5, k + 2), TriniaBlocks.goldenBrick.getDefaultState());
		world.setBlockState(new BlockPos(i + 7, j + 5, k + 3), TriniaBlocks.goldenBrick.getDefaultState());
		world.setBlockState(new BlockPos(i + 7, j + 5, k + 4), TriniaBlocks.goldenBrick.getDefaultState());
		world.setBlockState(new BlockPos(i + 7, j + 5, k + 5), TriniaBlocks.goldenBrick.getDefaultState());
		world.setBlockState(new BlockPos(i + 7, j + 5, k + 6), TriniaBlocks.goldenBrick.getDefaultState());
		world.setBlockState(new BlockPos(i + 7, j + 6, k + 2), TriniaBlocks.goldenBrick.getDefaultState());
		world.setBlockState(new BlockPos(i + 7, j + 6, k + 6), TriniaBlocks.goldenBrick.getDefaultState());
		world.setBlockState(new BlockPos(i + 8, j + 0, k + 2), TriniaBlocks.copperBlock.getDefaultState());
		world.setBlockState(new BlockPos(i + 8, j + 0, k + 3), TriniaBlocks.copperBlock.getDefaultState());
		world.setBlockState(new BlockPos(i + 8, j + 0, k + 4), TriniaBlocks.copperBlock.getDefaultState());
		world.setBlockState(new BlockPos(i + 8, j + 0, k + 5), TriniaBlocks.copperBlock.getDefaultState());
		world.setBlockState(new BlockPos(i + 8, j + 0, k + 6), TriniaBlocks.copperBlock.getDefaultState());
		world.setBlockState(new BlockPos(i + 8, j + 1, k + 2), TriniaBlocks.goldenBrick.getDefaultState());
		world.setBlockState(new BlockPos(i + 8, j + 1, k + 6), TriniaBlocks.goldenBrick.getDefaultState());
		world.setBlockState(new BlockPos(i + 8, j + 2, k + 2), TriniaBlocks.goldenBrick.getDefaultState());
		world.setBlockState(new BlockPos(i + 8, j + 2, k + 6), TriniaBlocks.goldenBrick.getDefaultState());
		world.setBlockState(new BlockPos(i + 8, j + 3, k + 2), TriniaBlocks.goldenBrick.getDefaultState());
		world.setBlockState(new BlockPos(i + 8, j + 3, k + 6), TriniaBlocks.goldenBrick.getDefaultState());
		world.setBlockState(new BlockPos(i + 8, j + 4, k + 1), TriniaBlocks.goldenPillar.getDefaultState());
		world.setBlockState(new BlockPos(i + 8, j + 4, k + 2), TriniaBlocks.goldenBrick.getDefaultState());
		world.setBlockState(new BlockPos(i + 8, j + 4, k + 6), TriniaBlocks.goldenBrick.getDefaultState());
		world.setBlockState(new BlockPos(i + 8, j + 4, k + 7), TriniaBlocks.goldenPillar.getDefaultState());
		world.setBlockState(new BlockPos(i + 8, j + 5, k + 3), TriniaBlocks.goldenBrick.getDefaultState());
		world.setBlockState(new BlockPos(i + 8, j + 5, k + 4), TriniaBlocks.goldenBrick.getDefaultState());
		world.setBlockState(new BlockPos(i + 8, j + 5, k + 5), TriniaBlocks.goldenBrick.getDefaultState());
		world.setBlockState(new BlockPos(i + 8, j + 6, k + 3), TriniaBlocks.goldenBrick.getDefaultState());
		world.setBlockState(new BlockPos(i + 8, j + 6, k + 5), TriniaBlocks.goldenBrick.getDefaultState());
		world.setBlockState(new BlockPos(i + 9, j + 0, k + 3), TriniaBlocks.copperBlock.getDefaultState());
		world.setBlockState(new BlockPos(i + 9, j + 0, k + 4), TriniaBlocks.copperBlock.getDefaultState());
		world.setBlockState(new BlockPos(i + 9, j + 0, k + 5), TriniaBlocks.copperBlock.getDefaultState());
		world.setBlockState(new BlockPos(i + 9, j + 1, k + 3), TriniaBlocks.goldenBrick.getDefaultState());
		world.setBlockState(new BlockPos(i + 9, j + 1, k + 4), TriniaBlocks.goldenBrick.getDefaultState());
		world.setBlockState(new BlockPos(i + 9, j + 1, k + 5), TriniaBlocks.goldenBrick.getDefaultState());
		world.setBlockState(new BlockPos(i + 9, j + 2, k + 3), TriniaBlocks.goldenBrick.getDefaultState());
		world.setBlockState(new BlockPos(i + 9, j + 2, k + 4), TriniaBlocks.goldenDoor.getDefaultState());
		world.setBlockState(new BlockPos(i + 9, j + 2, k + 5), TriniaBlocks.goldenBrick.getDefaultState());
		world.setBlockState(new BlockPos(i + 9, j + 3, k + 3), TriniaBlocks.goldenBrick.getDefaultState());
		world.setBlockState(new BlockPos(i + 9, j + 3, k + 4), TriniaBlocks.goldenDoor.getDefaultState());
		world.setBlockState(new BlockPos(i + 9, j + 3, k + 5), TriniaBlocks.goldenBrick.getDefaultState());
		world.setBlockState(new BlockPos(i + 9, j + 4, k + 2), TriniaBlocks.goldenPillar.getDefaultState());
		world.setBlockState(new BlockPos(i + 9, j + 4, k + 3), TriniaBlocks.goldenBrick.getDefaultState());
		world.setBlockState(new BlockPos(i + 9, j + 4, k + 4), TriniaBlocks.goldenBrick.getDefaultState());
		world.setBlockState(new BlockPos(i + 9, j + 4, k + 5), TriniaBlocks.goldenBrick.getDefaultState());
		world.setBlockState(new BlockPos(i + 9, j + 4, k + 6), TriniaBlocks.goldenPillar.getDefaultState());
		world.setBlockState(new BlockPos(i + 10, j + 4, k + 3), TriniaBlocks.goldenPillar.getDefaultState());
		world.setBlockState(new BlockPos(i + 10, j + 4, k + 5), TriniaBlocks.goldenPillar.getDefaultState());

		return true;
	}
}